Workbook
Name rf: data!$B$13
Name tau: #REF!

Sheet Answers
A1: Assignment 2 - answer summary
A2: Every value below is a live formula; the working is on the three sheets to the right.
A4: Q | B4: Question | C4: Answer | D4: Submit as | E4: Where it is computed
A5: 1 | B5: Estimated return of the efficient portfolio with 5% volatility (%) | C5: =Q1_Q2_Portfolio!B47 -> 5.3181915 | D5: =TEXT(C5,"0.00") -> 5.32 | E5: Q1_Q2_Portfolio
A6: 2 | B6: True (realised) expected return of that same portfolio (%) | C6: =Q1_Q2_Portfolio!B48 -> 3.8550479 | D6: =TEXT(C6,"0.00") -> 3.86 | E6: Q1_Q2_Portfolio
A7: 3 | B7: Value-at-Risk at the 90% level, monthly loss (%) | C7: =Q3_Q4_VaR!B74 -> 1.3005767 | D7: =TEXT(C7,"0.00") -> 1.30 | E7: Q3_Q4_VaR
A8: 4 | B8: Conditional Value-at-Risk at the 90% level, monthly loss (%) | C8: =Q3_Q4_VaR!B85 -> 2.1618167 | D8: =TEXT(C8,"0.00") -> 2.16 | E8: Q3_Q4_VaR
A13: Column D shows the value already rounded exactly the way the submission guidelines ask for.

Sheet data
B1: Asset 1 | C1: Asset 2 | D1: Asset 3
A2: Mean return | B2: 6 | C2: 2 | D2: 4
A4: Covariance matrix
B5: Asset 1 | C5: Asset 2 | D5: Asset 3
A6: Asset 1 | B6: 0.008 | C6: -0.002 | D6: 0.004
A7: Asset 2 | B7: -0.002 | C7: 0.002 | D7: -0.002
A8: Asset 3 | B8: 0.004 | C8: -0.002 | D8: 0.008
A13: Interest rate | B13: 1
A15: Excess return | B15: =B2-rf -> 5 | C15: =C2-rf -> 1 | D15: =D2-rf -> 3
A17: Porfolio | B17: x1 | C17: x2 | D17: x3
B18: 1 | C18: 0 | D18: 0 | F18: = | G18: 1
A20: Rate of return (%) | B20: =SUMPRODUCT(B18:D18,B2:D2) -> 6
H21: {=TRANSPOSE(B17:D18)} -> x1 | I21: 1
A22: Volatility (%) | B22: =100*SQRT(MMULT(B18:D18,MMULT(B6:D8,I21:I23))) -> 8.9442719 | C22: <= | D22: 85.940286 | H22: x2 | I22: 0
H23: x3 | I23: 0

Sheet Monthly returns
A1: Asset 1 | B1: Asset 2 | C1: Asset 3 | E1: Estimated Mean
A2: 2.1675 | B2: -1.8883 | C2: 3.0712 | F2: Asset 1 | G2: Asset 2 | H2: Asset 3
A3: 3.3875 | B3: -0.5608 | C3: 1.2428 | F3: -0.51864 | G3: 4.70574 | H3: -0.69862
A4: -2.5194 | B4: 1.5773 | C4: -3.184
A5: -1.3959 | B5: 1.4225 | C5: 3.0923 | E5: Estimated Covariance matrix
A6: -2.7264 | B6: 1.0408 | C6: -0.0131 | F6: Asset 1 | G6: Asset 2 | H6: Asset 3
A7: 0.7832 | B7: 1.2914 | C7: -2.0597 | E7: Asset 1 | F7: 0.0056 | G7: -0.002 | H7: 0.0037
A8: 3.9749 | B8: -0.2969 | C8: 2.0496 | E8: Asset 2 | F8: -0.002 | G8: 0.0022 | H8: -0.0022
A9: -3.3869 | B9: 0.6602 | C9: -0.585 | E9: Asset 3 | F9: 0.0037 | G9: -0.0022 | H9: 0.0074
A10: -0.1714 | B10: 0.2207 | C10: 0.6504
A11: 0.5439 | B11: 0.3632 | C11: 1.0962 | F11: Asset 1 | G11: Asset 2 | H11: Asset 3
A12: 1.0913 | B12: 0.103 | C12: 2.7193 | E12: Volatility | F12: =100*SQRT(F7) -> 7.4833148 | G12: =100*SQRT(G8) -> 4.6904158 | H12: =100*SQRT(H9) -> 8.6023253
A13: -1.0361 | B13: -0.5964 | C13: -0.8361
A14: -0.871 | B14: 2.2177 | C14: -4.2316 | E14: Interest rate | F14: 1
A15: 1.0377 | B15: 0.2439 | C15: 1.624
A16: -2.7236 | B16: 2.7658 | C16: -3.2315 | E16: Excess return | F16: =F3-rf -> -1.51864 | G16: =G3-rf -> 3.70574 | H16: =H3-rf -> -1.69862
A17: 2.7485 | B17: -1.4885 | C17: 7.4063
A18: -0.8348 | B18: -1.3056 | C18: 0.3338 | E18: Porfolio | F18: x1 | G18: x2 | H18: x3 | I18: x0
A19: -1.2728 | B19: 2.2504 | C19: -4.3389 | F19: 0 | G19: 0 | H19: 0 | J19: =SUM(F19:I19) -> 0 | K19: = | L19: 1
A20: -0.5232 | B20: 1.8409 | C20: 1.5357
A21: 0.1174 | B21: 0.9127 | C21: -1.2732 | E21: Rate of return (%) | F21: =SUMPRODUCT(F19:H19,F3:H3)+F14*I19 -> 0
A22: 1.1843 | B22: 1.6094 | C22: -0.208 | M22: {=TRANSPOSE(F18:I19)} -> x1 | N22: 0
A23: 0.6003 | B23: -0.1249 | C23: -0.6808 | E23: Volatility (%) | F23: =100*SQRT(MMULT(F19:H19,MMULT(F7:H9,N22:N24))) -> 0 | G23: <= | H23: 5 | M23: x2 | N23: 0
A24: -0.5785 | B24: -0.2565 | C24: 1.451 | M24: x3 | N24: 0
A25: -1.8834 | B25: 0.5511 | C25: -1.5372 | M25: x0 | N25: 0
A26: 1.0666 | B26: -0.555 | C26: -1.0502
A27: 3.7147 | B27: 0.2948 | C27: 3.36
A28: -0.3213 | B28: 0.8969 | C28: -0.3788
A29: 1.3712 | B29: -0.6688 | C29: -0.1197
A30: -0.7987 | B30: -0.0603 | C30: -0.1823
A31: 0.949 | B31: -0.0582 | C31: -0.1217
A32: -2.5322 | B32: 3.4582 | C32: -4.8028
A33: 0.4613 | B33: 1.0112 | C33: -0.5589
A34: -1.6205 | B34: 0.7624 | C34: -0.5277
A35: 4.7482 | B35: -2.1118 | C35: 3.0093
A36: 1.6551 | B36: 0.6686 | C36: 1.0955
A37: -5.1563 | B37: 1.286 | C37: -2.0927
... A61: 4.9665 | B61: -2.4944 | C61: -0.2641
A63: =AVERAGE(A2:A61)*12 -> -0.51864 | B63: =AVERAGE(B2:B61)*12 -> 4.70574 | C63: =AVERAGE(C2:C61)*12 -> -0.69862

Sheet Value_at_risk
A1: Asset 1 | B1: Asset 2 | C1: Asset 3 | E1: Equally weighted loss
A2: 2.1675 | B2: -1.8883 | C2: 3.0712 | E2: =-SUM(A2:C2)/3 -> -1.1168
A3: 3.3875 | B3: -0.5608 | C3: 1.2428 | E3: =-SUM(A3:C3)/3 -> -1.3565
A4: -2.5194 | B4: 1.5773 | C4: -3.184 | E4: =-SUM(A4:C4)/3 -> 1.3753667
A5: -1.3959 | B5: 1.4225 | C5: 3.0923 | E5: =-SUM(A5:C5)/3 -> -1.0396333
A6: -2.7264 | B6: 1.0408 | C6: -0.0131 | E6: =-SUM(A6:C6)/3 -> 0.56623333
A7: 0.7832 | B7: 1.2914 | C7: -2.0597 | E7: =-SUM(A7:C7)/3 -> -0.0049666667
A8: 3.9749 | B8: -0.2969 | C8: 2.0496 | E8: =-SUM(A8:C8)/3 -> -1.9092
A9: -3.3869 | B9: 0.6602 | C9: -0.585 | E9: =-SUM(A9:C9)/3 -> 1.1039
A10: -0.1714 | B10: 0.2207 | C10: 0.6504 | E10: =-SUM(A10:C10)/3 -> -0.23323333
A11: 0.5439 | B11: 0.3632 | C11: 1.0962 | E11: =-SUM(A11:C11)/3 -> -0.66776667
A12: 1.0913 | B12: 0.103 | C12: 2.7193 | E12: =-SUM(A12:C12)/3 -> -1.3045333
A13: -1.0361 | B13: -0.5964 | C13: -0.8361 | E13: =-SUM(A13:C13)/3 -> 0.82286667
... A61: 4.9665 | B61: -2.4944 | C61: -0.2641 | E61: =-SUM(A61:C61)/3 -> -0.736

Sheet Q1_Q2_Portfolio
A1: Q1 & Q2 - Efficient portfolio with 5% volatility
A3: INPUTS (linked to the original sheets)
A4: Returns are in PERCENT (6 = 6%). Covariances are ANNUAL and in DECIMAL units, so volatility in % = 100*SQRT(x'Vx).
A5: Asset | B5: Asset 1 | C5: Asset 2 | D5: Asset 3
A6: Estimated annual mean return (%) mu_hat | B6: ='Monthly returns'!F3 -> -0.51864 | C6: ='Monthly returns'!G3 -> 4.70574 | D6: ='Monthly returns'!H3 -> -0.69862
A7: TRUE annual mean return (%) mu | B7: =data!B2 -> 6 | C7: =data!C2 -> 2 | D7: =data!D2 -> 4
A8: Risk-free rate rf (%) | B8: ='Monthly returns'!F14 -> 1
A9: Target volatility (%) | B9: 5
A11: ESTIMATED covariance matrix V_hat (annual)
A12: Asset 1 | B12: ='Monthly returns'!F7 -> 0.0056 | C12: ='Monthly returns'!G7 -> -0.002 | D12: ='Monthly returns'!H7 -> 0.0037
A13: Asset 2 | B13: ='Monthly returns'!F8 -> -0.002 | C13: ='Monthly returns'!G8 -> 0.0022 | D13: ='Monthly returns'!H8 -> -0.0022
A14: Asset 3 | B14: ='Monthly returns'!F9 -> 0.0037 | C14: ='Monthly returns'!G9 -> -0.0022 | D14: ='Monthly returns'!H9 -> 0.0074
A16: TRUE covariance matrix V (annual)
A17: Asset 1 | B17: =data!B6 -> 0.008 | C17: =data!C6 -> -0.002 | D17: =data!D6 -> 0.004
A18: Asset 2 | B18: =data!B7 -> -0.002 | C18: =data!C7 -> 0.002 | D18: =data!D7 -> -0.002
A19: Asset 3 | B19: =data!B8 -> 0.004 | C19: =data!C8 -> -0.002 | D19: =data!D8 -> 0.008
A21: METHOD A - CLOSED FORM (no Solver needed)
A22: With a risk-free asset every efficient portfolio is x = k * V^-1 (mu - rf), i.e. a scaled copy of the tangency portfolio. Pick k so the volatility equals the target.
A24: Excess return e = mu_hat - rf (%) | B24: =B6-$B$8 -> -1.51864 | C24: =C6-$B$8 -> 3.70574 | D24: =D6-$B$8 -> -1.69862
A26: Inverse of V_hat
B27: =INDEX(MINVERSE($B$12:$D$14),1,1) -> 309.9767 | C27: =INDEX(MINVERSE($B$12:$D$14),1,2) -> 180.45846 | D27: =INDEX(MINVERSE($B$12:$D$14),1,3) -> -101.33854
B28: =INDEX(MINVERSE($B$12:$D$14),2,1) -> 180.45846 | C28: =INDEX(MINVERSE($B$12:$D$14),2,2) -> 751.91026 | D28: =INDEX(MINVERSE($B$12:$D$14),2,3) -> 133.31166
B29: =INDEX(MINVERSE($B$12:$D$14),3,1) -> -101.33854 | C29: =INDEX(MINVERSE($B$12:$D$14),3,2) -> 133.31166 | D29: =INDEX(MINVERSE($B$12:$D$14),3,3) -> 225.4376
A31: z = V_hat^-1 * e (unscaled tangency direction) | B31: =SUMPRODUCT(B27:D27,$B$24:$D$24) -> 370.12479 | C31: =SUMPRODUCT(B28:D28,$B$24:$D$24) -> 2285.8866 | D31: =SUMPRODUCT(B29:D29,$B$24:$D$24) -> 264.98228
A32: z'V_hat z = z'e | B32: =SUMPRODUCT(B31:D31,B24:D24) -> 7458.711 | C32: (because V z = e)
A33: Volatility of z (%) | B33: =100*SQRT(B32) -> 8636.3829
A34: Scale factor k = target vol / vol(z) | B34: =$B$9/B33 -> 0.00057894607
A36: OPTIMAL WEIGHTS
B37: x1 | C37: x2 | D37: x3 | E37: x0 (risk-free)
A38: x = k * z | B38: =$B$34*B31 -> 0.2142823 | C38: =$B$34*C31 -> 1.3234051 | D38: =$B$34*D31 -> 0.15341045 | E38: =1-SUM(B38:D38) -> -0.69109784
A40: V_hat * x | B40: =SUMPRODUCT(B12:D12,$B$38:$D$38) -> -0.00087921067 | C40: =SUMPRODUCT(B13:D13,$B$38:$D$38) -> 0.0021454236 | D40: =SUMPRODUCT(B14:D14,$B$38:$D$38) -> -0.00098340938
A41: Estimated volatility (%) = 100*SQRT(x'V_hat x) | B41: =100*SQRT(SUMPRODUCT(B38:D38,B40:D40)) -> 5 | C41: must equal the 5% target
A43: V_true * x | B43: =SUMPRODUCT(B17:D17,$B$38:$D$38) -> -0.00031891002 | C43: =SUMPRODUCT(B18:D18,$B$38:$D$38) -> 0.0019114247 | D43: =SUMPRODUCT(B19:D19,$B$38:$D$38) -> -0.0005623974
A44: TRUE volatility (%) = 100*SQRT(x'V x) | B44: =100*SQRT(SUMPRODUCT(B38:D38,B43:D43)) -> 4.8733713 | C44: the realised risk differs from the 5% we aimed at
A46: ANSWERS
A47: Q1 Estimated return of the 5%-vol efficient portfolio (%) | B47: =SUMPRODUCT(B38:D38,B6:D6)+E38*B8 -> 5.3181915 | C47: submit rounded to 2 dp
A48: Q2 TRUE expected return of that same portfolio (%) | B48: =SUMPRODUCT(B38:D38,B7:D7)+E38*B8 -> 3.8550479 | C48: same weights, true mu
A50: Q1 uses the estimated mu_hat from the 60 simulated months; Q2 re-prices the identical weights with the true mu = (6%, 2%, 4%). The gap is estimation error.
A52: METHOD B - SOLVER SET-UP (same problem, Excel Solver)
A53: Yellow = changing cells, orange = constraint. The starting point below is 'everything in the risk-free asset', which is feasible. Run Solver more than once, each time restarting from the previous result, until the answer stops moving.
...

Sheet Q3_Q4_VaR
A1: Q3 & Q4 - Historical Value-at-Risk and Conditional VaR (90%)
A3: LOSS DATA (linked to the 'Value_at_risk' sheet, column E)
A4: Loss_t = -(r1+r2+r3)/3 : the monthly rate of loss on the equally weighted portfolio of the three risky assets. 60 observations.
A6: Month | B6: Loss (%) | C6: Loss sorted ascending
A7: 1 | B7: =Value_at_risk!E2 -> -1.1168 | C7: =SMALL($B$7:$B$66,1) -> -2.8887667
A8: 2 | B8: =Value_at_risk!E3 -> -1.3565 | C8: =SMALL($B$7:$B$66,2) -> -2.4565
A9: 3 | B9: =Value_at_risk!E4 -> 1.3753667 | C9: =SMALL($B$7:$B$66,3) -> -2.0568667
A10: 4 | B10: =Value_at_risk!E5 -> -1.0396333 | C10: =SMALL($B$7:$B$66,4) -> -1.9092
A11: 5 | B11: =Value_at_risk!E6 -> 0.56623333 | C11: =SMALL($B$7:$B$66,5) -> -1.8819
A12: 6 | B12: =Value_at_risk!E7 -> -0.0049666667 | C12: =SMALL($B$7:$B$66,6) -> -1.4915667
A13: 7 | B13: =Value_at_risk!E8 -> -1.9092 | C13: =SMALL($B$7:$B$66,7) -> -1.3565
A14: 8 | B14: =Value_at_risk!E9 -> 1.1039 | C14: =SMALL($B$7:$B$66,8) -> -1.3045333
A15: 9 | B15: =Value_at_risk!E10 -> -0.23323333 | C15: =SMALL($B$7:$B$66,9) -> -1.2639333
A16: 10 | B16: =Value_at_risk!E11 -> -0.66776667 | C16: =SMALL($B$7:$B$66,10) -> -1.1397333
A17: 11 | B17: =Value_at_risk!E12 -> -1.3045333 | C17: =SMALL($B$7:$B$66,11) -> -1.1168
A18: 12 | B18: =Value_at_risk!E13 -> 0.82286667 | C18: =SMALL($B$7:$B$66,12) -> -1.0396333
A19: 13 | B19: =Value_at_risk!E14 -> 0.96163333 | C19: =SMALL($B$7:$B$66,13) -> -0.96853333
A20: 14 | B20: =Value_at_risk!E15 -> -0.96853333 | C20: =SMALL($B$7:$B$66,14) -> -0.95113333
A21: 15 | B21: =Value_at_risk!E16 -> 1.0631 | C21: =SMALL($B$7:$B$66,15) -> -0.93953333
A22: 16 | B22: =Value_at_risk!E17 -> -2.8887667 | C22: =SMALL($B$7:$B$66,16) -> -0.86986667
A23: 17 | B23: =Value_at_risk!E18 -> 0.6022 | C23: =SMALL($B$7:$B$66,17) -> -0.8619
A24: 18 | B24: =Value_at_risk!E19 -> 1.1204333 | C24: =SMALL($B$7:$B$66,18) -> -0.736
A25: 19 | B25: =Value_at_risk!E20 -> -0.95113333 | C25: =SMALL($B$7:$B$66,19) -> -0.66776667
A26: 20 | B26: =Value_at_risk!E21 -> 0.081033333 | C26: =SMALL($B$7:$B$66,20) -> -0.60766667
A27: 21 | B27: =Value_at_risk!E22 -> -0.8619 | C27: =SMALL($B$7:$B$66,21) -> -0.5114
A28: 22 | B28: =Value_at_risk!E23 -> 0.068466667 | C28: =SMALL($B$7:$B$66,22) -> -0.45506667
A29: 23 | B29: =Value_at_risk!E24 -> -0.20533333 | C29: =SMALL($B$7:$B$66,23) -> -0.39243333
A30: 24 | B30: =Value_at_risk!E25 -> 0.9565 | C30: =SMALL($B$7:$B$66,24) -> -0.30453333
A31: 25 | B31: =Value_at_risk!E26 -> 0.17953333 | C31: =SMALL($B$7:$B$66,25) -> -0.27586667
A32: 26 | B32: =Value_at_risk!E27 -> -2.4565 | C32: =SMALL($B$7:$B$66,26) -> -0.27556667
A33: 27 | B33: =Value_at_risk!E28 -> -0.0656 | C33: =SMALL($B$7:$B$66,27) -> -0.27216667
A34: 28 | B34: =Value_at_risk!E29 -> -0.19423333 | C34: =SMALL($B$7:$B$66,28) -> -0.25636667
A35: 29 | B35: =Value_at_risk!E30 -> 0.3471 | C35: =SMALL($B$7:$B$66,29) -> -0.23323333
A36: 30 | B36: =Value_at_risk!E31 -> -0.25636667 | C36: =SMALL($B$7:$B$66,30) -> -0.20533333
A37: 31 | B37: =Value_at_risk!E32 -> 1.2922667 | C37: =SMALL($B$7:$B$66,31) -> -0.19423333
A38: 32 | B38: =Value_at_risk!E33 -> -0.30453333 | C38: =SMALL($B$7:$B$66,32) -> -0.095966667
A39: 33 | B39: =Value_at_risk!E34 -> 0.46193333 | C39: =SMALL($B$7:$B$66,33) -> -0.0656
A40: 34 | B40: =Value_at_risk!E35 -> -1.8819 | C40: =SMALL($B$7:$B$66,34) -> -0.041166667
A41: 35 | B41: =Value_at_risk!E36 -> -1.1397333 | C41: =SMALL($B$7:$B$66,35) -> -0.021833333
A42: 36 | B42: =Value_at_risk!E37 -> 1.9876667 | C42: =SMALL($B$7:$B$66,36) -> -0.0049666667
...

Sheet Q5_Q7_Probability
A1: Q5, Q6, Q7 - Track records and the 4-door Monty Hall problem
A3: Q5 - one manager, 12 successes out of 15
A4: Under 'no skill' the number of good years X ~ Binomial(n = 15, p = 0.5). We want P(X >= 12) = 1 - P(X <= 11).
A6: Years n | B6: 15
A7: Success probability p | B7: 0.5
A8: Observed successes k | B8: 12
A10: Q5 P(X >= 12) | B10: =1-BINOMDIST(B8-1,B6,B7,TRUE()) -> 0.017578125 | C10: submit to 4 dp
A11: long-hand check: sum of C(15,k)/2^15 for k = 12..15 | B11: =SUMPRODUCT(COMBIN(B6,ROW(INDIRECT(B8&":"&B6))))/2^B6 -> 0.017578125
A14: Q6 - best of M = 100 managers, 14 successes out of 15
A15: A single no-skill manager beats the market 14+ times with probability q. The 100 managers are independent, so P(at least one does it) = 1 - (1-q)^100. This is the multiple-comparisons / data-snooping effect.
A17: Number of managers M | B17: 100
A18: Observed successes k | B18: 14
A19: q = P(one manager gets >= 14) | B19: =1-BINOMDIST(B18-1,B6,B7,TRUE()) -> 0.00048828125
A20: P(none of the M reaches it) = (1-q)^M | B20: =(1-B19)^B17 -> 0.95233344
A22: Q6 P(best of 100 has >= 14 out of 15) | B22: =1-B20 -> 0.047666557 | C22: submit to 4 dp
A24: Note how a 0.05% event for one manager becomes a 4.8% event once you go looking for the best of a hundred.
A27: Q7 - Monty Hall with 4 doors, 2 prizes, 2 goats
A28: Monty always opens a door with a goat that you did not pick, then you may move to one of the 2 remaining unopened doors. Compare STAY against SWITCH.
A30: Doors | B30: 4
A31: Prizes | B31: 2
A33: Case | B33: Probability | C33: Unopened others: prizes | D33: Unopened others: goats | E33: P(win | switch)
A34: Your first door hides a PRIZE | B34: =B31/B30 -> 0.5 | C34: =B31-1 -> 1 | D34: =B30-B31-1 -> 1 | E34: =C34/(C34+D34) -> 0.5
A35: Your first door hides a GOAT | B35: =(B30-B31)/B30 -> 0.5 | C35: =B31 -> 2 | D35: =B30-B31-2 -> 0 | E35: =C35/(C35+D35) -> 1
A37: P(win | STAY) = P(first door is a prize) | B37: =B31/B30 -> 0.5
A38: P(win | SWITCH) = sum of prob x P(win|switch) | B38: =SUMPRODUCT(B34:B35,E34:E35) -> 0.75
A40: Q7 P(win) playing optimally = MAX(stay, switch) | B40: =MAX(B37,B38) -> 0.75 | C40: submit to 2 dp - switching is optimal
A42: If your door is a prize (prob 1/2) the 2 remaining doors hold 1 prize and 1 goat, so switching wins half the time. If your door is a goat (prob 1/2) Monty removed the only other goat, so both remaining doors are prizes and switching always wins: 1/2 x 1/2 + 1/2 x 1 = 3/4.
