Workbook

Sheet Daily_Returns_Q1_Q2
A1: date | B1: IBM | C1: GE | D1: LLY | E1: F | F1: BAC | G1: KR | H1: ITUB | I1: GG | J1: SIRI | K1: ACB | L1: VALE | M1: PFE | N1: CTL | O1: T | P1: ECA | Q1: ABEV | R1: CVS | S1: MRVL | T1: CSCO | U1: MO | V1: BMY | W1: WFC | X1: HBAN
A2: 42373 | B2: -0.00073576783 | C2: 0.00097635896 | D2: 0.014852325 | E2: -0.018057551 | F2: 0 | G2: 0.022343279 | H2: 0.0080064403 | I2: -0.023028694 | J2: -0.010178195 | K2: 0.046628518 | L2: -0.0031695716 | M2: 0.0071729463 | N2: -0.0047904618 | O2: 0.0069626531 | P2: 0.026924677 | Q2: 0.013953702 | R2: 0.0028985402 | S2: -0.032335349 | T2: -0.004554047 | U2: 0.020011016 | V2: 0.019501279 | W2: -0.00037808049 | X2: 0.0018674569
A3: 42374 | B3: -0.0050181489 | C3: -0.016068534 | D3: -0.0063211943 | E3: -0.04547937 | F3: -0.021532692 | G3: -0.00095081813 | H3: -0.0080064403 | I3: 0.018803995 | J3: -0.0051282114 | K3: -0.0068572177 | L3: -0.079249372 | M3: -0.017871606 | N3: -0.010863131 | O3: -0.015440912 | P3: -0.062642821 | Q3: -0.011614466 | R3: -0.012272648 | S3: -0.056744279 | T3: -0.010707585 | U3: 0.010533549 | V3: -0.017712595 | W3: -0.019280894 | X3: -0.015985303
A4: 42375 | B4: -0.017237285 | C4: -0.043235336 | D4: -0.026306118 | E4: -0.031773293 | F4: -0.036736235 | G4: -0.023581448 | H4: -0.031022866 | I4: 0.074228913 | J4: -0.01293684 | K4: -0.061485068 | L4: -0.071204462 | M4: -0.0066656648 | N4: -0.020433895 | O4: -0.016279864 | P4: -0.049699622 | Q4: -0.040529998 | R4: -0.014546449 | S4: 0.0098888225 | T4: -0.023338297 | U4: -0.017560741 | V4: -0.028090046 | W4: -0.028942175 | X4: -0.030801343
A5: 42376 | B5: -0.0093009533 | C5: -0.018112651 | D5: -0.0019673394 | E5: -0.012678446 | F5: -0.019544609 | G5: -0.0065958578 | H5: 0 | I5: -0.018247273 | J5: -0.0078431701 | K5: 0.026475692 | L5: -0.041437241 | M5: -0.012820676 | N5: -0.01037569 | O5: 0.00089493203 | P5: 0.03750436 | Q5: 0.016888144 | R5: -0.0066049324 | S5: 0.011009304 | T5: -0.025105887 | U5: 0.0017185481 | V5: -0.025753825 | W5: -0.016807121 | X5: -0.017751882
A6: 42377 | B6: 0.012081932 | C6: 0.0045590118 | D6: -0.012134911 | E6: 0.018175174 | F6: 0.0072108218 | G6: 0.011696029 | H6: -0.0016597498 | I6: -0.05598164 | J6: 0.002621231 | K6: -0.0023781627 | L6: -0.023347342 | M6: 0.0022555091 | N6: 0.0062383869 | O6: 0.012150093 | P6: -0.035383521 | Q6: -0.016888144 | R6: 0.014431497 | S6: 0.012091977 | T6: 0.019581036 | U6: 0.020731369 | V6: -0.010267866 | W6: 0.010637306 | X6: 0.0049628081
A7: 42380 | B7: -0.0024800061 | C7: 0.0020971429 | D7: 0.0016182848 | E7: 0.0062451351 | F7: 0 | G7: -0.00096939175 | H7: 0.014839499 | I7: -0.031830716 | J7: -0.0078843961 | K7: 0.011834517 | L7: -0.069274159 | M7: -0.0022555091 | N7: -0.030305401 | O7: -0.0014738171 | P7: -0.032295513 | Q7: 0.021661419 | R7: 0.008079413 | S7: 0.019048178 | T7: 0.0031608056 | U7: -0.0013463148 | V7: 0.0072773473 | W7: 0.025038281 | X7: 0.0078895795
A8: 42381 | B8: -0.013102742 | C8: -0.014064913 | D8: -0.013776028 | E8: -0.051907905 | F8: -0.02714505 | G8: -0.050731934 | H8: -0.024856334 | I8: -0.024780006 | J8: -0.021334122 | K8: -0.035932046 | L8: -0.060888313 | M8: -0.020531898 | N8: -0.016372583 | O8: -0.0047309325 | P8: -0.079678164 | Q8: -0.014388724 | R8: -0.016649508 | S8: -0.022660431 | T8: -0.030032287 | U8: -0.027314813 | V8: -0.03464105 | W8: -0.032251308 | X8: -0.043157756
A9: 42382 | B9: 0.013178057 | C9: 0.02862325 | D9: 0.040044868 | E9: -0.00082002704 | F9: 0.0060221095 | G9: -0.0043462163 | H9: 0.021577646 | I9: -0.067649645 | J9: 0.0026917891 | K9: -0.034742945 | L9: 0.089996469 | M9: 0.024074024 | N9: 0.037096513 | O9: 0.016461205 | P9: -0.023981943 | Q9: 0.021506242 | R9: 0.014766659 | S9: 0.0060132701 | T9: 0.0024360331 | U9: 0.0075862854 | V9: 0.035743842 | W9: 0.018133402 | X9: 0.010204209
A10: 42383 | B10: -0.021907051 | C10: -0.019809568 | D10: -0.015875325 | E10: -0.018212367 | F10: -0.035997077 | G10: -0.013932039 | H10: -0.041917311 | I10: -0.010602568 | J10: -0.024490996 | K10: -0.070617595 | L10: -0.029108156 | M10: -0.0096900353 | N10: -0.025435813 | O10: -0.0090789188 | P10: -0.11022666 | Q10: -0.041019038 | R10: -0.017000574 | S10: -0.027965409 | T10: -0.043088645 | U10: -0.017675048 | V10: -0.011560815 | W10: -0.036601707 | X10: -0.02779391
A11: 42384 | B11: -0.014875909 | C11: 0 | D11: 0.02420019 | E11: -0.0016722795 | F11: -0.015331329 | G11: -0.0078248456 | H11: -0.013793309 | I11: -0.047628004 | J11: 0.0082304911 | K11: 0.037238343 | L11: -0.017021672 | M11: -0.0039024092 | N11: -0.0030101765 | O11: 0.015182675 | P11: -0.12083649 | Q11: 0.017094475 | R11: 0.012277843 | S11: -0.042827664 | T11: 0.009690387 | U11: 0.020762004 | V11: 0.00682597 | W11: -0.012573609 | X11: -0.010493316
A12: 42388 | B12: -0.050016425 | C12: -0.017348617 | D12: -0.0073560849 | E12: -0.0041928944 | F12: -0.039389281 | G12: -0.0089427257 | H12: -0.015748342 | I12: 0.0020304072 | J12: -0.016529352 | K12: -0.042673069 | L12: 0 | M12: -0.00097801757 | N12: -0.043121488 | O12: -0.017834029 | P12: 0.067972989 | Q12: -0.024511007 | R12: -0.0099376525 | S12: 0.017857601 | T12: -0.040647339 | U12: -0.020412407 | V12: 0.0053644836 | W12: -0.0070774683 | X12: -0.023480195
A13: 42389 | B13: 0.0085795602 | C13: 0.020852523 | D13: -0.014876523 | E13: 0.0092012871 | F13: -0.024400466 | G13: -0.018667127 | H13: -0.032260902 | I13: -0.0040650425 | J13: 0.016529352 | K13: -0.0054645054 | L13: -0.057410853 | M13: -0.0026126705 | N13: 0.016942049 | O13: 0.01870304 | P13: 0.087487437 | Q13: -0.037931245 | R13: 0.0038176144 | S13: 0.024970063 | T13: 0 | U13: 0.0040115086 | V13: -0.0066308763 | W13: 0.0029203065 | X13: -0.028479496
... A503: 43097 | B503: -0.0040330188 | C503: 0.0051709304 | D503: -0.0069613161 | E503: -0.0071799394 | F503: -0.0094403527 | G503: -0.0072595184 | H503: 0.0053992146 | I503: 0.0047096177 | J503: -0.0037243955 | K503: 0.062182195 | L503: 0.0040966249 | M503: -0.0041327435 | N503: -0.026037005 | O503: -0.0076864132 | P503: 0.00075048627 | Q503: 0.0062111941 | R503: -0.0075576181 | S503: -0.019373304 | T503: -0.0075433032 | U503: 0.0019625324 | V503: -0.0079643116 | W503: -0.010330519 | X503: -0.0122868

Sheet Optimal_Portfolio_Q3-Q8
A1: Optimal Portfolio Calculation--Cells in Yellow Are Not Optimal nor Correct, So You Need to Compute By Yourself
A3: COVARIANCE MATRIX | B3: IBM | C3: GE | D3: LLY | E3: F | F3: BAC | G3: KR | H3: ITUB | I3: GG | J3: SIRI | K3: ACB | L3: VALE | M3: PFE | N3: CTL | O3: T | P3: ECA | Q3: ABEV | R3: CVS | S3: MRVL | T3: CSCO | U3: MO | V3: BMY | W3: WFC | X3: HBAN
A4: IBM | B4: 0.000127 | C4: =_xlfn.COVARIANCE.S(Daily_Returns_Q1_Q2!B2:B503,Daily_Returns_Q1_Q2!C2:C503) | D4: 1.9e-05 | E4: 5.5e-05 | F4: 7e-05 | G4: 5e-06 | H4: 7.3e-05 | I4: 1.1e-05 | J4: 3.2e-05 | K4: 3.1e-05 | L4: 0.000104 | M4: 2.2e-05 | N4: 3.5e-05 | O4: 2.4e-05 | P4: 8.4e-05 | Q4: 4.6e-05 | R4: 2e-05 | S4: 5.8e-05 | T4: 4.7e-05 | U4: 1.6e-05 | V4: 1.4e-05 | W4: 5e-05 | X4: 6.9e-05
A5: GE | B5: =C4 | C5: 0.000139 | D5: 2.2e-05 | E5: 7e-05 | F5: 8.7e-05 | G5: 1.5e-05 | H5: 8.4e-05 | I5: -2.6e-05 | J5: 3.9e-05 | K5: -1.4e-05 | L5: 0.000137 | M5: 2.9e-05 | N5: 5.1e-05 | O5: 3.9e-05 | P5: 8.5e-05 | Q5: 4.8e-05 | R5: 3.9e-05 | S5: 5.1e-05 | T5: 4.1e-05 | U5: 2e-05 | V5: 3.2e-05 | W5: 6.2e-05 | X5: 7.6e-05
A6: LLY | B6: 1.9e-05 | C6: 2.2e-05 | D6: 0.000163 | E6: 3e-05 | F6: 4.1e-05 | G6: 2e-05 | H6: 3e-05 | I6: 1.1e-05 | J6: 2.6e-05 | K6: 1.1e-05 | L6: 5.1e-05 | M6: 5.3e-05 | N6: 3.3e-05 | O6: 2e-05 | P6: 1.9e-05 | Q6: 2.7e-05 | R6: 2.9e-05 | S6: 2.5e-05 | T6: 3.4e-05 | U6: 1.4e-05 | V6: 7.1e-05 | W6: 3.1e-05 | X6: 3e-05
A7: F | B7: 5.5e-05 | C7: 7e-05 | D7: 3e-05 | E7: 0.000204 | F7: 0.000127 | G7: 3.5e-05 | H7: 9.2e-05 | I7: -4e-06 | J7: 7.1e-05 | K7: 2.6e-05 | L7: 0.000193 | M7: 3.5e-05 | N7: 7.5e-05 | O7: 3.2e-05 | P7: 0.000152 | Q7: 5.1e-05 | R7: 3.3e-05 | S7: 8.9e-05 | T7: 6.5e-05 | U7: 1.1e-05 | V7: 5.5e-05 | W7: 9.4e-05 | X7: 0.000115
A8: BAC | B8: 7e-05 | C8: 8.7e-05 | D8: 4.1e-05 | E8: 0.000127 | F8: 0.000296 | G8: 5.8e-05 | H8: 0.000129 | I8: -0.000121 | J8: 8.5e-05 | K8: 4.4e-05 | L8: 0.000257 | M8: 5.3e-05 | N8: 7.4e-05 | O8: 1.9e-05 | P8: 0.000214 | Q8: 7.2e-05 | R8: 4.5e-05 | S8: 0.000103 | T8: 6.9e-05 | U8: -9e-06 | V8: 4e-05 | W8: 0.000175 | X8: 0.000233
A9: KR | B9: 5e-06 | C9: 1.5e-05 | D9: 2e-05 | E9: 3.5e-05 | F9: 5.8e-05 | G9: 0.000366 | H9: -1.6e-05 | I9: -2.4e-05 | J9: 3e-05 | K9: 4.2e-05 | L9: 1.9e-05 | M9: 2.1e-05 | N9: 6.5e-05 | O9: 1.5e-05 | P9: 4.9e-05 | Q9: 1.6e-05 | R9: 6.3e-05 | S9: 3.8e-05 | T9: 2.6e-05 | U9: 9e-06 | V9: 2.8e-05 | W9: 4.2e-05 | X9: 4.3e-05
A10: ITUB | B10: 7.3e-05 | C10: 8.4e-05 | D10: 3e-05 | E10: 9.2e-05 | F10: 0.000129 | G10: -1.6e-05 | H10: 0.000701 | I10: 0.00013 | J10: 7e-05 | K10: 9.9e-05 | L10: 0.000529 | M10: 1.2e-05 | N10: 0.000106 | O10: 5.2e-05 | P10: 0.000294 | Q10: 0.00034 | R10: 3.8e-05 | S10: 0.000127 | T10: 0.000113 | U10: 5e-05 | V10: 6.3e-05 | W10: 6.8e-05 | X10: 0.000106
A11: GG | B11: 1.1e-05 | C11: -2.6e-05 | D11: 1.1e-05 | E11: -4e-06 | F11: -0.000121 | G11: -2.4e-05 | H11: 0.00013 | I11: 0.000642 | J11: -3e-06 | K11: -5.8e-05 | L11: 0.000235 | M11: -1.7e-05 | N11: 5.4e-05 | O11: 3e-05 | P11: 0.000148 | Q11: 9e-05 | R11: -1.5e-05 | S11: 9e-06 | T11: 1.4e-05 | U11: 1.2e-05 | V11: 1.6e-05 | W11: -7.9e-05 | X11: -0.00011
A12: SIRI | B12: 3.2e-05 | C12: 3.9e-05 | D12: 2.6e-05 | E12: 7.1e-05 | F12: 8.5e-05 | G12: 3e-05 | H12: 7e-05 | I12: -3e-06 | J12: 0.000169 | K12: 5.2e-05 | L12: 0.000121 | M12: 2.1e-05 | N12: 6.1e-05 | O12: 2.9e-05 | P12: 9.4e-05 | Q12: 4.8e-05 | R12: 2e-05 | S12: 7.6e-05 | T12: 4.7e-05 | U12: 1.9e-05 | V12: 1.8e-05 | W12: 5.7e-05 | X12: 6.3e-05
A13: ACB | B13: 3.1e-05 | C13: -1.4e-05 | D13: 1.1e-05 | E13: 2.6e-05 | F13: 4.4e-05 | G13: 4.2e-05 | H13: 9.9e-05 | I13: -5.8e-05 | J13: 5.2e-05 | K13: 0.002376 | L13: 0.000164 | M13: 2e-05 | N13: 2.3e-05 | O13: -6e-06 | P13: 0.000149 | Q13: 0.000103 | R13: 3.6e-05 | S13: 6.6e-05 | T13: 4.5e-05 | U13: 1.9e-05 | V13: -1.8e-05 | W13: 2.5e-05 | X13: 5.7e-05
A14: VALE | B14: 0.000104 | C14: 0.000137 | D14: 5.1e-05 | E14: 0.000193 | F14: 0.000257 | G14: 1.9e-05 | H14: 0.000529 | I14: 0.000235 | J14: 0.000121 | K14: 0.000164 | L14: 0.001406 | M14: 3.9e-05 | N14: 0.000184 | O14: 5.8e-05 | P14: 0.000536 | Q14: 0.000326 | R14: 4.6e-05 | S14: 0.000174 | T14: 0.000129 | U14: 1.8e-05 | V14: 8.5e-05 | W14: 0.000159 | X14: 0.000218
A15: PFE | B15: 2.2e-05 | C15: 2.9e-05 | D15: 5.3e-05 | E15: 3.5e-05 | F15: 5.3e-05 | G15: 2.1e-05 | H15: 1.2e-05 | I15: -1.7e-05 | J15: 2.1e-05 | K15: 2e-05 | L15: 3.9e-05 | M15: 9.5e-05 | N15: 2.4e-05 | O15: 1.4e-05 | P15: 1e-05 | Q15: 2.1e-05 | R15: 3.9e-05 | S15: 2.8e-05 | T15: 2.8e-05 | U15: 4e-06 | V15: 5.6e-05 | W15: 4.6e-05 | X15: 5.2e-05
A16: CTL | B16: 3.5e-05 | C16: 5.1e-05 | D16: 3.3e-05 | E16: 7.5e-05 | F16: 7.4e-05 | G16: 6.5e-05 | H16: 0.000106 | I16: 5.4e-05 | J16: 6.1e-05 | K16: 2.3e-05 | L16: 0.000184 | M16: 2.4e-05 | N16: 0.000455 | O16: 5.9e-05 | P16: 0.000162 | Q16: 8.2e-05 | R16: 3e-05 | S16: 5.8e-05 | T16: 8.2e-05 | U16: 3.4e-05 | V16: 4e-05 | W16: 5.5e-05 | X16: 5.1e-05
A17: T | B17: 2.4e-05 | C17: 3.9e-05 | D17: 2e-05 | E17: 3.2e-05 | F17: 1.9e-05 | G17: 1.5e-05 | H17: 5.2e-05 | I17: 3e-05 | J17: 2.9e-05 | K17: -6e-06 | L17: 5.8e-05 | M17: 1.4e-05 | N17: 5.9e-05 | O17: 0.000105 | P17: 4.5e-05 | Q17: 3.7e-05 | R17: 1.9e-05 | S17: 1.3e-05 | T17: 2.4e-05 | U17: 3.4e-05 | V17: 1.1e-05 | W17: 2e-05 | X17: 2e-05
... A26: HBAN | B26: 6.9e-05 | C26: 7.6e-05 | D26: 3e-05 | E26: 0.000115 | F26: 0.000233 | G26: 4.3e-05 | H26: 0.000106 | I26: -0.00011 | J26: 6.3e-05 | K26: 5.7e-05 | L26: 0.000218 | M26: 5.2e-05 | N26: 5.1e-05 | O26: 2e-05 | P26: 0.000163 | Q26: 5.4e-05 | R26: 4.7e-05 | S26: 9.5e-05 | T26: 5.4e-05 | U26: -1e-05 | V26: 3.6e-05 | W26: 0.000165 | X26: 0.000295
B30: IBM | C30: GE | D30: LLY | E30: F | F30: BAC | G30: KR | H30: ITUB | I30: GG | J30: SIRI | K30: ACB | L30: VALE | M30: PFE | N30: CTL | O30: T | P30: ECA | Q30: ABEV | R30: CVS | S30: MRVL | T30: CSCO | U30: MO | V30: BMY | W30: WFC | X30: HBAN
A31: Average_Daily_Returns | B31: 0.000241 | C31: =AVERAGE(Daily_Returns_Q1_Q2!C2:C503) | D31: 3.8e-05 | E31: -0.000223 | F31: 0.001167 | G31: -0.000807 | H31: 0.001658 | I31: 0.000147 | J31: 0.000608 | K31: 0.005781 | L31: 0.002696 | M31: 0.00025 | N31: -0.000815 | O31: 0.000247 | P31: 0.001902 | Q31: 0.000825 | R31: -0.000569 | S31: 0.001777 | T31: 0.00074 | U31: 0.000435 | V31: -0.000179 | W31: 0.000273 | X31: 0.000614
B33: IBM | C33: GE | D33: LLY | E33: F | F33: BAC | G33: KR | H33: ITUB | I33: GG | J33: SIRI | K33: ACB | L33: VALE | M33: PFE | N33: CTL | O33: T | P33: ECA | Q33: ABEV | R33: CVS | S33: MRVL | T33: CSCO | U33: MO | V33: BMY | W33: WFC | X33: HBAN
A34: Percentage_Portfolio_Allocation_1 | B34: 0.089023557 | C34: -0.020725238 | D34: 0.02362748 | E34: -0.043433669 | F34: 0.058478954 | G34: 0.022396137 | H34: -0.024999679 | I34: 0.070482263 | J34: 0.065180425 | K34: 0.019914185 | L34: -0.02437887 | M34: 0.17286329 | N34: -0.035327997 | O34: 0.14679367 | P34: 0.0043730752 | Q34: 0.022322851 | R34: 0.032272739 | S34: 0.03501936 | T34: 0.061743817 | U34: 0.23273382 | V34: 0.044561079 | W34: 0.030124678 | X34: 0.016954067
A38: Portfolio_Expected_Returns | B38: =SUMPRODUCT(B31:X31,B34:X34)
A39: Total_Wealth | B39: =SUM(B34:X34)
A40: Portfolio_Variance | B40: =SUMPRODUCT(B34:X34,MMULT(B34:X34,B4:X26))
A42: Q4: Expected return of x1 (= B38 above) — equal to 0.05%, the constraint binds
A44: Q5: Percentage_Portfolio_Allocation_2 (x2, target mean >= 0.0008)
B45: 0.084928244 | C45: -0.089604703 | D45: 0.012974617 | E45: -0.065535851 | F45: 0.10546914 | G45: 0.0094669131 | H45: -0.021141524 | I45: 0.069525783 | J45: 0.067590355 | K45: 0.028724255 | L45: -0.01578853 | M45: 0.19202727 | N45: -0.050503554 | O45: 0.17399892 | P45: 0.006206528 | Q45: 0.013683083 | R45: 0.021684799 | S45: 0.051551779 | T45: 0.083276946 | U45: 0.25651009 | V45: 0.044236638 | W45: 0.012520617 | X45: 0.0081981893
A47: Portfolio_Expected_Returns_2 | B47: =SUMPRODUCT(B31:X31,B45:X45)
A48: Total_Wealth_2 | B48: =SUM(B45:X45)
A49: Portfolio_Variance_2 [Q5 answer] | B49: =SUMPRODUCT(B45:X45,MMULT(B45:X45,B4:X26))
A52: Q6: Percentage_Portfolio_Allocation_3 (x3, target mean >= 0.001)
B53: 0.082198035 | C53: -0.13552435 | D53: 0.0058727092 | E53: -0.080270638 | F53: 0.13679592 | G53: 0.00084743045 | H53: -0.018569421 | I53: 0.068888129 | J53: 0.069196974 | K53: 0.034597635 | L53: -0.010061638 | M53: 0.20480326 | N53: -0.060620592 | O53: 0.19213574 | P53: 0.0074288299 | Q53: 0.0079232377 | R53: 0.014626172 | S53: 0.062573393 | T53: 0.097632365 | U53: 0.27236094 | V53: 0.044020344 | W53: 0.00078457554 | X53: 0.0023609374
A55: Portfolio_Expected_Returns_3 | B55: =SUMPRODUCT(B31:X31,B53:X53)
A56: Total_Wealth_3 | B56: =SUM(B53:X53)
A57: Portfolio_Variance_3 | B57: =SUMPRODUCT(B53:X53,MMULT(B53:X53,B4:X26))
A59: Two-fund theorem check: phi = (0.08%-0.1%)/(0.08%-0.05%); z = phi*x1 + (1-phi)*x2
A60: phi | B60: =(0.0008-0.001)/(0.0008-0.0005)
A61: z (=phi*x1+(1-phi)*x2) | B61: {=$B$60*B34:X34+(1-$B$60)*B45:X45}
A62: x3 | B62: =B53 | C62: =C53 | D62: =D53 | E62: =E53 | F62: =F53 | G62: =G53 | H62: =H53 | I62: =I53 | ... X62: =X53
A63: Max |z - x3| (should be ~0 -> two-fund theorem holds, z = x3) | B63: {=MAX(ABS(B61:X61-B62:X62))}

Sheet Sharpe_Ratio_Q9-Q10
A1: Sharpe Portfolio Calculation--Cells in Yellow Are Not Optimal nor Correct, So You Need to Compute By Yourself
A3: COVARIANCE MATRIX | B3: IBM | C3: GE | D3: LLY | E3: F | F3: BAC | G3: KR | H3: ITUB | I3: GG | J3: SIRI | K3: ACB | L3: VALE | M3: PFE | N3: CTL | O3: T | P3: ECA | Q3: ABEV | R3: CVS | S3: MRVL | T3: CSCO | U3: MO | V3: BMY | W3: WFC | X3: HBAN
A4: IBM | B4: 0.000127 | C4: =_xlfn.COVARIANCE.S(Daily_Returns_Q1_Q2!B2:B503,Daily_Returns_Q1_Q2!C2:C503) | D4: 1.9e-05 | E4: 5.5e-05 | F4: 7e-05 | G4: 5e-06 | H4: 7.3e-05 | I4: 1.1e-05 | J4: 3.2e-05 | K4: 3.1e-05 | L4: 0.000104 | M4: 2.2e-05 | N4: 3.5e-05 | O4: 2.4e-05 | P4: 8.4e-05 | Q4: 4.6e-05 | R4: 2e-05 | S4: 5.8e-05 | T4: 4.7e-05 | U4: 1.6e-05 | V4: 1.4e-05 | W4: 5e-05 | X4: 6.9e-05
A5: GE | B5: =C4 | C5: 0.000139 | D5: 2.2e-05 | E5: 7e-05 | F5: 8.7e-05 | G5: 1.5e-05 | H5: 8.4e-05 | I5: -2.6e-05 | J5: 3.9e-05 | K5: -1.4e-05 | L5: 0.000137 | M5: 2.9e-05 | N5: 5.1e-05 | O5: 3.9e-05 | P5: 8.5e-05 | Q5: 4.8e-05 | R5: 3.9e-05 | S5: 5.1e-05 | T5: 4.1e-05 | U5: 2e-05 | V5: 3.2e-05 | W5: 6.2e-05 | X5: 7.6e-05
A6: LLY | B6: 1.9e-05 | C6: 2.2e-05 | D6: 0.000163 | E6: 3e-05 | F6: 4.1e-05 | G6: 2e-05 | H6: 3e-05 | I6: 1.1e-05 | J6: 2.6e-05 | K6: 1.1e-05 | L6: 5.1e-05 | M6: 5.3e-05 | N6: 3.3e-05 | O6: 2e-05 | P6: 1.9e-05 | Q6: 2.7e-05 | R6: 2.9e-05 | S6: 2.5e-05 | T6: 3.4e-05 | U6: 1.4e-05 | V6: 7.1e-05 | W6: 3.1e-05 | X6: 3e-05
A7: F | B7: 5.5e-05 | C7: 7e-05 | D7: 3e-05 | E7: 0.000204 | F7: 0.000127 | G7: 3.5e-05 | H7: 9.2e-05 | I7: -4e-06 | J7: 7.1e-05 | K7: 2.6e-05 | L7: 0.000193 | M7: 3.5e-05 | N7: 7.5e-05 | O7: 3.2e-05 | P7: 0.000152 | Q7: 5.1e-05 | R7: 3.3e-05 | S7: 8.9e-05 | T7: 6.5e-05 | U7: 1.1e-05 | V7: 5.5e-05 | W7: 9.4e-05 | X7: 0.000115
A8: BAC | B8: 7e-05 | C8: 8.7e-05 | D8: 4.1e-05 | E8: 0.000127 | F8: 0.000296 | G8: 5.8e-05 | H8: 0.000129 | I8: -0.000121 | J8: 8.5e-05 | K8: 4.4e-05 | L8: 0.000257 | M8: 5.3e-05 | N8: 7.4e-05 | O8: 1.9e-05 | P8: 0.000214 | Q8: 7.2e-05 | R8: 4.5e-05 | S8: 0.000103 | T8: 6.9e-05 | U8: -9e-06 | V8: 4e-05 | W8: 0.000175 | X8: 0.000233
A9: KR | B9: 5e-06 | C9: 1.5e-05 | D9: 2e-05 | E9: 3.5e-05 | F9: 5.8e-05 | G9: 0.000366 | H9: -1.6e-05 | I9: -2.4e-05 | J9: 3e-05 | K9: 4.2e-05 | L9: 1.9e-05 | M9: 2.1e-05 | N9: 6.5e-05 | O9: 1.5e-05 | P9: 4.9e-05 | Q9: 1.6e-05 | R9: 6.3e-05 | S9: 3.8e-05 | T9: 2.6e-05 | U9: 9e-06 | V9: 2.8e-05 | W9: 4.2e-05 | X9: 4.3e-05
A10: ITUB | B10: 7.3e-05 | C10: 8.4e-05 | D10: 3e-05 | E10: 9.2e-05 | F10: 0.000129 | G10: -1.6e-05 | H10: 0.000701 | I10: 0.00013 | J10: 7e-05 | K10: 9.9e-05 | L10: 0.000529 | M10: 1.2e-05 | N10: 0.000106 | O10: 5.2e-05 | P10: 0.000294 | Q10: 0.00034 | R10: 3.8e-05 | S10: 0.000127 | T10: 0.000113 | U10: 5e-05 | V10: 6.3e-05 | W10: 6.8e-05 | X10: 0.000106
A11: GG | B11: 1.1e-05 | C11: -2.6e-05 | D11: 1.1e-05 | E11: -4e-06 | F11: -0.000121 | G11: -2.4e-05 | H11: 0.00013 | I11: 0.000642 | J11: -3e-06 | K11: -5.8e-05 | L11: 0.000235 | M11: -1.7e-05 | N11: 5.4e-05 | O11: 3e-05 | P11: 0.000148 | Q11: 9e-05 | R11: -1.5e-05 | S11: 9e-06 | T11: 1.4e-05 | U11: 1.2e-05 | V11: 1.6e-05 | W11: -7.9e-05 | X11: -0.00011
A12: SIRI | B12: 3.2e-05 | C12: 3.9e-05 | D12: 2.6e-05 | E12: 7.1e-05 | F12: 8.5e-05 | G12: 3e-05 | H12: 7e-05 | I12: -3e-06 | J12: 0.000169 | K12: 5.2e-05 | L12: 0.000121 | M12: 2.1e-05 | N12: 6.1e-05 | O12: 2.9e-05 | P12: 9.4e-05 | Q12: 4.8e-05 | R12: 2e-05 | S12: 7.6e-05 | T12: 4.7e-05 | U12: 1.9e-05 | V12: 1.8e-05 | W12: 5.7e-05 | X12: 6.3e-05
A13: ACB | B13: 3.1e-05 | C13: -1.4e-05 | D13: 1.1e-05 | E13: 2.6e-05 | F13: 4.4e-05 | G13: 4.2e-05 | H13: 9.9e-05 | I13: -5.8e-05 | J13: 5.2e-05 | K13: 0.002376 | L13: 0.000164 | M13: 2e-05 | N13: 2.3e-05 | O13: -6e-06 | P13: 0.000149 | Q13: 0.000103 | R13: 3.6e-05 | S13: 6.6e-05 | T13: 4.5e-05 | U13: 1.9e-05 | V13: -1.8e-05 | W13: 2.5e-05 | X13: 5.7e-05
A14: VALE | B14: 0.000104 | C14: 0.000137 | D14: 5.1e-05 | E14: 0.000193 | F14: 0.000257 | G14: 1.9e-05 | H14: 0.000529 | I14: 0.000235 | J14: 0.000121 | K14: 0.000164 | L14: 0.001406 | M14: 3.9e-05 | N14: 0.000184 | O14: 5.8e-05 | P14: 0.000536 | Q14: 0.000326 | R14: 4.6e-05 | S14: 0.000174 | T14: 0.000129 | U14: 1.8e-05 | V14: 8.5e-05 | W14: 0.000159 | X14: 0.000218
A15: PFE | B15: 2.2e-05 | C15: 2.9e-05 | D15: 5.3e-05 | E15: 3.5e-05 | F15: 5.3e-05 | G15: 2.1e-05 | H15: 1.2e-05 | I15: -1.7e-05 | J15: 2.1e-05 | K15: 2e-05 | L15: 3.9e-05 | M15: 9.5e-05 | N15: 2.4e-05 | O15: 1.4e-05 | P15: 1e-05 | Q15: 2.1e-05 | R15: 3.9e-05 | S15: 2.8e-05 | T15: 2.8e-05 | U15: 4e-06 | V15: 5.6e-05 | W15: 4.6e-05 | X15: 5.2e-05
A16: CTL | B16: 3.5e-05 | C16: 5.1e-05 | D16: 3.3e-05 | E16: 7.5e-05 | F16: 7.4e-05 | G16: 6.5e-05 | H16: 0.000106 | I16: 5.4e-05 | J16: 6.1e-05 | K16: 2.3e-05 | L16: 0.000184 | M16: 2.4e-05 | N16: 0.000455 | O16: 5.9e-05 | P16: 0.000162 | Q16: 8.2e-05 | R16: 3e-05 | S16: 5.8e-05 | T16: 8.2e-05 | U16: 3.4e-05 | V16: 4e-05 | W16: 5.5e-05 | X16: 5.1e-05
A17: T | B17: 2.4e-05 | C17: 3.9e-05 | D17: 2e-05 | E17: 3.2e-05 | F17: 1.9e-05 | G17: 1.5e-05 | H17: 5.2e-05 | I17: 3e-05 | J17: 2.9e-05 | K17: -6e-06 | L17: 5.8e-05 | M17: 1.4e-05 | N17: 5.9e-05 | O17: 0.000105 | P17: 4.5e-05 | Q17: 3.7e-05 | R17: 1.9e-05 | S17: 1.3e-05 | T17: 2.4e-05 | U17: 3.4e-05 | V17: 1.1e-05 | W17: 2e-05 | X17: 2e-05
... A26: HBAN | B26: 6.9e-05 | C26: 7.6e-05 | D26: 3e-05 | E26: 0.000115 | F26: 0.000233 | G26: 4.3e-05 | H26: 0.000106 | I26: -0.00011 | J26: 6.3e-05 | K26: 5.7e-05 | L26: 0.000218 | M26: 5.2e-05 | N26: 5.1e-05 | O26: 2e-05 | P26: 0.000163 | Q26: 5.4e-05 | R26: 4.7e-05 | S26: 9.5e-05 | T26: 5.4e-05 | U26: -1e-05 | V26: 3.6e-05 | W26: 0.000165 | X26: 0.000295
A29: Risk_Free_Rate | B29: 0.0001
B31: IBM | C31: GE | D31: LLY | E31: F | F31: BAC | G31: KR | H31: ITUB | I31: GG | J31: SIRI | K31: ACB | L31: VALE | M31: PFE | N31: CTL | O31: T | P31: ECA | Q31: ABEV | R31: CVS | S31: MRVL | T31: CSCO | U31: MO | V31: BMY | W31: WFC | X31: HBAN
A32: Average_Daily_Returns | B32: 0.000241 | C32: =AVERAGE(Daily_Returns_Q1_Q2!C2:C503) | D32: 3.8e-05 | E32: -0.000223 | F32: 0.001167 | G32: -0.000807 | H32: 0.001658 | I32: 0.000147 | J32: 0.000608 | K32: 0.005781 | L32: 0.002696 | M32: 0.00025 | N32: -0.000815 | O32: 0.000247 | P32: 0.001902 | Q32: 0.000825 | R32: -0.000569 | S32: 0.001777 | T32: 0.00074 | U32: 0.000435 | V32: -0.000179 | W32: 0.000273 | X32: 0.000614
A33: Excess_Returns | B33: {=B32:X32-B29} | C33: -0.0001 | D33: -6.2e-05 | E33: -0.000323 | F33: 0.001067 | G33: -0.000907 | H33: 0.001558 | I33: 4.7e-05 | J33: 0.000508 | K33: 0.005681 | L33: 0.002596 | M33: 0.00015 | N33: -0.000915 | O33: 0.000147 | P33: 0.001802 | Q33: 0.000725 | R33: -0.000669 | S33: 0.001677 | T33: 0.00064 | U33: 0.000335 | V33: -0.000279 | W33: 0.000173 | X33: 0.000514
B35: IBM | C35: GE | D35: LLY | E35: F | F35: BAC | G35: KR | H35: ITUB | I35: GG | J35: SIRI | K35: ACB | L35: VALE | M35: PFE | N35: CTL | O35: T | P35: ECA | Q35: ABEV | R35: CVS | S35: MRVL | T35: CSCO | U35: MO | V35: BMY | W35: WFC | X35: HBAN
A36: Sharpe_Optimal_Solution | B36: -13.205646 | C36: -229.10989 | D36: -34.363742 | E36: -73.236469 | F36: 155.07454 | G36: -43.151135 | H36: 11.871068 | I36: -2.6703812 | J36: 9.0590061 | K36: 29.446545 | L36: 28.272008 | M36: 64.092888 | N36: -50.851954 | O36: 93.707825 | P36: 6.0853016 | Q36: -27.959197 | R36: -35.027744 | S36: 55.364894 | T36: 73.714367 | U36: 81.714131 | V36: -0.54994385 | W36: -54.578755 | X36: -29.615459
A37: Solution_Excess_Returns | B37: =SUMPRODUCT(B33:X33,B36:X36) | C37: = | D37: 1
A38: Solution_Variance | B38: =SUMPRODUCT(B36:X36,MMULT(B36:X36,B4:X26)) | C38: (Minimization)
A39: Potofolio_Allocation( Normalized Sharpe Solution) | B39: -0.9377503 | C39: -16.269395 | D39: -2.4402146 | E39: -5.2006181 | F39: 11.012047 | G39: -3.0642189 | H39: 0.8429802 | I39: -0.18962728 | J39: 0.64329196 | K39: 2.0910379 | L39: 2.0076326 | M39: 4.5513204 | N39: -3.6110642 | O39: 6.6543161 | P39: 0.43212528 | Q39: -1.9854194 | R39: -2.4873662 | S39: 3.9315341 | T39: 5.2345543 | U39: 5.802628 | V39: -0.039052237 | W39: -3.8757093 | X39: -2.1030327
A42: Portfolio_Expected_Returns | B42: =SUMPRODUCT(B39:X39,B32:X32)
A43: Total_Wealth | B43: =SUM(B39:X39)
A44: Portfolio_Variance | B44: =SUMPRODUCT(B39:X39,MMULT(B39:X39,B4:X26))
A45: Sharpe_Ratio | B45: =(B42-B29)/SQRT(B44)
A47: Q9 answer: Sharpe ratio (B45), rounded to 3 decimal places -> 0.260
A49: Q10: Can the Sharpe portfolio (row 39) be realized long-only?
A50: Most negative weight in row 39: | B50: =MIN(B39:X39)
A51: Long-only feasible? [Q10 answer] | B51: =IF(B50>=0,"Yes","No")

Sheet Efficient_Frontier_Q7-Q8
A1: Q7: Efficient frontier via two-fund theorem, z = phi*x1 + (1-phi)*x2, phi in [-2,2]
A2: x1, x2 pulled from Optimal_Portfolio_Q3-Q8!B34:X34 and !B45:X45. mu (mean returns) from Optimal_Portfolio_Q3-Q8!B31:X31. V (covariance) from !B4:X26.
A4: phi | B4: mean_return | C4: variance | E4: IBM | F4: GE | G4: LLY | H4: F | I4: BAC | J4: KR | K4: ITUB | L4: GG | M4: SIRI | N4: ACB | O4: VALE | P4: PFE | Q4: CTL | R4: T | S4: ECA | T4: ABEV | U4: CVS | V4: MRVL | W4: CSCO | X4: MO | Y4: BMY | Z4: WFC | AA4: HBAN
A5: -2 | B5: =SUMPRODUCT(E5:AA5,'Optimal_Portfolio_Q3-Q8'!B31:X31) | C5: =SUMPRODUCT(E5:AA5,MMULT(E5:AA5,'Optimal_Portfolio_Q3-Q8'!B4:X26)) | E5: =$A5*'Optimal_Portfolio_Q3-Q8'!B34+(1-$A5)*'Optimal_Portfolio_Q3-Q8'!B45 | F5: =$A5*'Optimal_Portfolio_Q3-Q8'!C34+(1-$A5)*'Optimal_Portfolio_Q3-Q8'!C45 | G5: =$A5*'Optimal_Portfolio_Q3-Q8'!D34+(1-$A5)*'Optimal_Portfolio_Q3-Q8'!D45 | H5: =$A5*'Optimal_Portfolio_Q3-Q8'!E34+(1-$A5)*'Optimal_Portfolio_Q3-Q8'!E45 | I5: =$A5*'Optimal_Portfolio_Q3-Q8'!F34+(1-$A5)*'Optimal_Portfolio_Q3-Q8'!F45 | J5: =$A5*'Optimal_Portfolio_Q3-Q8'!G34+(1-$A5)*'Optimal_Portfolio_Q3-Q8'!G45 | K5: =$A5*'Optimal_Portfolio_Q3-Q8'!H34+(1-$A5)*'Optimal_Portfolio_Q3-Q8'!H45 | L5: =$A5*'Optimal_Portfolio_Q3-Q8'!I34+(1-$A5)*'Optimal_Portfolio_Q3-Q8'!I45 | ... AA5: =$A5*'Optimal_Portfolio_Q3-Q8'!X34+(1-$A5)*'Optimal_Portfolio_Q3-Q8'!X45
A6: -1.9 | B6: =SUMPRODUCT(E6:AA6,'Optimal_Portfolio_Q3-Q8'!B31:X31) | C6: =SUMPRODUCT(E6:AA6,MMULT(E6:AA6,'Optimal_Portfolio_Q3-Q8'!B4:X26)) | E6: =$A6*'Optimal_Portfolio_Q3-Q8'!B34+(1-$A6)*'Optimal_Portfolio_Q3-Q8'!B45 | F6: =$A6*'Optimal_Portfolio_Q3-Q8'!C34+(1-$A6)*'Optimal_Portfolio_Q3-Q8'!C45 | G6: =$A6*'Optimal_Portfolio_Q3-Q8'!D34+(1-$A6)*'Optimal_Portfolio_Q3-Q8'!D45 | H6: =$A6*'Optimal_Portfolio_Q3-Q8'!E34+(1-$A6)*'Optimal_Portfolio_Q3-Q8'!E45 | I6: =$A6*'Optimal_Portfolio_Q3-Q8'!F34+(1-$A6)*'Optimal_Portfolio_Q3-Q8'!F45 | J6: =$A6*'Optimal_Portfolio_Q3-Q8'!G34+(1-$A6)*'Optimal_Portfolio_Q3-Q8'!G45 | K6: =$A6*'Optimal_Portfolio_Q3-Q8'!H34+(1-$A6)*'Optimal_Portfolio_Q3-Q8'!H45 | L6: =$A6*'Optimal_Portfolio_Q3-Q8'!I34+(1-$A6)*'Optimal_Portfolio_Q3-Q8'!I45 | ... AA6: =$A6*'Optimal_Portfolio_Q3-Q8'!X34+(1-$A6)*'Optimal_Portfolio_Q3-Q8'!X45
A7: -1.8 | B7: =SUMPRODUCT(E7:AA7,'Optimal_Portfolio_Q3-Q8'!B31:X31) | C7: =SUMPRODUCT(E7:AA7,MMULT(E7:AA7,'Optimal_Portfolio_Q3-Q8'!B4:X26)) | E7: =$A7*'Optimal_Portfolio_Q3-Q8'!B34+(1-$A7)*'Optimal_Portfolio_Q3-Q8'!B45 | F7: =$A7*'Optimal_Portfolio_Q3-Q8'!C34+(1-$A7)*'Optimal_Portfolio_Q3-Q8'!C45 | G7: =$A7*'Optimal_Portfolio_Q3-Q8'!D34+(1-$A7)*'Optimal_Portfolio_Q3-Q8'!D45 | H7: =$A7*'Optimal_Portfolio_Q3-Q8'!E34+(1-$A7)*'Optimal_Portfolio_Q3-Q8'!E45 | I7: =$A7*'Optimal_Portfolio_Q3-Q8'!F34+(1-$A7)*'Optimal_Portfolio_Q3-Q8'!F45 | J7: =$A7*'Optimal_Portfolio_Q3-Q8'!G34+(1-$A7)*'Optimal_Portfolio_Q3-Q8'!G45 | K7: =$A7*'Optimal_Portfolio_Q3-Q8'!H34+(1-$A7)*'Optimal_Portfolio_Q3-Q8'!H45 | L7: =$A7*'Optimal_Portfolio_Q3-Q8'!I34+(1-$A7)*'Optimal_Portfolio_Q3-Q8'!I45 | ... AA7: =$A7*'Optimal_Portfolio_Q3-Q8'!X34+(1-$A7)*'Optimal_Portfolio_Q3-Q8'!X45
A8: -1.7 | B8: =SUMPRODUCT(E8:AA8,'Optimal_Portfolio_Q3-Q8'!B31:X31) | C8: =SUMPRODUCT(E8:AA8,MMULT(E8:AA8,'Optimal_Portfolio_Q3-Q8'!B4:X26)) | E8: =$A8*'Optimal_Portfolio_Q3-Q8'!B34+(1-$A8)*'Optimal_Portfolio_Q3-Q8'!B45 | F8: =$A8*'Optimal_Portfolio_Q3-Q8'!C34+(1-$A8)*'Optimal_Portfolio_Q3-Q8'!C45 | G8: =$A8*'Optimal_Portfolio_Q3-Q8'!D34+(1-$A8)*'Optimal_Portfolio_Q3-Q8'!D45 | H8: =$A8*'Optimal_Portfolio_Q3-Q8'!E34+(1-$A8)*'Optimal_Portfolio_Q3-Q8'!E45 | I8: =$A8*'Optimal_Portfolio_Q3-Q8'!F34+(1-$A8)*'Optimal_Portfolio_Q3-Q8'!F45 | J8: =$A8*'Optimal_Portfolio_Q3-Q8'!G34+(1-$A8)*'Optimal_Portfolio_Q3-Q8'!G45 | K8: =$A8*'Optimal_Portfolio_Q3-Q8'!H34+(1-$A8)*'Optimal_Portfolio_Q3-Q8'!H45 | L8: =$A8*'Optimal_Portfolio_Q3-Q8'!I34+(1-$A8)*'Optimal_Portfolio_Q3-Q8'!I45 | ... AA8: =$A8*'Optimal_Portfolio_Q3-Q8'!X34+(1-$A8)*'Optimal_Portfolio_Q3-Q8'!X45
A9: -1.6 | B9: =SUMPRODUCT(E9:AA9,'Optimal_Portfolio_Q3-Q8'!B31:X31) | C9: =SUMPRODUCT(E9:AA9,MMULT(E9:AA9,'Optimal_Portfolio_Q3-Q8'!B4:X26)) | E9: =$A9*'Optimal_Portfolio_Q3-Q8'!B34+(1-$A9)*'Optimal_Portfolio_Q3-Q8'!B45 | F9: =$A9*'Optimal_Portfolio_Q3-Q8'!C34+(1-$A9)*'Optimal_Portfolio_Q3-Q8'!C45 | G9: =$A9*'Optimal_Portfolio_Q3-Q8'!D34+(1-$A9)*'Optimal_Portfolio_Q3-Q8'!D45 | H9: =$A9*'Optimal_Portfolio_Q3-Q8'!E34+(1-$A9)*'Optimal_Portfolio_Q3-Q8'!E45 | I9: =$A9*'Optimal_Portfolio_Q3-Q8'!F34+(1-$A9)*'Optimal_Portfolio_Q3-Q8'!F45 | J9: =$A9*'Optimal_Portfolio_Q3-Q8'!G34+(1-$A9)*'Optimal_Portfolio_Q3-Q8'!G45 | K9: =$A9*'Optimal_Portfolio_Q3-Q8'!H34+(1-$A9)*'Optimal_Portfolio_Q3-Q8'!H45 | L9: =$A9*'Optimal_Portfolio_Q3-Q8'!I34+(1-$A9)*'Optimal_Portfolio_Q3-Q8'!I45 | ... AA9: =$A9*'Optimal_Portfolio_Q3-Q8'!X34+(1-$A9)*'Optimal_Portfolio_Q3-Q8'!X45
A10: -1.5 | B10: =SUMPRODUCT(E10:AA10,'Optimal_Portfolio_Q3-Q8'!B31:X31) | C10: =SUMPRODUCT(E10:AA10,MMULT(E10:AA10,'Optimal_Portfolio_Q3-Q8'!B4:X26)) | E10: =$A10*'Optimal_Portfolio_Q3-Q8'!B34+(1-$A10)*'Optimal_Portfolio_Q3-Q8'!B45 | F10: =$A10*'Optimal_Portfolio_Q3-Q8'!C34+(1-$A10)*'Optimal_Portfolio_Q3-Q8'!C45 | G10: =$A10*'Optimal_Portfolio_Q3-Q8'!D34+(1-$A10)*'Optimal_Portfolio_Q3-Q8'!D45 | H10: =$A10*'Optimal_Portfolio_Q3-Q8'!E34+(1-$A10)*'Optimal_Portfolio_Q3-Q8'!E45 | I10: =$A10*'Optimal_Portfolio_Q3-Q8'!F34+(1-$A10)*'Optimal_Portfolio_Q3-Q8'!F45 | J10: =$A10*'Optimal_Portfolio_Q3-Q8'!G34+(1-$A10)*'Optimal_Portfolio_Q3-Q8'!G45 | K10: =$A10*'Optimal_Portfolio_Q3-Q8'!H34+(1-$A10)*'Optimal_Portfolio_Q3-Q8'!H45 | L10: =$A10*'Optimal_Portfolio_Q3-Q8'!I34+(1-$A10)*'Optimal_Portfolio_Q3-Q8'!I45 | ... AA10: =$A10*'Optimal_Portfolio_Q3-Q8'!X34+(1-$A10)*'Optimal_Portfolio_Q3-Q8'!X45
A11: -1.4 | B11: =SUMPRODUCT(E11:AA11,'Optimal_Portfolio_Q3-Q8'!B31:X31) | C11: =SUMPRODUCT(E11:AA11,MMULT(E11:AA11,'Optimal_Portfolio_Q3-Q8'!B4:X26)) | E11: =$A11*'Optimal_Portfolio_Q3-Q8'!B34+(1-$A11)*'Optimal_Portfolio_Q3-Q8'!B45 | F11: =$A11*'Optimal_Portfolio_Q3-Q8'!C34+(1-$A11)*'Optimal_Portfolio_Q3-Q8'!C45 | G11: =$A11*'Optimal_Portfolio_Q3-Q8'!D34+(1-$A11)*'Optimal_Portfolio_Q3-Q8'!D45 | H11: =$A11*'Optimal_Portfolio_Q3-Q8'!E34+(1-$A11)*'Optimal_Portfolio_Q3-Q8'!E45 | I11: =$A11*'Optimal_Portfolio_Q3-Q8'!F34+(1-$A11)*'Optimal_Portfolio_Q3-Q8'!F45 | J11: =$A11*'Optimal_Portfolio_Q3-Q8'!G34+(1-$A11)*'Optimal_Portfolio_Q3-Q8'!G45 | K11: =$A11*'Optimal_Portfolio_Q3-Q8'!H34+(1-$A11)*'Optimal_Portfolio_Q3-Q8'!H45 | L11: =$A11*'Optimal_Portfolio_Q3-Q8'!I34+(1-$A11)*'Optimal_Portfolio_Q3-Q8'!I45 | ... AA11: =$A11*'Optimal_Portfolio_Q3-Q8'!X34+(1-$A11)*'Optimal_Portfolio_Q3-Q8'!X45
A12: -1.3 | B12: =SUMPRODUCT(E12:AA12,'Optimal_Portfolio_Q3-Q8'!B31:X31) | C12: =SUMPRODUCT(E12:AA12,MMULT(E12:AA12,'Optimal_Portfolio_Q3-Q8'!B4:X26)) | E12: =$A12*'Optimal_Portfolio_Q3-Q8'!B34+(1-$A12)*'Optimal_Portfolio_Q3-Q8'!B45 | F12: =$A12*'Optimal_Portfolio_Q3-Q8'!C34+(1-$A12)*'Optimal_Portfolio_Q3-Q8'!C45 | G12: =$A12*'Optimal_Portfolio_Q3-Q8'!D34+(1-$A12)*'Optimal_Portfolio_Q3-Q8'!D45 | H12: =$A12*'Optimal_Portfolio_Q3-Q8'!E34+(1-$A12)*'Optimal_Portfolio_Q3-Q8'!E45 | I12: =$A12*'Optimal_Portfolio_Q3-Q8'!F34+(1-$A12)*'Optimal_Portfolio_Q3-Q8'!F45 | J12: =$A12*'Optimal_Portfolio_Q3-Q8'!G34+(1-$A12)*'Optimal_Portfolio_Q3-Q8'!G45 | K12: =$A12*'Optimal_Portfolio_Q3-Q8'!H34+(1-$A12)*'Optimal_Portfolio_Q3-Q8'!H45 | L12: =$A12*'Optimal_Portfolio_Q3-Q8'!I34+(1-$A12)*'Optimal_Portfolio_Q3-Q8'!I45 | ... AA12: =$A12*'Optimal_Portfolio_Q3-Q8'!X34+(1-$A12)*'Optimal_Portfolio_Q3-Q8'!X45
A13: -1.2 | B13: =SUMPRODUCT(E13:AA13,'Optimal_Portfolio_Q3-Q8'!B31:X31) | C13: =SUMPRODUCT(E13:AA13,MMULT(E13:AA13,'Optimal_Portfolio_Q3-Q8'!B4:X26)) | E13: =$A13*'Optimal_Portfolio_Q3-Q8'!B34+(1-$A13)*'Optimal_Portfolio_Q3-Q8'!B45 | F13: =$A13*'Optimal_Portfolio_Q3-Q8'!C34+(1-$A13)*'Optimal_Portfolio_Q3-Q8'!C45 | G13: =$A13*'Optimal_Portfolio_Q3-Q8'!D34+(1-$A13)*'Optimal_Portfolio_Q3-Q8'!D45 | H13: =$A13*'Optimal_Portfolio_Q3-Q8'!E34+(1-$A13)*'Optimal_Portfolio_Q3-Q8'!E45 | I13: =$A13*'Optimal_Portfolio_Q3-Q8'!F34+(1-$A13)*'Optimal_Portfolio_Q3-Q8'!F45 | J13: =$A13*'Optimal_Portfolio_Q3-Q8'!G34+(1-$A13)*'Optimal_Portfolio_Q3-Q8'!G45 | K13: =$A13*'Optimal_Portfolio_Q3-Q8'!H34+(1-$A13)*'Optimal_Portfolio_Q3-Q8'!H45 | L13: =$A13*'Optimal_Portfolio_Q3-Q8'!I34+(1-$A13)*'Optimal_Portfolio_Q3-Q8'!I45 | ... AA13: =$A13*'Optimal_Portfolio_Q3-Q8'!X34+(1-$A13)*'Optimal_Portfolio_Q3-Q8'!X45
A14: -1.1 | B14: =SUMPRODUCT(E14:AA14,'Optimal_Portfolio_Q3-Q8'!B31:X31) | C14: =SUMPRODUCT(E14:AA14,MMULT(E14:AA14,'Optimal_Portfolio_Q3-Q8'!B4:X26)) | E14: =$A14*'Optimal_Portfolio_Q3-Q8'!B34+(1-$A14)*'Optimal_Portfolio_Q3-Q8'!B45 | F14: =$A14*'Optimal_Portfolio_Q3-Q8'!C34+(1-$A14)*'Optimal_Portfolio_Q3-Q8'!C45 | G14: =$A14*'Optimal_Portfolio_Q3-Q8'!D34+(1-$A14)*'Optimal_Portfolio_Q3-Q8'!D45 | H14: =$A14*'Optimal_Portfolio_Q3-Q8'!E34+(1-$A14)*'Optimal_Portfolio_Q3-Q8'!E45 | I14: =$A14*'Optimal_Portfolio_Q3-Q8'!F34+(1-$A14)*'Optimal_Portfolio_Q3-Q8'!F45 | J14: =$A14*'Optimal_Portfolio_Q3-Q8'!G34+(1-$A14)*'Optimal_Portfolio_Q3-Q8'!G45 | K14: =$A14*'Optimal_Portfolio_Q3-Q8'!H34+(1-$A14)*'Optimal_Portfolio_Q3-Q8'!H45 | L14: =$A14*'Optimal_Portfolio_Q3-Q8'!I34+(1-$A14)*'Optimal_Portfolio_Q3-Q8'!I45 | ... AA14: =$A14*'Optimal_Portfolio_Q3-Q8'!X34+(1-$A14)*'Optimal_Portfolio_Q3-Q8'!X45
A15: -1 | B15: =SUMPRODUCT(E15:AA15,'Optimal_Portfolio_Q3-Q8'!B31:X31) | C15: =SUMPRODUCT(E15:AA15,MMULT(E15:AA15,'Optimal_Portfolio_Q3-Q8'!B4:X26)) | E15: =$A15*'Optimal_Portfolio_Q3-Q8'!B34+(1-$A15)*'Optimal_Portfolio_Q3-Q8'!B45 | F15: =$A15*'Optimal_Portfolio_Q3-Q8'!C34+(1-$A15)*'Optimal_Portfolio_Q3-Q8'!C45 | G15: =$A15*'Optimal_Portfolio_Q3-Q8'!D34+(1-$A15)*'Optimal_Portfolio_Q3-Q8'!D45 | H15: =$A15*'Optimal_Portfolio_Q3-Q8'!E34+(1-$A15)*'Optimal_Portfolio_Q3-Q8'!E45 | I15: =$A15*'Optimal_Portfolio_Q3-Q8'!F34+(1-$A15)*'Optimal_Portfolio_Q3-Q8'!F45 | J15: =$A15*'Optimal_Portfolio_Q3-Q8'!G34+(1-$A15)*'Optimal_Portfolio_Q3-Q8'!G45 | K15: =$A15*'Optimal_Portfolio_Q3-Q8'!H34+(1-$A15)*'Optimal_Portfolio_Q3-Q8'!H45 | L15: =$A15*'Optimal_Portfolio_Q3-Q8'!I34+(1-$A15)*'Optimal_Portfolio_Q3-Q8'!I45 | ... AA15: =$A15*'Optimal_Portfolio_Q3-Q8'!X34+(1-$A15)*'Optimal_Portfolio_Q3-Q8'!X45
A16: -0.9 | B16: =SUMPRODUCT(E16:AA16,'Optimal_Portfolio_Q3-Q8'!B31:X31) | C16: =SUMPRODUCT(E16:AA16,MMULT(E16:AA16,'Optimal_Portfolio_Q3-Q8'!B4:X26)) | E16: =$A16*'Optimal_Portfolio_Q3-Q8'!B34+(1-$A16)*'Optimal_Portfolio_Q3-Q8'!B45 | F16: =$A16*'Optimal_Portfolio_Q3-Q8'!C34+(1-$A16)*'Optimal_Portfolio_Q3-Q8'!C45 | G16: =$A16*'Optimal_Portfolio_Q3-Q8'!D34+(1-$A16)*'Optimal_Portfolio_Q3-Q8'!D45 | H16: =$A16*'Optimal_Portfolio_Q3-Q8'!E34+(1-$A16)*'Optimal_Portfolio_Q3-Q8'!E45 | I16: =$A16*'Optimal_Portfolio_Q3-Q8'!F34+(1-$A16)*'Optimal_Portfolio_Q3-Q8'!F45 | J16: =$A16*'Optimal_Portfolio_Q3-Q8'!G34+(1-$A16)*'Optimal_Portfolio_Q3-Q8'!G45 | K16: =$A16*'Optimal_Portfolio_Q3-Q8'!H34+(1-$A16)*'Optimal_Portfolio_Q3-Q8'!H45 | L16: =$A16*'Optimal_Portfolio_Q3-Q8'!I34+(1-$A16)*'Optimal_Portfolio_Q3-Q8'!I45 | ... AA16: =$A16*'Optimal_Portfolio_Q3-Q8'!X34+(1-$A16)*'Optimal_Portfolio_Q3-Q8'!X45
A17: -0.8 | B17: =SUMPRODUCT(E17:AA17,'Optimal_Portfolio_Q3-Q8'!B31:X31) | C17: =SUMPRODUCT(E17:AA17,MMULT(E17:AA17,'Optimal_Portfolio_Q3-Q8'!B4:X26)) | E17: =$A17*'Optimal_Portfolio_Q3-Q8'!B34+(1-$A17)*'Optimal_Portfolio_Q3-Q8'!B45 | F17: =$A17*'Optimal_Portfolio_Q3-Q8'!C34+(1-$A17)*'Optimal_Portfolio_Q3-Q8'!C45 | G17: =$A17*'Optimal_Portfolio_Q3-Q8'!D34+(1-$A17)*'Optimal_Portfolio_Q3-Q8'!D45 | H17: =$A17*'Optimal_Portfolio_Q3-Q8'!E34+(1-$A17)*'Optimal_Portfolio_Q3-Q8'!E45 | I17: =$A17*'Optimal_Portfolio_Q3-Q8'!F34+(1-$A17)*'Optimal_Portfolio_Q3-Q8'!F45 | J17: =$A17*'Optimal_Portfolio_Q3-Q8'!G34+(1-$A17)*'Optimal_Portfolio_Q3-Q8'!G45 | K17: =$A17*'Optimal_Portfolio_Q3-Q8'!H34+(1-$A17)*'Optimal_Portfolio_Q3-Q8'!H45 | L17: =$A17*'Optimal_Portfolio_Q3-Q8'!I34+(1-$A17)*'Optimal_Portfolio_Q3-Q8'!I45 | ... AA17: =$A17*'Optimal_Portfolio_Q3-Q8'!X34+(1-$A17)*'Optimal_Portfolio_Q3-Q8'!X45
A18: -0.7 | B18: =SUMPRODUCT(E18:AA18,'Optimal_Portfolio_Q3-Q8'!B31:X31) | C18: =SUMPRODUCT(E18:AA18,MMULT(E18:AA18,'Optimal_Portfolio_Q3-Q8'!B4:X26)) | E18: =$A18*'Optimal_Portfolio_Q3-Q8'!B34+(1-$A18)*'Optimal_Portfolio_Q3-Q8'!B45 | F18: =$A18*'Optimal_Portfolio_Q3-Q8'!C34+(1-$A18)*'Optimal_Portfolio_Q3-Q8'!C45 | G18: =$A18*'Optimal_Portfolio_Q3-Q8'!D34+(1-$A18)*'Optimal_Portfolio_Q3-Q8'!D45 | H18: =$A18*'Optimal_Portfolio_Q3-Q8'!E34+(1-$A18)*'Optimal_Portfolio_Q3-Q8'!E45 | I18: =$A18*'Optimal_Portfolio_Q3-Q8'!F34+(1-$A18)*'Optimal_Portfolio_Q3-Q8'!F45 | J18: =$A18*'Optimal_Portfolio_Q3-Q8'!G34+(1-$A18)*'Optimal_Portfolio_Q3-Q8'!G45 | K18: =$A18*'Optimal_Portfolio_Q3-Q8'!H34+(1-$A18)*'Optimal_Portfolio_Q3-Q8'!H45 | L18: =$A18*'Optimal_Portfolio_Q3-Q8'!I34+(1-$A18)*'Optimal_Portfolio_Q3-Q8'!I45 | ... AA18: =$A18*'Optimal_Portfolio_Q3-Q8'!X34+(1-$A18)*'Optimal_Portfolio_Q3-Q8'!X45
A19: -0.6 | B19: =SUMPRODUCT(E19:AA19,'Optimal_Portfolio_Q3-Q8'!B31:X31) | C19: =SUMPRODUCT(E19:AA19,MMULT(E19:AA19,'Optimal_Portfolio_Q3-Q8'!B4:X26)) | E19: =$A19*'Optimal_Portfolio_Q3-Q8'!B34+(1-$A19)*'Optimal_Portfolio_Q3-Q8'!B45 | F19: =$A19*'Optimal_Portfolio_Q3-Q8'!C34+(1-$A19)*'Optimal_Portfolio_Q3-Q8'!C45 | G19: =$A19*'Optimal_Portfolio_Q3-Q8'!D34+(1-$A19)*'Optimal_Portfolio_Q3-Q8'!D45 | H19: =$A19*'Optimal_Portfolio_Q3-Q8'!E34+(1-$A19)*'Optimal_Portfolio_Q3-Q8'!E45 | I19: =$A19*'Optimal_Portfolio_Q3-Q8'!F34+(1-$A19)*'Optimal_Portfolio_Q3-Q8'!F45 | J19: =$A19*'Optimal_Portfolio_Q3-Q8'!G34+(1-$A19)*'Optimal_Portfolio_Q3-Q8'!G45 | K19: =$A19*'Optimal_Portfolio_Q3-Q8'!H34+(1-$A19)*'Optimal_Portfolio_Q3-Q8'!H45 | L19: =$A19*'Optimal_Portfolio_Q3-Q8'!I34+(1-$A19)*'Optimal_Portfolio_Q3-Q8'!I45 | ... AA19: =$A19*'Optimal_Portfolio_Q3-Q8'!X34+(1-$A19)*'Optimal_Portfolio_Q3-Q8'!X45
A20: -0.5 | B20: =SUMPRODUCT(E20:AA20,'Optimal_Portfolio_Q3-Q8'!B31:X31) | C20: =SUMPRODUCT(E20:AA20,MMULT(E20:AA20,'Optimal_Portfolio_Q3-Q8'!B4:X26)) | E20: =$A20*'Optimal_Portfolio_Q3-Q8'!B34+(1-$A20)*'Optimal_Portfolio_Q3-Q8'!B45 | F20: =$A20*'Optimal_Portfolio_Q3-Q8'!C34+(1-$A20)*'Optimal_Portfolio_Q3-Q8'!C45 | G20: =$A20*'Optimal_Portfolio_Q3-Q8'!D34+(1-$A20)*'Optimal_Portfolio_Q3-Q8'!D45 | H20: =$A20*'Optimal_Portfolio_Q3-Q8'!E34+(1-$A20)*'Optimal_Portfolio_Q3-Q8'!E45 | I20: =$A20*'Optimal_Portfolio_Q3-Q8'!F34+(1-$A20)*'Optimal_Portfolio_Q3-Q8'!F45 | J20: =$A20*'Optimal_Portfolio_Q3-Q8'!G34+(1-$A20)*'Optimal_Portfolio_Q3-Q8'!G45 | K20: =$A20*'Optimal_Portfolio_Q3-Q8'!H34+(1-$A20)*'Optimal_Portfolio_Q3-Q8'!H45 | L20: =$A20*'Optimal_Portfolio_Q3-Q8'!I34+(1-$A20)*'Optimal_Portfolio_Q3-Q8'!I45 | ... AA20: =$A20*'Optimal_Portfolio_Q3-Q8'!X34+(1-$A20)*'Optimal_Portfolio_Q3-Q8'!X45
A21: -0.4 | B21: =SUMPRODUCT(E21:AA21,'Optimal_Portfolio_Q3-Q8'!B31:X31) | C21: =SUMPRODUCT(E21:AA21,MMULT(E21:AA21,'Optimal_Portfolio_Q3-Q8'!B4:X26)) | E21: =$A21*'Optimal_Portfolio_Q3-Q8'!B34+(1-$A21)*'Optimal_Portfolio_Q3-Q8'!B45 | F21: =$A21*'Optimal_Portfolio_Q3-Q8'!C34+(1-$A21)*'Optimal_Portfolio_Q3-Q8'!C45 | G21: =$A21*'Optimal_Portfolio_Q3-Q8'!D34+(1-$A21)*'Optimal_Portfolio_Q3-Q8'!D45 | H21: =$A21*'Optimal_Portfolio_Q3-Q8'!E34+(1-$A21)*'Optimal_Portfolio_Q3-Q8'!E45 | I21: =$A21*'Optimal_Portfolio_Q3-Q8'!F34+(1-$A21)*'Optimal_Portfolio_Q3-Q8'!F45 | J21: =$A21*'Optimal_Portfolio_Q3-Q8'!G34+(1-$A21)*'Optimal_Portfolio_Q3-Q8'!G45 | K21: =$A21*'Optimal_Portfolio_Q3-Q8'!H34+(1-$A21)*'Optimal_Portfolio_Q3-Q8'!H45 | L21: =$A21*'Optimal_Portfolio_Q3-Q8'!I34+(1-$A21)*'Optimal_Portfolio_Q3-Q8'!I45 | ... AA21: =$A21*'Optimal_Portfolio_Q3-Q8'!X34+(1-$A21)*'Optimal_Portfolio_Q3-Q8'!X45
A22: -0.3 | B22: =SUMPRODUCT(E22:AA22,'Optimal_Portfolio_Q3-Q8'!B31:X31) | C22: =SUMPRODUCT(E22:AA22,MMULT(E22:AA22,'Optimal_Portfolio_Q3-Q8'!B4:X26)) | E22: =$A22*'Optimal_Portfolio_Q3-Q8'!B34+(1-$A22)*'Optimal_Portfolio_Q3-Q8'!B45 | F22: =$A22*'Optimal_Portfolio_Q3-Q8'!C34+(1-$A22)*'Optimal_Portfolio_Q3-Q8'!C45 | G22: =$A22*'Optimal_Portfolio_Q3-Q8'!D34+(1-$A22)*'Optimal_Portfolio_Q3-Q8'!D45 | H22: =$A22*'Optimal_Portfolio_Q3-Q8'!E34+(1-$A22)*'Optimal_Portfolio_Q3-Q8'!E45 | I22: =$A22*'Optimal_Portfolio_Q3-Q8'!F34+(1-$A22)*'Optimal_Portfolio_Q3-Q8'!F45 | J22: =$A22*'Optimal_Portfolio_Q3-Q8'!G34+(1-$A22)*'Optimal_Portfolio_Q3-Q8'!G45 | K22: =$A22*'Optimal_Portfolio_Q3-Q8'!H34+(1-$A22)*'Optimal_Portfolio_Q3-Q8'!H45 | L22: =$A22*'Optimal_Portfolio_Q3-Q8'!I34+(1-$A22)*'Optimal_Portfolio_Q3-Q8'!I45 | ... AA22: =$A22*'Optimal_Portfolio_Q3-Q8'!X34+(1-$A22)*'Optimal_Portfolio_Q3-Q8'!X45
A23: -0.2 | B23: =SUMPRODUCT(E23:AA23,'Optimal_Portfolio_Q3-Q8'!B31:X31) | C23: =SUMPRODUCT(E23:AA23,MMULT(E23:AA23,'Optimal_Portfolio_Q3-Q8'!B4:X26)) | E23: =$A23*'Optimal_Portfolio_Q3-Q8'!B34+(1-$A23)*'Optimal_Portfolio_Q3-Q8'!B45 | F23: =$A23*'Optimal_Portfolio_Q3-Q8'!C34+(1-$A23)*'Optimal_Portfolio_Q3-Q8'!C45 | G23: =$A23*'Optimal_Portfolio_Q3-Q8'!D34+(1-$A23)*'Optimal_Portfolio_Q3-Q8'!D45 | H23: =$A23*'Optimal_Portfolio_Q3-Q8'!E34+(1-$A23)*'Optimal_Portfolio_Q3-Q8'!E45 | I23: =$A23*'Optimal_Portfolio_Q3-Q8'!F34+(1-$A23)*'Optimal_Portfolio_Q3-Q8'!F45 | J23: =$A23*'Optimal_Portfolio_Q3-Q8'!G34+(1-$A23)*'Optimal_Portfolio_Q3-Q8'!G45 | K23: =$A23*'Optimal_Portfolio_Q3-Q8'!H34+(1-$A23)*'Optimal_Portfolio_Q3-Q8'!H45 | L23: =$A23*'Optimal_Portfolio_Q3-Q8'!I34+(1-$A23)*'Optimal_Portfolio_Q3-Q8'!I45 | ... AA23: =$A23*'Optimal_Portfolio_Q3-Q8'!X34+(1-$A23)*'Optimal_Portfolio_Q3-Q8'!X45
A24: -0.1 | B24: =SUMPRODUCT(E24:AA24,'Optimal_Portfolio_Q3-Q8'!B31:X31) | C24: =SUMPRODUCT(E24:AA24,MMULT(E24:AA24,'Optimal_Portfolio_Q3-Q8'!B4:X26)) | E24: =$A24*'Optimal_Portfolio_Q3-Q8'!B34+(1-$A24)*'Optimal_Portfolio_Q3-Q8'!B45 | F24: =$A24*'Optimal_Portfolio_Q3-Q8'!C34+(1-$A24)*'Optimal_Portfolio_Q3-Q8'!C45 | G24: =$A24*'Optimal_Portfolio_Q3-Q8'!D34+(1-$A24)*'Optimal_Portfolio_Q3-Q8'!D45 | H24: =$A24*'Optimal_Portfolio_Q3-Q8'!E34+(1-$A24)*'Optimal_Portfolio_Q3-Q8'!E45 | I24: =$A24*'Optimal_Portfolio_Q3-Q8'!F34+(1-$A24)*'Optimal_Portfolio_Q3-Q8'!F45 | J24: =$A24*'Optimal_Portfolio_Q3-Q8'!G34+(1-$A24)*'Optimal_Portfolio_Q3-Q8'!G45 | K24: =$A24*'Optimal_Portfolio_Q3-Q8'!H34+(1-$A24)*'Optimal_Portfolio_Q3-Q8'!H45 | L24: =$A24*'Optimal_Portfolio_Q3-Q8'!I34+(1-$A24)*'Optimal_Portfolio_Q3-Q8'!I45 | ... AA24: =$A24*'Optimal_Portfolio_Q3-Q8'!X34+(1-$A24)*'Optimal_Portfolio_Q3-Q8'!X45
A25: 0 | B25: =SUMPRODUCT(E25:AA25,'Optimal_Portfolio_Q3-Q8'!B31:X31) | C25: =SUMPRODUCT(E25:AA25,MMULT(E25:AA25,'Optimal_Portfolio_Q3-Q8'!B4:X26)) | E25: =$A25*'Optimal_Portfolio_Q3-Q8'!B34+(1-$A25)*'Optimal_Portfolio_Q3-Q8'!B45 | F25: =$A25*'Optimal_Portfolio_Q3-Q8'!C34+(1-$A25)*'Optimal_Portfolio_Q3-Q8'!C45 | G25: =$A25*'Optimal_Portfolio_Q3-Q8'!D34+(1-$A25)*'Optimal_Portfolio_Q3-Q8'!D45 | H25: =$A25*'Optimal_Portfolio_Q3-Q8'!E34+(1-$A25)*'Optimal_Portfolio_Q3-Q8'!E45 | I25: =$A25*'Optimal_Portfolio_Q3-Q8'!F34+(1-$A25)*'Optimal_Portfolio_Q3-Q8'!F45 | J25: =$A25*'Optimal_Portfolio_Q3-Q8'!G34+(1-$A25)*'Optimal_Portfolio_Q3-Q8'!G45 | K25: =$A25*'Optimal_Portfolio_Q3-Q8'!H34+(1-$A25)*'Optimal_Portfolio_Q3-Q8'!H45 | L25: =$A25*'Optimal_Portfolio_Q3-Q8'!I34+(1-$A25)*'Optimal_Portfolio_Q3-Q8'!I45 | ... AA25: =$A25*'Optimal_Portfolio_Q3-Q8'!X34+(1-$A25)*'Optimal_Portfolio_Q3-Q8'!X45
A26: 0.1 | B26: =SUMPRODUCT(E26:AA26,'Optimal_Portfolio_Q3-Q8'!B31:X31) | C26: =SUMPRODUCT(E26:AA26,MMULT(E26:AA26,'Optimal_Portfolio_Q3-Q8'!B4:X26)) | E26: =$A26*'Optimal_Portfolio_Q3-Q8'!B34+(1-$A26)*'Optimal_Portfolio_Q3-Q8'!B45 | F26: =$A26*'Optimal_Portfolio_Q3-Q8'!C34+(1-$A26)*'Optimal_Portfolio_Q3-Q8'!C45 | G26: =$A26*'Optimal_Portfolio_Q3-Q8'!D34+(1-$A26)*'Optimal_Portfolio_Q3-Q8'!D45 | H26: =$A26*'Optimal_Portfolio_Q3-Q8'!E34+(1-$A26)*'Optimal_Portfolio_Q3-Q8'!E45 | I26: =$A26*'Optimal_Portfolio_Q3-Q8'!F34+(1-$A26)*'Optimal_Portfolio_Q3-Q8'!F45 | J26: =$A26*'Optimal_Portfolio_Q3-Q8'!G34+(1-$A26)*'Optimal_Portfolio_Q3-Q8'!G45 | K26: =$A26*'Optimal_Portfolio_Q3-Q8'!H34+(1-$A26)*'Optimal_Portfolio_Q3-Q8'!H45 | L26: =$A26*'Optimal_Portfolio_Q3-Q8'!I34+(1-$A26)*'Optimal_Portfolio_Q3-Q8'!I45 | ... AA26: =$A26*'Optimal_Portfolio_Q3-Q8'!X34+(1-$A26)*'Optimal_Portfolio_Q3-Q8'!X45
A27: 0.2 | B27: =SUMPRODUCT(E27:AA27,'Optimal_Portfolio_Q3-Q8'!B31:X31) | C27: =SUMPRODUCT(E27:AA27,MMULT(E27:AA27,'Optimal_Portfolio_Q3-Q8'!B4:X26)) | E27: =$A27*'Optimal_Portfolio_Q3-Q8'!B34+(1-$A27)*'Optimal_Portfolio_Q3-Q8'!B45 | F27: =$A27*'Optimal_Portfolio_Q3-Q8'!C34+(1-$A27)*'Optimal_Portfolio_Q3-Q8'!C45 | G27: =$A27*'Optimal_Portfolio_Q3-Q8'!D34+(1-$A27)*'Optimal_Portfolio_Q3-Q8'!D45 | H27: =$A27*'Optimal_Portfolio_Q3-Q8'!E34+(1-$A27)*'Optimal_Portfolio_Q3-Q8'!E45 | I27: =$A27*'Optimal_Portfolio_Q3-Q8'!F34+(1-$A27)*'Optimal_Portfolio_Q3-Q8'!F45 | J27: =$A27*'Optimal_Portfolio_Q3-Q8'!G34+(1-$A27)*'Optimal_Portfolio_Q3-Q8'!G45 | K27: =$A27*'Optimal_Portfolio_Q3-Q8'!H34+(1-$A27)*'Optimal_Portfolio_Q3-Q8'!H45 | L27: =$A27*'Optimal_Portfolio_Q3-Q8'!I34+(1-$A27)*'Optimal_Portfolio_Q3-Q8'!I45 | ... AA27: =$A27*'Optimal_Portfolio_Q3-Q8'!X34+(1-$A27)*'Optimal_Portfolio_Q3-Q8'!X45
A28: 0.3 | B28: =SUMPRODUCT(E28:AA28,'Optimal_Portfolio_Q3-Q8'!B31:X31) | C28: =SUMPRODUCT(E28:AA28,MMULT(E28:AA28,'Optimal_Portfolio_Q3-Q8'!B4:X26)) | E28: =$A28*'Optimal_Portfolio_Q3-Q8'!B34+(1-$A28)*'Optimal_Portfolio_Q3-Q8'!B45 | F28: =$A28*'Optimal_Portfolio_Q3-Q8'!C34+(1-$A28)*'Optimal_Portfolio_Q3-Q8'!C45 | G28: =$A28*'Optimal_Portfolio_Q3-Q8'!D34+(1-$A28)*'Optimal_Portfolio_Q3-Q8'!D45 | H28: =$A28*'Optimal_Portfolio_Q3-Q8'!E34+(1-$A28)*'Optimal_Portfolio_Q3-Q8'!E45 | I28: =$A28*'Optimal_Portfolio_Q3-Q8'!F34+(1-$A28)*'Optimal_Portfolio_Q3-Q8'!F45 | J28: =$A28*'Optimal_Portfolio_Q3-Q8'!G34+(1-$A28)*'Optimal_Portfolio_Q3-Q8'!G45 | K28: =$A28*'Optimal_Portfolio_Q3-Q8'!H34+(1-$A28)*'Optimal_Portfolio_Q3-Q8'!H45 | L28: =$A28*'Optimal_Portfolio_Q3-Q8'!I34+(1-$A28)*'Optimal_Portfolio_Q3-Q8'!I45 | ... AA28: =$A28*'Optimal_Portfolio_Q3-Q8'!X34+(1-$A28)*'Optimal_Portfolio_Q3-Q8'!X45
A29: 0.4 | B29: =SUMPRODUCT(E29:AA29,'Optimal_Portfolio_Q3-Q8'!B31:X31) | C29: =SUMPRODUCT(E29:AA29,MMULT(E29:AA29,'Optimal_Portfolio_Q3-Q8'!B4:X26)) | E29: =$A29*'Optimal_Portfolio_Q3-Q8'!B34+(1-$A29)*'Optimal_Portfolio_Q3-Q8'!B45 | F29: =$A29*'Optimal_Portfolio_Q3-Q8'!C34+(1-$A29)*'Optimal_Portfolio_Q3-Q8'!C45 | G29: =$A29*'Optimal_Portfolio_Q3-Q8'!D34+(1-$A29)*'Optimal_Portfolio_Q3-Q8'!D45 | H29: =$A29*'Optimal_Portfolio_Q3-Q8'!E34+(1-$A29)*'Optimal_Portfolio_Q3-Q8'!E45 | I29: =$A29*'Optimal_Portfolio_Q3-Q8'!F34+(1-$A29)*'Optimal_Portfolio_Q3-Q8'!F45 | J29: =$A29*'Optimal_Portfolio_Q3-Q8'!G34+(1-$A29)*'Optimal_Portfolio_Q3-Q8'!G45 | K29: =$A29*'Optimal_Portfolio_Q3-Q8'!H34+(1-$A29)*'Optimal_Portfolio_Q3-Q8'!H45 | L29: =$A29*'Optimal_Portfolio_Q3-Q8'!I34+(1-$A29)*'Optimal_Portfolio_Q3-Q8'!I45 | ... AA29: =$A29*'Optimal_Portfolio_Q3-Q8'!X34+(1-$A29)*'Optimal_Portfolio_Q3-Q8'!X45
A30: 0.5 | B30: =SUMPRODUCT(E30:AA30,'Optimal_Portfolio_Q3-Q8'!B31:X31) | C30: =SUMPRODUCT(E30:AA30,MMULT(E30:AA30,'Optimal_Portfolio_Q3-Q8'!B4:X26)) | E30: =$A30*'Optimal_Portfolio_Q3-Q8'!B34+(1-$A30)*'Optimal_Portfolio_Q3-Q8'!B45 | F30: =$A30*'Optimal_Portfolio_Q3-Q8'!C34+(1-$A30)*'Optimal_Portfolio_Q3-Q8'!C45 | G30: =$A30*'Optimal_Portfolio_Q3-Q8'!D34+(1-$A30)*'Optimal_Portfolio_Q3-Q8'!D45 | H30: =$A30*'Optimal_Portfolio_Q3-Q8'!E34+(1-$A30)*'Optimal_Portfolio_Q3-Q8'!E45 | I30: =$A30*'Optimal_Portfolio_Q3-Q8'!F34+(1-$A30)*'Optimal_Portfolio_Q3-Q8'!F45 | J30: =$A30*'Optimal_Portfolio_Q3-Q8'!G34+(1-$A30)*'Optimal_Portfolio_Q3-Q8'!G45 | K30: =$A30*'Optimal_Portfolio_Q3-Q8'!H34+(1-$A30)*'Optimal_Portfolio_Q3-Q8'!H45 | L30: =$A30*'Optimal_Portfolio_Q3-Q8'!I34+(1-$A30)*'Optimal_Portfolio_Q3-Q8'!I45 | ... AA30: =$A30*'Optimal_Portfolio_Q3-Q8'!X34+(1-$A30)*'Optimal_Portfolio_Q3-Q8'!X45
A31: 0.6 | B31: =SUMPRODUCT(E31:AA31,'Optimal_Portfolio_Q3-Q8'!B31:X31) | C31: =SUMPRODUCT(E31:AA31,MMULT(E31:AA31,'Optimal_Portfolio_Q3-Q8'!B4:X26)) | E31: =$A31*'Optimal_Portfolio_Q3-Q8'!B34+(1-$A31)*'Optimal_Portfolio_Q3-Q8'!B45 | F31: =$A31*'Optimal_Portfolio_Q3-Q8'!C34+(1-$A31)*'Optimal_Portfolio_Q3-Q8'!C45 | G31: =$A31*'Optimal_Portfolio_Q3-Q8'!D34+(1-$A31)*'Optimal_Portfolio_Q3-Q8'!D45 | H31: =$A31*'Optimal_Portfolio_Q3-Q8'!E34+(1-$A31)*'Optimal_Portfolio_Q3-Q8'!E45 | I31: =$A31*'Optimal_Portfolio_Q3-Q8'!F34+(1-$A31)*'Optimal_Portfolio_Q3-Q8'!F45 | J31: =$A31*'Optimal_Portfolio_Q3-Q8'!G34+(1-$A31)*'Optimal_Portfolio_Q3-Q8'!G45 | K31: =$A31*'Optimal_Portfolio_Q3-Q8'!H34+(1-$A31)*'Optimal_Portfolio_Q3-Q8'!H45 | L31: =$A31*'Optimal_Portfolio_Q3-Q8'!I34+(1-$A31)*'Optimal_Portfolio_Q3-Q8'!I45 | ... AA31: =$A31*'Optimal_Portfolio_Q3-Q8'!X34+(1-$A31)*'Optimal_Portfolio_Q3-Q8'!X45
A32: 0.7 | B32: =SUMPRODUCT(E32:AA32,'Optimal_Portfolio_Q3-Q8'!B31:X31) | C32: =SUMPRODUCT(E32:AA32,MMULT(E32:AA32,'Optimal_Portfolio_Q3-Q8'!B4:X26)) | E32: =$A32*'Optimal_Portfolio_Q3-Q8'!B34+(1-$A32)*'Optimal_Portfolio_Q3-Q8'!B45 | F32: =$A32*'Optimal_Portfolio_Q3-Q8'!C34+(1-$A32)*'Optimal_Portfolio_Q3-Q8'!C45 | G32: =$A32*'Optimal_Portfolio_Q3-Q8'!D34+(1-$A32)*'Optimal_Portfolio_Q3-Q8'!D45 | H32: =$A32*'Optimal_Portfolio_Q3-Q8'!E34+(1-$A32)*'Optimal_Portfolio_Q3-Q8'!E45 | I32: =$A32*'Optimal_Portfolio_Q3-Q8'!F34+(1-$A32)*'Optimal_Portfolio_Q3-Q8'!F45 | J32: =$A32*'Optimal_Portfolio_Q3-Q8'!G34+(1-$A32)*'Optimal_Portfolio_Q3-Q8'!G45 | K32: =$A32*'Optimal_Portfolio_Q3-Q8'!H34+(1-$A32)*'Optimal_Portfolio_Q3-Q8'!H45 | L32: =$A32*'Optimal_Portfolio_Q3-Q8'!I34+(1-$A32)*'Optimal_Portfolio_Q3-Q8'!I45 | ... AA32: =$A32*'Optimal_Portfolio_Q3-Q8'!X34+(1-$A32)*'Optimal_Portfolio_Q3-Q8'!X45
A33: 0.8 | B33: =SUMPRODUCT(E33:AA33,'Optimal_Portfolio_Q3-Q8'!B31:X31) | C33: =SUMPRODUCT(E33:AA33,MMULT(E33:AA33,'Optimal_Portfolio_Q3-Q8'!B4:X26)) | E33: =$A33*'Optimal_Portfolio_Q3-Q8'!B34+(1-$A33)*'Optimal_Portfolio_Q3-Q8'!B45 | F33: =$A33*'Optimal_Portfolio_Q3-Q8'!C34+(1-$A33)*'Optimal_Portfolio_Q3-Q8'!C45 | G33: =$A33*'Optimal_Portfolio_Q3-Q8'!D34+(1-$A33)*'Optimal_Portfolio_Q3-Q8'!D45 | H33: =$A33*'Optimal_Portfolio_Q3-Q8'!E34+(1-$A33)*'Optimal_Portfolio_Q3-Q8'!E45 | I33: =$A33*'Optimal_Portfolio_Q3-Q8'!F34+(1-$A33)*'Optimal_Portfolio_Q3-Q8'!F45 | J33: =$A33*'Optimal_Portfolio_Q3-Q8'!G34+(1-$A33)*'Optimal_Portfolio_Q3-Q8'!G45 | K33: =$A33*'Optimal_Portfolio_Q3-Q8'!H34+(1-$A33)*'Optimal_Portfolio_Q3-Q8'!H45 | L33: =$A33*'Optimal_Portfolio_Q3-Q8'!I34+(1-$A33)*'Optimal_Portfolio_Q3-Q8'!I45 | ... AA33: =$A33*'Optimal_Portfolio_Q3-Q8'!X34+(1-$A33)*'Optimal_Portfolio_Q3-Q8'!X45
A34: 0.9 | B34: =SUMPRODUCT(E34:AA34,'Optimal_Portfolio_Q3-Q8'!B31:X31) | C34: =SUMPRODUCT(E34:AA34,MMULT(E34:AA34,'Optimal_Portfolio_Q3-Q8'!B4:X26)) | E34: =$A34*'Optimal_Portfolio_Q3-Q8'!B34+(1-$A34)*'Optimal_Portfolio_Q3-Q8'!B45 | F34: =$A34*'Optimal_Portfolio_Q3-Q8'!C34+(1-$A34)*'Optimal_Portfolio_Q3-Q8'!C45 | G34: =$A34*'Optimal_Portfolio_Q3-Q8'!D34+(1-$A34)*'Optimal_Portfolio_Q3-Q8'!D45 | H34: =$A34*'Optimal_Portfolio_Q3-Q8'!E34+(1-$A34)*'Optimal_Portfolio_Q3-Q8'!E45 | I34: =$A34*'Optimal_Portfolio_Q3-Q8'!F34+(1-$A34)*'Optimal_Portfolio_Q3-Q8'!F45 | J34: =$A34*'Optimal_Portfolio_Q3-Q8'!G34+(1-$A34)*'Optimal_Portfolio_Q3-Q8'!G45 | K34: =$A34*'Optimal_Portfolio_Q3-Q8'!H34+(1-$A34)*'Optimal_Portfolio_Q3-Q8'!H45 | L34: =$A34*'Optimal_Portfolio_Q3-Q8'!I34+(1-$A34)*'Optimal_Portfolio_Q3-Q8'!I45 | ... AA34: =$A34*'Optimal_Portfolio_Q3-Q8'!X34+(1-$A34)*'Optimal_Portfolio_Q3-Q8'!X45
A35: 1 | B35: =SUMPRODUCT(E35:AA35,'Optimal_Portfolio_Q3-Q8'!B31:X31) | C35: =SUMPRODUCT(E35:AA35,MMULT(E35:AA35,'Optimal_Portfolio_Q3-Q8'!B4:X26)) | E35: =$A35*'Optimal_Portfolio_Q3-Q8'!B34+(1-$A35)*'Optimal_Portfolio_Q3-Q8'!B45 | F35: =$A35*'Optimal_Portfolio_Q3-Q8'!C34+(1-$A35)*'Optimal_Portfolio_Q3-Q8'!C45 | G35: =$A35*'Optimal_Portfolio_Q3-Q8'!D34+(1-$A35)*'Optimal_Portfolio_Q3-Q8'!D45 | H35: =$A35*'Optimal_Portfolio_Q3-Q8'!E34+(1-$A35)*'Optimal_Portfolio_Q3-Q8'!E45 | I35: =$A35*'Optimal_Portfolio_Q3-Q8'!F34+(1-$A35)*'Optimal_Portfolio_Q3-Q8'!F45 | J35: =$A35*'Optimal_Portfolio_Q3-Q8'!G34+(1-$A35)*'Optimal_Portfolio_Q3-Q8'!G45 | K35: =$A35*'Optimal_Portfolio_Q3-Q8'!H34+(1-$A35)*'Optimal_Portfolio_Q3-Q8'!H45 | L35: =$A35*'Optimal_Portfolio_Q3-Q8'!I34+(1-$A35)*'Optimal_Portfolio_Q3-Q8'!I45 | ... AA35: =$A35*'Optimal_Portfolio_Q3-Q8'!X34+(1-$A35)*'Optimal_Portfolio_Q3-Q8'!X45
A36: 1.1 | B36: =SUMPRODUCT(E36:AA36,'Optimal_Portfolio_Q3-Q8'!B31:X31) | C36: =SUMPRODUCT(E36:AA36,MMULT(E36:AA36,'Optimal_Portfolio_Q3-Q8'!B4:X26)) | E36: =$A36*'Optimal_Portfolio_Q3-Q8'!B34+(1-$A36)*'Optimal_Portfolio_Q3-Q8'!B45 | F36: =$A36*'Optimal_Portfolio_Q3-Q8'!C34+(1-$A36)*'Optimal_Portfolio_Q3-Q8'!C45 | G36: =$A36*'Optimal_Portfolio_Q3-Q8'!D34+(1-$A36)*'Optimal_Portfolio_Q3-Q8'!D45 | H36: =$A36*'Optimal_Portfolio_Q3-Q8'!E34+(1-$A36)*'Optimal_Portfolio_Q3-Q8'!E45 | I36: =$A36*'Optimal_Portfolio_Q3-Q8'!F34+(1-$A36)*'Optimal_Portfolio_Q3-Q8'!F45 | J36: =$A36*'Optimal_Portfolio_Q3-Q8'!G34+(1-$A36)*'Optimal_Portfolio_Q3-Q8'!G45 | K36: =$A36*'Optimal_Portfolio_Q3-Q8'!H34+(1-$A36)*'Optimal_Portfolio_Q3-Q8'!H45 | L36: =$A36*'Optimal_Portfolio_Q3-Q8'!I34+(1-$A36)*'Optimal_Portfolio_Q3-Q8'!I45 | ... AA36: =$A36*'Optimal_Portfolio_Q3-Q8'!X34+(1-$A36)*'Optimal_Portfolio_Q3-Q8'!X45
A37: 1.2 | B37: =SUMPRODUCT(E37:AA37,'Optimal_Portfolio_Q3-Q8'!B31:X31) | C37: =SUMPRODUCT(E37:AA37,MMULT(E37:AA37,'Optimal_Portfolio_Q3-Q8'!B4:X26)) | E37: =$A37*'Optimal_Portfolio_Q3-Q8'!B34+(1-$A37)*'Optimal_Portfolio_Q3-Q8'!B45 | F37: =$A37*'Optimal_Portfolio_Q3-Q8'!C34+(1-$A37)*'Optimal_Portfolio_Q3-Q8'!C45 | G37: =$A37*'Optimal_Portfolio_Q3-Q8'!D34+(1-$A37)*'Optimal_Portfolio_Q3-Q8'!D45 | H37: =$A37*'Optimal_Portfolio_Q3-Q8'!E34+(1-$A37)*'Optimal_Portfolio_Q3-Q8'!E45 | I37: =$A37*'Optimal_Portfolio_Q3-Q8'!F34+(1-$A37)*'Optimal_Portfolio_Q3-Q8'!F45 | J37: =$A37*'Optimal_Portfolio_Q3-Q8'!G34+(1-$A37)*'Optimal_Portfolio_Q3-Q8'!G45 | K37: =$A37*'Optimal_Portfolio_Q3-Q8'!H34+(1-$A37)*'Optimal_Portfolio_Q3-Q8'!H45 | L37: =$A37*'Optimal_Portfolio_Q3-Q8'!I34+(1-$A37)*'Optimal_Portfolio_Q3-Q8'!I45 | ... AA37: =$A37*'Optimal_Portfolio_Q3-Q8'!X34+(1-$A37)*'Optimal_Portfolio_Q3-Q8'!X45
A38: 1.3 | B38: =SUMPRODUCT(E38:AA38,'Optimal_Portfolio_Q3-Q8'!B31:X31) | C38: =SUMPRODUCT(E38:AA38,MMULT(E38:AA38,'Optimal_Portfolio_Q3-Q8'!B4:X26)) | E38: =$A38*'Optimal_Portfolio_Q3-Q8'!B34+(1-$A38)*'Optimal_Portfolio_Q3-Q8'!B45 | F38: =$A38*'Optimal_Portfolio_Q3-Q8'!C34+(1-$A38)*'Optimal_Portfolio_Q3-Q8'!C45 | G38: =$A38*'Optimal_Portfolio_Q3-Q8'!D34+(1-$A38)*'Optimal_Portfolio_Q3-Q8'!D45 | H38: =$A38*'Optimal_Portfolio_Q3-Q8'!E34+(1-$A38)*'Optimal_Portfolio_Q3-Q8'!E45 | I38: =$A38*'Optimal_Portfolio_Q3-Q8'!F34+(1-$A38)*'Optimal_Portfolio_Q3-Q8'!F45 | J38: =$A38*'Optimal_Portfolio_Q3-Q8'!G34+(1-$A38)*'Optimal_Portfolio_Q3-Q8'!G45 | K38: =$A38*'Optimal_Portfolio_Q3-Q8'!H34+(1-$A38)*'Optimal_Portfolio_Q3-Q8'!H45 | L38: =$A38*'Optimal_Portfolio_Q3-Q8'!I34+(1-$A38)*'Optimal_Portfolio_Q3-Q8'!I45 | ... AA38: =$A38*'Optimal_Portfolio_Q3-Q8'!X34+(1-$A38)*'Optimal_Portfolio_Q3-Q8'!X45
A39: 1.4 | B39: =SUMPRODUCT(E39:AA39,'Optimal_Portfolio_Q3-Q8'!B31:X31) | C39: =SUMPRODUCT(E39:AA39,MMULT(E39:AA39,'Optimal_Portfolio_Q3-Q8'!B4:X26)) | E39: =$A39*'Optimal_Portfolio_Q3-Q8'!B34+(1-$A39)*'Optimal_Portfolio_Q3-Q8'!B45 | F39: =$A39*'Optimal_Portfolio_Q3-Q8'!C34+(1-$A39)*'Optimal_Portfolio_Q3-Q8'!C45 | G39: =$A39*'Optimal_Portfolio_Q3-Q8'!D34+(1-$A39)*'Optimal_Portfolio_Q3-Q8'!D45 | H39: =$A39*'Optimal_Portfolio_Q3-Q8'!E34+(1-$A39)*'Optimal_Portfolio_Q3-Q8'!E45 | I39: =$A39*'Optimal_Portfolio_Q3-Q8'!F34+(1-$A39)*'Optimal_Portfolio_Q3-Q8'!F45 | J39: =$A39*'Optimal_Portfolio_Q3-Q8'!G34+(1-$A39)*'Optimal_Portfolio_Q3-Q8'!G45 | K39: =$A39*'Optimal_Portfolio_Q3-Q8'!H34+(1-$A39)*'Optimal_Portfolio_Q3-Q8'!H45 | L39: =$A39*'Optimal_Portfolio_Q3-Q8'!I34+(1-$A39)*'Optimal_Portfolio_Q3-Q8'!I45 | ... AA39: =$A39*'Optimal_Portfolio_Q3-Q8'!X34+(1-$A39)*'Optimal_Portfolio_Q3-Q8'!X45
A40: 1.5 | B40: =SUMPRODUCT(E40:AA40,'Optimal_Portfolio_Q3-Q8'!B31:X31) | C40: =SUMPRODUCT(E40:AA40,MMULT(E40:AA40,'Optimal_Portfolio_Q3-Q8'!B4:X26)) | E40: =$A40*'Optimal_Portfolio_Q3-Q8'!B34+(1-$A40)*'Optimal_Portfolio_Q3-Q8'!B45 | F40: =$A40*'Optimal_Portfolio_Q3-Q8'!C34+(1-$A40)*'Optimal_Portfolio_Q3-Q8'!C45 | G40: =$A40*'Optimal_Portfolio_Q3-Q8'!D34+(1-$A40)*'Optimal_Portfolio_Q3-Q8'!D45 | H40: =$A40*'Optimal_Portfolio_Q3-Q8'!E34+(1-$A40)*'Optimal_Portfolio_Q3-Q8'!E45 | I40: =$A40*'Optimal_Portfolio_Q3-Q8'!F34+(1-$A40)*'Optimal_Portfolio_Q3-Q8'!F45 | J40: =$A40*'Optimal_Portfolio_Q3-Q8'!G34+(1-$A40)*'Optimal_Portfolio_Q3-Q8'!G45 | K40: =$A40*'Optimal_Portfolio_Q3-Q8'!H34+(1-$A40)*'Optimal_Portfolio_Q3-Q8'!H45 | L40: =$A40*'Optimal_Portfolio_Q3-Q8'!I34+(1-$A40)*'Optimal_Portfolio_Q3-Q8'!I45 | ... AA40: =$A40*'Optimal_Portfolio_Q3-Q8'!X34+(1-$A40)*'Optimal_Portfolio_Q3-Q8'!X45
A41: 1.6 | B41: =SUMPRODUCT(E41:AA41,'Optimal_Portfolio_Q3-Q8'!B31:X31) | C41: =SUMPRODUCT(E41:AA41,MMULT(E41:AA41,'Optimal_Portfolio_Q3-Q8'!B4:X26)) | E41: =$A41*'Optimal_Portfolio_Q3-Q8'!B34+(1-$A41)*'Optimal_Portfolio_Q3-Q8'!B45 | F41: =$A41*'Optimal_Portfolio_Q3-Q8'!C34+(1-$A41)*'Optimal_Portfolio_Q3-Q8'!C45 | G41: =$A41*'Optimal_Portfolio_Q3-Q8'!D34+(1-$A41)*'Optimal_Portfolio_Q3-Q8'!D45 | H41: =$A41*'Optimal_Portfolio_Q3-Q8'!E34+(1-$A41)*'Optimal_Portfolio_Q3-Q8'!E45 | I41: =$A41*'Optimal_Portfolio_Q3-Q8'!F34+(1-$A41)*'Optimal_Portfolio_Q3-Q8'!F45 | J41: =$A41*'Optimal_Portfolio_Q3-Q8'!G34+(1-$A41)*'Optimal_Portfolio_Q3-Q8'!G45 | K41: =$A41*'Optimal_Portfolio_Q3-Q8'!H34+(1-$A41)*'Optimal_Portfolio_Q3-Q8'!H45 | L41: =$A41*'Optimal_Portfolio_Q3-Q8'!I34+(1-$A41)*'Optimal_Portfolio_Q3-Q8'!I45 | ... AA41: =$A41*'Optimal_Portfolio_Q3-Q8'!X34+(1-$A41)*'Optimal_Portfolio_Q3-Q8'!X45
...

Sheet Returns_2018
A1: date | B1: IBM | C1: GE | D1: LLY | E1: F | F1: BAC | G1: KR | H1: ITUB | I1: GG | J1: SIRI | K1: ACB | L1: VALE | M1: PFE | N1: CTL | O1: T | P1: ECA | Q1: ABEV | R1: CVS | S1: MRVL | T1: CSCO | U1: MO | V1: BMY | W1: WFC | X1: HBAN
A2: 2018-01-02 | B2: 0.027116872 | C2: 0.00941054 | D2: 0.0054175034 | E2: 0.0078678912 | F2: -0.0033500997 | G2: -0.016028798 | H2: 0.013216038 | I2: 0.0082862738 | J2: 0 | K2: 0.17650306 | L2: 0.0062451351 | M2: 0.0073821379 | N2: -0.019136561 | O2: -0.023363692 | P2: 0.0058139642 | Q2: 0.0060331949 | R2: -0.0043620531 | S2: 0.030607784 | T2: 0.0079456413 | U2: -0.0036821243 | V2: 0.00081518283 | W2: 0.0076641421 | X2: 0.0081855766
A3: 2018-01-03 | B3: 0.020051213 | C3: 0.020720504 | D3: 0.0044532742 | E3: 0.01709438 | F3: 0.013002393 | G3: -0.031737146 | H3: 0.012323398 | I3: 0.0044910569 | J3: 0.019011961 | K3: -0.079085367 | L3: -0.0015576683 | M3: 0.0021769214 | N3: -0.0064611451 | O3: 0.009253165 | P3: -0.024203596 | Q3: -0.0015049256 | R3: 0.026024531 | S3: 0.022463168 | T3: -0.0046058549 | U3: -0.0039807617 | V3: 0.0063358085 | W3: 0.012430549 | X3: 0.0087927595
A4: 2018-01-04 | B4: 0.0048737475 | C4: 0.00053949513 | D4: 0.012203104 | E4: 0.016807139 | F4: 0.0046265578 | G4: 0.01252319 | H4: 0.01217348 | I4: 0.0022379519 | J4: 0.0037593994 | K4: 0.01519496 | L4: 0.020062419 | M4: 0.0019008748 | N4: 0.0017663053 | O4: 0.0036774244 | P4: -0.0089485968 | Q4: 0.004507928 | R4: 0.04324153 | S4: -0.017669059 | T4: 0.0137546 | U4: 0.0028450173 | V4: 0.0022646304 | W4: 0.0067156978 | X4: 0.0087160566
A5: 2018-01-05 | B5: 0.0060129995 | C5: -0.014122994 | D5: -0.0050955808 | E5: -0.0037950855 | F5: -0.0069478884 | G5: 0.023513459 | H5: -0.01361544 | I5: 0.0081632852 | J5: -0.0037593994 | K5: 0.052776712 | L5: 0.017418051 | M5: -0.011185489 | N5: 0.01343868 | O5: 0.0028799761 | P5: -0.0030007495 | Q5: -0.0075245187 | R5: -0.0087057307 | S5: 0.0073641258 | T5: 0.010318447 | U5: -0.0012792834 | V5: 0.00032310918 | W5: -0.011379225 | X5: -0.0020046605
A6: 2018-01-08 | B6: 0.0021998213 | C6: 0.015201112 | D6: -0.00081305187 | E6: -0.0053373894 | F6: 0.0049677074 | G6: -0.0071761649 | H6: -0.013072069 | I6: 0 | J6: 0 | K6: -0.022056433 | L6: -0.006024109 | M6: -0.0010980214 | N6: -0.040870279 | O6: -0.020069285 | P6: 0.024491014 | Q6: -0.0060606189 | R6: -0.0010291292 | S6: -0.00086357768 | T6: -0.0062790614 | U6: -0.010580566 | V6: -0.0009696409 | W6: 0.003539785 | X6: 0.01855585
