Workbook

Sheet Answers
A1: Practice Set 3 - Delta-hedging P&L and realized volatility: worked answers
A3: SETUP. At t=0 we sell 100,000 European calls (K=50, T=0.25y) for the Black-Scholes premium computed with a 30% IMPLIED volatility,
A4: and we delta-hedge them with a self-financing portfolio rebalanced 50 times. Holding x_t = N(d1)*100,000 shares and c_t = V_t - x_t*S_t in cash,
A5: the portfolio rolls forward as V_t+1 = x_t*S_t+1 + c_t*EXP(r*dt), dt = T/50 = 0.005 years. No money is ever added or taken out.
A7: ANSWER 1 (volatility). u_t = LN(S_t / S_t-1) for t = 1..50. Annualized realized vol = STDEV(u_1..u_50) / SQRT(dt) = STDEV(...) * SQRT(200).
A8: STDEV (sample, n-1) is the right convention: it reproduces DemoSheet!N2 exactly; STDEVP does not.
A9: ANSWER 2 (P&L). Total hedging P&L = V_50 - 100,000 * MAX(S_50 - K, 0) = final portfolio value minus the option payoff (DemoSheet!B11).
A11: Each answer below is a LIVE formula pointing at the sheet PathN_Hedge, where the whole 51-row table is itself built from live Excel formulas.
A12: DemoCheck_Hedge applies the identical construction to the worked example: its L19 reproduces DemoSheet!B11 = 55,394, which validates the method.
A14: Q | B14: Path | C14: Quantity | D14: Excel answer (live formula) | E14: Python answer | F14: SUBMIT
A15: 1 | B15: #1 | C15: Annualized realized volatility of log-returns (%) | D15: =Path1_Hedge!$L$14 | E15: 25.42 | F15: 25.42
A16: 2 | B16: #1 | C16: Total realized P&L when delta-hedging ($) | D16: =Path1_Hedge!$L$19 | E16: 46625 | F16: 46625
A17: 3 | B17: #2 | C17: Annualized realized volatility of log-returns (%) | D17: =Path2_Hedge!$L$14 | E17: 30.36 | F17: 30.36
A18: 4 | B18: #2 | C18: Total realized P&L when delta-hedging ($) | D18: =Path2_Hedge!$L$19 | E18: -20263 | F18: -20263
A19: 5 | B19: #3 | C19: Annualized realized volatility of log-returns (%) | D19: =Path3_Hedge!$L$14 | E19: 51.57 | F19: 51.57
A20: 6 | B20: #3 | C20: Total realized P&L when delta-hedging ($) | D20: =Path3_Hedge!$L$19 | E20: -122867 | F20: -122867
A21: 7 | B21: #4 | C21: Annualized realized volatility of log-returns (%) | D21: =Path4_Hedge!$L$14 | E21: 40.14 | F21: 40.14
A22: 8 | B22: #4 | C22: Total realized P&L when delta-hedging ($) | D22: =Path4_Hedge!$L$19 | E22: -104401 | F22: -104401
A24: REALIZED vs IMPLIED VOLATILITY
A25: Path | B25: Realized vol | C25: Implied vol | D25: Gap (real - implied) | E25: S_T | F25: Option payoff | G25: Final portfolio V_T | H25: Hedging P&L | I25: Verdict
A26: Path 1 | B26: =Path1_Hedge!$L$13 | C26: =DemoSheet!$B$4 | D26: =B26-C26 | E26: =Path1_Hedge!$L$15 | F26: =Path1_Hedge!$L$16 | G26: =Path1_Hedge!$L$17 | H26: =Path1_Hedge!$L$18 | I26: =IF(B26<C26,"calmer than implied -> hedging PROFIT","wilder than implied -> hedging LOSS")
A27: Path 2 | B27: =Path2_Hedge!$L$13 | C27: =DemoSheet!$B$4 | D27: =B27-C27 | E27: =Path2_Hedge!$L$15 | F27: =Path2_Hedge!$L$16 | G27: =Path2_Hedge!$L$17 | H27: =Path2_Hedge!$L$18 | I27: =IF(B27<C27,"calmer than implied -> hedging PROFIT","wilder than implied -> hedging LOSS")
A28: Path 3 | B28: =Path3_Hedge!$L$13 | C28: =DemoSheet!$B$4 | D28: =B28-C28 | E28: =Path3_Hedge!$L$15 | F28: =Path3_Hedge!$L$16 | G28: =Path3_Hedge!$L$17 | H28: =Path3_Hedge!$L$18 | I28: =IF(B28<C28,"calmer than implied -> hedging PROFIT","wilder than implied -> hedging LOSS")
A29: Path 4 | B29: =Path4_Hedge!$L$13 | C29: =DemoSheet!$B$4 | D29: =B29-C29 | E29: =Path4_Hedge!$L$15 | F29: =Path4_Hedge!$L$16 | G29: =Path4_Hedge!$L$17 | H29: =Path4_Hedge!$L$18 | I29: =IF(B29<C29,"calmer than implied -> hedging PROFIT","wilder than implied -> hedging LOSS")
A31: VALIDATION: DemoCheck_Hedge!L19 must equal DemoSheet!B11 (= 55,394). Live check -> | D31: =DemoCheck_Hedge!$L$19 | E31: =DemoSheet!$B$11 | F31: =IF(ROUND(D31-E31,0)=0,"MATCH","CHECK")
A33: CONCLUSION. Selling and delta-hedging an option is a bet on volatility, not on direction:
A34: * Path #1 realizes 25.42%, BELOW the 30% we charged: the stock moved less than we were paid for, so the hedge profits (+46,625).
A35: * Path #2 realizes 30.36%, essentially AT implied: theory says P&L ~ 0; the -20,263 left over is discrete-hedging error (we rebalance 50 times, not continuously).
A36: * Path #3 realizes 51.57% and Path #4 realizes 40.14%, well ABOVE implied: both lose heavily (-122,867 and -104,401).
A37: * Direction is irrelevant. Path #3 finishes deep in the money and Path #4 finishes worthless, yet BOTH lose money, because both were far more volatile than 30%.
A38: Path #4's loss is burned in the whipsawing hedge (buying high, selling low), even though the option it hedged expired worthless.
A39: * Rule of thumb: P&L ~ 0.5 * INTEGRAL[ exp(r(T-t)) * S_t^2 * Gamma_t * (sigma_implied^2 - sigma_realized^2) ] dt -> positive only when implied > realized.

Sheet DemoSheet
A1: European Call Option Parameters | D1: Period | E1: Stock Price | F1: S.F. Portfolio Value | G1: "d1" | H1: # Stocks held | I1: Cash Account $ Position | M1: Avg Return (Annualized) | N1: Std Return (Annualized)
A2: Initial Stock Price | B2: 50 | D2: 0 | E2: 50 | F2: 310815.12 | G2: 0.10833333 | H2: 54313.436 | I2: -2404856.7 | L2: Log-Returns | M2: 0.33794343 | N2: 0.24901388
A3: Expiration | B3: 0.25 | D3: 1 | E3: 49.507226 | F3: 283810.38 | G3: 0.040545076 | H3: 51617.071 | I3: -2271607.6 | L3: -0.0099043634
A4: Implied Volatility | B4: 0.3 | D4: 2 | E4: 48.005821 | F4: 206085.05 | G4: -0.1707889 | H4: 43219.488 | I4: -1868701.9 | L4: -0.030796375
A5: Risk-Free Rate | B5: 0.02 | D5: 3 | E5: 47.765455 | F5: 195509.68 | G5: -0.20934642 | H5: 41708.891 | I5: -1796734.4 | L5: -0.0050195944
A6: Strike | B6: 50 | D6: 4 | E6: 47.946162 | F6: 202867.1 | G6: -0.18762301 | H6: 42558.609 | I6: -1837654.9 | L6: 0.0037760829
A7: # of Options | B7: 100000 | D7: 5 | E7: 48.675265 | F7: 233712.94 | G7: -0.085922673 | H7: 46576.394 | I7: -2033405.4 | L7: 0.01509224
A8: # of Hedging Periods | B8: 50 | D8: 6 | E8: 48.879096 | F8: 243003.28 | G8: -0.059505691 | H8: 47627.467 | I8: -2084984.2 | L8: 0.0041788177
A9: "d_1" | B9: 0.10833333 | D9: 7 | E9: 49.279433 | F9: 261861.85 | G9: -0.0038904769 | H9: 49844.793 | I9: -2194461.3 | L9: 0.008157011
A10: Total BS Option Price | B10: 310815.12 | D10: 8 | E10: 50.190454 | F10: 307052.03 | G10: 0.12694352 | H10: 55050.745 | I10: -2455969.9 | L10: 0.018318031
A11: Total Hedging P&L | B11: 55393.577 | D11: 9 | E11: 49.961242 | F11: 294188.1 | G11: 0.092390923 | H11: 53680.627 | I11: -2387762.7 | L11: -0.0045773178
D12: 10 | E12: 50.843417 | F12: 341305.06 | G12: 0.22157687 | H12: 58767.835 | I12: -2646652.5 | L12: 0.017503126
D13: 11 | E13: 51.472769 | F13: 378026.04 | G13: 0.31481011 | H13: 62354.708 | I13: -2831543.5 | L13: 0.012302257
D14: 12 | E14: 52.021059 | F14: 411931.31 | G14: 0.39746745 | H14: 65448.861 | I14: -2992787.7 | L14: 0.010595699
D15: 13 | E15: 52.697966 | F15: 455934.83 | G15: 0.50047601 | H15: 69163.003 | I15: -3188814.8 | L15: 0.012928249
D16: 14 | E16: 51.728483 | F16: 388563.52 | G16: 0.35893954 | H16: 64017.984 | I16: -2922989.6 | L16: -0.018568317
D17: 15 | E17: 52.552503 | F17: 441023.31 | G17: 0.4873721 | H17: 68700.267 | I17: -3169347.7 | L17: 0.015804169
D18: 16 | E18: 50.925201 | F18: 328910.31 | G18: 0.23756287 | H18: 59388.993 | I18: -2695486.1 | L18: -0.031454809
D19: 17 | E19: 50.188991 | F19: 284917.94 | G19: 0.11896945 | H19: 54735.022 | I19: -2462177.6 | L19: -0.014562219
D20: 18 | E20: 51.969065 | F20: 382104.11 | G20: 0.40854687 | H20: 65856.389 | I20: -3040390.8 | L20: 0.034852939
D21: 19 | E21: 52.980929 | F21: 448437.8 | G21: 0.57559859 | H21: 71755.673 | I21: -3353244.4 | L21: 0.019283392
D22: 20 | E22: 52.111638 | F22: 385725.85 | G22: 0.43993034 | H22: 67000.622 | I22: -3105786.3 | L22: -0.01654373
D23: 21 | E23: 51.120443 | F23: 319004.64 | G23: 0.27650053 | H23: 60891.817 | I23: -2793812.1 | L23: -0.019203807
... D51: 49 | E51: 53.570821 | F51: 413015.33 | G51: 3.2671415 | H51: 99945.68 | I51: -4941156.9 | L51: 0.04079405
D52: 50 | E52: 54.407873 | F52: 496180.85 | L52: 0.015504319

Sheet StockPricePaths
A1: Period | B1: Stock Path # 1 | C1: Stock Path # 2 | D1: Stock Path # 3 | E1: Stock Path # 4
A2: 0 | B2: 50 | C2: 50 | D2: 50 | E2: =B2
A3: =A2+1 | B3: 49.672466 | C3: 49.177203 | D3: 48.66991 | E3: 47.640628
A4: =A3+1 | B4: 49.625614 | C4: 49.818076 | D4: 46.169337 | E4: 49.449656
A5: =A4+1 | B5: 49.743893 | C5: 51.179055 | D5: 47.481015 | E5: 49.372705
A6: =A5+1 | B6: 50.215642 | C6: 50.332767 | D6: 49.034295 | E6: 49.947589
A7: =A6+1 | B7: 48.356972 | C7: 52.619256 | D7: 48.263274 | E7: 47.819475
A8: =A7+1 | B8: 48.741614 | C8: 54.685272 | D8: 47.894761 | E8: 44.883729
A9: =A8+1 | B9: 50.075533 | C9: 56.008341 | D9: 52.309947 | E9: 47.058018
A10: =A9+1 | B10: 49.634212 | C10: 56.069325 | D10: 53.255408 | E10: 45.955043
A11: =A10+1 | B11: 48.392042 | C11: 56.525448 | D11: 53.182812 | E11: 47.55577
A12: =A11+1 | B12: 48.19366 | C12: 56.38809 | D12: 55.004763 | E12: 47.32946
A13: =A12+1 | B13: 48.954316 | C13: 55.187382 | D13: 54.179706 | E13: 46.027518
A14: =A13+1 | B14: 48.572178 | C14: 55.611357 | D14: 52.222247 | E14: 45.262779
... A52: =A51+1 | B52: 48.208999 | C52: 54.555658 | D52: 64.036909 | E52: 42.999052

Sheet Path1_Hedge
A1: Period t | B1: Stock Price S_t | C1: Time to maturity (T-t) | D1: d1 | E1: Delta = N(d1) | F1: # Stocks held x_t | G1: S.F. Portfolio Value V_t | H1: Cash Account $ c_t | I1: Log-return ln(S_t/S_t-1) | K1: Parameter | L1: Value
A2: 0 | B2: =StockPricePaths!B2 | C2: =$L$3-A2*$L$9 | D2: =(LN(B2/$L$6)+($L$5+0.5*$L$4^2)*C2)/($L$4*SQRT(C2)) | E2: =NORMSDIST(D2) | F2: =E2*$L$7 | G2: =$L$7*(B2*NORMSDIST(D2)-$L$6*EXP(-$L$5*C2)*NORMSDIST(D2-$L$4*SQRT(C2))) | H2: =G2-F2*B2 | K2: Initial stock price S0 | L2: =DemoSheet!$B$2
A3: =A2+1 | B3: =StockPricePaths!B3 | C3: =$L$3-A3*$L$9 | D3: =(LN(B3/$L$6)+($L$5+0.5*$L$4^2)*C3)/($L$4*SQRT(C3)) | E3: =NORMSDIST(D3) | F3: =E3*$L$7 | G3: =F2*B3+H2*EXP($L$5*$L$9) | H3: =G3-F3*B3 | I3: =LN(B3/B2) | K3: Expiration T (years) | L3: =DemoSheet!$B$3
A4: =A3+1 | B4: =StockPricePaths!B4 | C4: =$L$3-A4*$L$9 | D4: =(LN(B4/$L$6)+($L$5+0.5*$L$4^2)*C4)/($L$4*SQRT(C4)) | E4: =NORMSDIST(D4) | F4: =E4*$L$7 | G4: =F3*B4+H3*EXP($L$5*$L$9) | H4: =G4-F4*B4 | I4: =LN(B4/B3) | K4: Implied volatility | L4: =DemoSheet!$B$4
A5: =A4+1 | B5: =StockPricePaths!B5 | C5: =$L$3-A5*$L$9 | D5: =(LN(B5/$L$6)+($L$5+0.5*$L$4^2)*C5)/($L$4*SQRT(C5)) | E5: =NORMSDIST(D5) | F5: =E5*$L$7 | G5: =F4*B5+H4*EXP($L$5*$L$9) | H5: =G5-F5*B5 | I5: =LN(B5/B4) | K5: Risk-free rate r | L5: =DemoSheet!$B$5
A6: =A5+1 | B6: =StockPricePaths!B6 | C6: =$L$3-A6*$L$9 | D6: =(LN(B6/$L$6)+($L$5+0.5*$L$4^2)*C6)/($L$4*SQRT(C6)) | E6: =NORMSDIST(D6) | F6: =E6*$L$7 | G6: =F5*B6+H5*EXP($L$5*$L$9) | H6: =G6-F6*B6 | I6: =LN(B6/B5) | K6: Strike K | L6: =DemoSheet!$B$6
A7: =A6+1 | B7: =StockPricePaths!B7 | C7: =$L$3-A7*$L$9 | D7: =(LN(B7/$L$6)+($L$5+0.5*$L$4^2)*C7)/($L$4*SQRT(C7)) | E7: =NORMSDIST(D7) | F7: =E7*$L$7 | G7: =F6*B7+H6*EXP($L$5*$L$9) | H7: =G7-F7*B7 | I7: =LN(B7/B6) | K7: # of options sold | L7: =DemoSheet!$B$7
A8: =A7+1 | B8: =StockPricePaths!B8 | C8: =$L$3-A8*$L$9 | D8: =(LN(B8/$L$6)+($L$5+0.5*$L$4^2)*C8)/($L$4*SQRT(C8)) | E8: =NORMSDIST(D8) | F8: =E8*$L$7 | G8: =F7*B8+H7*EXP($L$5*$L$9) | H8: =G8-F8*B8 | I8: =LN(B8/B7) | K8: # of hedging periods | L8: =DemoSheet!$B$8
A9: =A8+1 | B9: =StockPricePaths!B9 | C9: =$L$3-A9*$L$9 | D9: =(LN(B9/$L$6)+($L$5+0.5*$L$4^2)*C9)/($L$4*SQRT(C9)) | E9: =NORMSDIST(D9) | F9: =E9*$L$7 | G9: =F8*B9+H8*EXP($L$5*$L$9) | H9: =G9-F9*B9 | I9: =LN(B9/B8) | K9: dt = T / # periods | L9: =L3/L8
A10: =A9+1 | B10: =StockPricePaths!B10 | C10: =$L$3-A10*$L$9 | D10: =(LN(B10/$L$6)+($L$5+0.5*$L$4^2)*C10)/($L$4*SQRT(C10)) | E10: =NORMSDIST(D10) | F10: =E10*$L$7 | G10: =F9*B10+H9*EXP($L$5*$L$9) | H10: =G10-F10*B10 | I10: =LN(B10/B9)
A11: =A10+1 | B11: =StockPricePaths!B11 | C11: =$L$3-A11*$L$9 | D11: =(LN(B11/$L$6)+($L$5+0.5*$L$4^2)*C11)/($L$4*SQRT(C11)) | E11: =NORMSDIST(D11) | F11: =E11*$L$7 | G11: =F10*B11+H10*EXP($L$5*$L$9) | H11: =G11-F11*B11 | I11: =LN(B11/B10) | K11: RESULTS
A12: =A11+1 | B12: =StockPricePaths!B12 | C12: =$L$3-A12*$L$9 | D12: =(LN(B12/$L$6)+($L$5+0.5*$L$4^2)*C12)/($L$4*SQRT(C12)) | E12: =NORMSDIST(D12) | F12: =E12*$L$7 | G12: =F11*B12+H11*EXP($L$5*$L$9) | H12: =G12-F12*B12 | I12: =LN(B12/B11) | K12: Mean log-return (annualized) | L12: =AVERAGE(I3:I52)/$L$9
A13: =A12+1 | B13: =StockPricePaths!B13 | C13: =$L$3-A13*$L$9 | D13: =(LN(B13/$L$6)+($L$5+0.5*$L$4^2)*C13)/($L$4*SQRT(C13)) | E13: =NORMSDIST(D13) | F13: =E13*$L$7 | G13: =F12*B13+H12*EXP($L$5*$L$9) | H13: =G13-F13*B13 | I13: =LN(B13/B12) | K13: Realized volatility (annualized) | L13: =STDEV(I3:I52)/SQRT($L$9)
A14: =A13+1 | B14: =StockPricePaths!B14 | C14: =$L$3-A14*$L$9 | D14: =(LN(B14/$L$6)+($L$5+0.5*$L$4^2)*C14)/($L$4*SQRT(C14)) | E14: =NORMSDIST(D14) | F14: =E14*$L$7 | G14: =F13*B14+H13*EXP($L$5*$L$9) | H14: =G14-F14*B14 | I14: =LN(B14/B13) | K14: ANSWER - realized vol in %, 2 dp | L14: =ROUND(L13*100,2)
A15: =A14+1 | B15: =StockPricePaths!B15 | C15: =$L$3-A15*$L$9 | D15: =(LN(B15/$L$6)+($L$5+0.5*$L$4^2)*C15)/($L$4*SQRT(C15)) | E15: =NORMSDIST(D15) | F15: =E15*$L$7 | G15: =F14*B15+H14*EXP($L$5*$L$9) | H15: =G15-F15*B15 | I15: =LN(B15/B14) | K15: Terminal stock price S_T | L15: =B52
A16: =A15+1 | B16: =StockPricePaths!B16 | C16: =$L$3-A16*$L$9 | D16: =(LN(B16/$L$6)+($L$5+0.5*$L$4^2)*C16)/($L$4*SQRT(C16)) | E16: =NORMSDIST(D16) | F16: =E16*$L$7 | G16: =F15*B16+H15*EXP($L$5*$L$9) | H16: =G16-F16*B16 | I16: =LN(B16/B15) | K16: Option payoff = # options x MAX(S_T-K,0) | L16: =MAX(L15-$L$6,0)*$L$7
A17: =A16+1 | B17: =StockPricePaths!B17 | C17: =$L$3-A17*$L$9 | D17: =(LN(B17/$L$6)+($L$5+0.5*$L$4^2)*C17)/($L$4*SQRT(C17)) | E17: =NORMSDIST(D17) | F17: =E17*$L$7 | G17: =F16*B17+H16*EXP($L$5*$L$9) | H17: =G17-F17*B17 | I17: =LN(B17/B16) | K17: Final self-financing portfolio V_T | L17: =G52
A18: =A17+1 | B18: =StockPricePaths!B18 | C18: =$L$3-A18*$L$9 | D18: =(LN(B18/$L$6)+($L$5+0.5*$L$4^2)*C18)/($L$4*SQRT(C18)) | E18: =NORMSDIST(D18) | F18: =E18*$L$7 | G18: =F17*B18+H17*EXP($L$5*$L$9) | H18: =G18-F18*B18 | I18: =LN(B18/B17) | K18: Total hedging P&L = V_T - payoff | L18: =L17-L16
A19: =A18+1 | B19: =StockPricePaths!B19 | C19: =$L$3-A19*$L$9 | D19: =(LN(B19/$L$6)+($L$5+0.5*$L$4^2)*C19)/($L$4*SQRT(C19)) | E19: =NORMSDIST(D19) | F19: =E19*$L$7 | G19: =F18*B19+H18*EXP($L$5*$L$9) | H19: =G19-F19*B19 | I19: =LN(B19/B18) | K19: ANSWER - P&L to nearest integer | L19: =ROUND(L18,0)
A20: =A19+1 | B20: =StockPricePaths!B20 | C20: =$L$3-A20*$L$9 | D20: =(LN(B20/$L$6)+($L$5+0.5*$L$4^2)*C20)/($L$4*SQRT(C20)) | E20: =NORMSDIST(D20) | F20: =E20*$L$7 | G20: =F19*B20+H19*EXP($L$5*$L$9) | H20: =G20-F20*B20 | I20: =LN(B20/B19)
A21: =A20+1 | B21: =StockPricePaths!B21 | C21: =$L$3-A21*$L$9 | D21: =(LN(B21/$L$6)+($L$5+0.5*$L$4^2)*C21)/($L$4*SQRT(C21)) | E21: =NORMSDIST(D21) | F21: =E21*$L$7 | G21: =F20*B21+H20*EXP($L$5*$L$9) | H21: =G21-F21*B21 | I21: =LN(B21/B20) | K21: Prices are linked to StockPricePaths!B. Every other column is a live formula:
A22: =A21+1 | B22: =StockPricePaths!B22 | C22: =$L$3-A22*$L$9 | D22: =(LN(B22/$L$6)+($L$5+0.5*$L$4^2)*C22)/($L$4*SQRT(C22)) | E22: =NORMSDIST(D22) | F22: =E22*$L$7 | G22: =F21*B22+H21*EXP($L$5*$L$9) | H22: =G22-F22*B22 | I22: =LN(B22/B21) | K22: A Period t = 0..50.
A23: =A22+1 | B23: =StockPricePaths!B23 | C23: =$L$3-A23*$L$9 | D23: =(LN(B23/$L$6)+($L$5+0.5*$L$4^2)*C23)/($L$4*SQRT(C23)) | E23: =NORMSDIST(D23) | F23: =E23*$L$7 | G23: =F22*B23+H22*EXP($L$5*$L$9) | H23: =G23-F23*B23 | I23: =LN(B23/B22) | K23: B Stock price, linked to the price path (this is the only input).
A24: =A23+1 | B24: =StockPricePaths!B24 | C24: =$L$3-A24*$L$9 | D24: =(LN(B24/$L$6)+($L$5+0.5*$L$4^2)*C24)/($L$4*SQRT(C24)) | E24: =NORMSDIST(D24) | F24: =E24*$L$7 | G24: =F23*B24+H23*EXP($L$5*$L$9) | H24: =G24-F24*B24 | I24: =LN(B24/B23) | K24: C Time to maturity tau = T - t*dt, dt = T/50 = 0.005 years.
A25: =A24+1 | B25: =StockPricePaths!B25 | C25: =$L$3-A25*$L$9 | D25: =(LN(B25/$L$6)+($L$5+0.5*$L$4^2)*C25)/($L$4*SQRT(C25)) | E25: =NORMSDIST(D25) | F25: =E25*$L$7 | G25: =F24*B25+H24*EXP($L$5*$L$9) | H25: =G25-F25*B25 | I25: =LN(B25/B24) | K25: D d1 = (LN(S/K) + (r + 0.5*sigma^2)*tau) / (sigma*SQRT(tau)), sigma = IMPLIED vol 30%.
A26: =A25+1 | B26: =StockPricePaths!B26 | C26: =$L$3-A26*$L$9 | D26: =(LN(B26/$L$6)+($L$5+0.5*$L$4^2)*C26)/($L$4*SQRT(C26)) | E26: =NORMSDIST(D26) | F26: =E26*$L$7 | G26: =F25*B26+H25*EXP($L$5*$L$9) | H26: =G26-F26*B26 | I26: =LN(B26/B25) | K26: E Delta = N(d1) = NORMSDIST(d1): shares to hold per option.
A27: =A26+1 | B27: =StockPricePaths!B27 | C27: =$L$3-A27*$L$9 | D27: =(LN(B27/$L$6)+($L$5+0.5*$L$4^2)*C27)/($L$4*SQRT(C27)) | E27: =NORMSDIST(D27) | F27: =E27*$L$7 | G27: =F26*B27+H26*EXP($L$5*$L$9) | H27: =G27-F27*B27 | I27: =LN(B27/B26) | K27: F # stocks held x_t = Delta * 100,000 options.
A28: =A27+1 | B28: =StockPricePaths!B28 | C28: =$L$3-A28*$L$9 | D28: =(LN(B28/$L$6)+($L$5+0.5*$L$4^2)*C28)/($L$4*SQRT(C28)) | E28: =NORMSDIST(D28) | F28: =E28*$L$7 | G28: =F27*B28+H27*EXP($L$5*$L$9) | H28: =G28-F28*B28 | I28: =LN(B28/B27) | K28: G Self-financing portfolio. Row 2 = Black-Scholes premium received;
A29: =A28+1 | B29: =StockPricePaths!B29 | C29: =$L$3-A29*$L$9 | D29: =(LN(B29/$L$6)+($L$5+0.5*$L$4^2)*C29)/($L$4*SQRT(C29)) | E29: =NORMSDIST(D29) | F29: =E29*$L$7 | G29: =F28*B29+H28*EXP($L$5*$L$9) | H29: =G29-F29*B29 | I29: =LN(B29/B28) | K29: afterwards V_t+1 = x_t*S_t+1 + c_t*EXP(r*dt) (no cash added or withdrawn).
A30: =A29+1 | B30: =StockPricePaths!B30 | C30: =$L$3-A30*$L$9 | D30: =(LN(B30/$L$6)+($L$5+0.5*$L$4^2)*C30)/($L$4*SQRT(C30)) | E30: =NORMSDIST(D30) | F30: =E30*$L$7 | G30: =F29*B30+H29*EXP($L$5*$L$9) | H30: =G30-F30*B30 | I30: =LN(B30/B29) | K30: H Cash account c_t = V_t - x_t*S_t (negative: we borrow to buy the hedge).
A31: =A30+1 | B31: =StockPricePaths!B31 | C31: =$L$3-A31*$L$9 | D31: =(LN(B31/$L$6)+($L$5+0.5*$L$4^2)*C31)/($L$4*SQRT(C31)) | E31: =NORMSDIST(D31) | F31: =E31*$L$7 | G31: =F30*B31+H30*EXP($L$5*$L$9) | H31: =G31-F31*B31 | I31: =LN(B31/B30) | K31: I Log-returns used for the realized-volatility answer.
A32: =A31+1 | B32: =StockPricePaths!B32 | C32: =$L$3-A32*$L$9 | D32: =(LN(B32/$L$6)+($L$5+0.5*$L$4^2)*C32)/($L$4*SQRT(C32)) | E32: =NORMSDIST(D32) | F32: =E32*$L$7 | G32: =F31*B32+H31*EXP($L$5*$L$9) | H32: =G32-F32*B32 | I32: =LN(B32/B31)
A33: =A32+1 | B33: =StockPricePaths!B33 | C33: =$L$3-A33*$L$9 | D33: =(LN(B33/$L$6)+($L$5+0.5*$L$4^2)*C33)/($L$4*SQRT(C33)) | E33: =NORMSDIST(D33) | F33: =E33*$L$7 | G33: =F32*B33+H32*EXP($L$5*$L$9) | H33: =G33-F33*B33 | I33: =LN(B33/B32)
A34: =A33+1 | B34: =StockPricePaths!B34 | C34: =$L$3-A34*$L$9 | D34: =(LN(B34/$L$6)+($L$5+0.5*$L$4^2)*C34)/($L$4*SQRT(C34)) | E34: =NORMSDIST(D34) | F34: =E34*$L$7 | G34: =F33*B34+H33*EXP($L$5*$L$9) | H34: =G34-F34*B34 | I34: =LN(B34/B33)
A35: =A34+1 | B35: =StockPricePaths!B35 | C35: =$L$3-A35*$L$9 | D35: =(LN(B35/$L$6)+($L$5+0.5*$L$4^2)*C35)/($L$4*SQRT(C35)) | E35: =NORMSDIST(D35) | F35: =E35*$L$7 | G35: =F34*B35+H34*EXP($L$5*$L$9) | H35: =G35-F35*B35 | I35: =LN(B35/B34)
A36: =A35+1 | B36: =StockPricePaths!B36 | C36: =$L$3-A36*$L$9 | D36: =(LN(B36/$L$6)+($L$5+0.5*$L$4^2)*C36)/($L$4*SQRT(C36)) | E36: =NORMSDIST(D36) | F36: =E36*$L$7 | G36: =F35*B36+H35*EXP($L$5*$L$9) | H36: =G36-F36*B36 | I36: =LN(B36/B35)
A37: =A36+1 | B37: =StockPricePaths!B37 | C37: =$L$3-A37*$L$9 | D37: =(LN(B37/$L$6)+($L$5+0.5*$L$4^2)*C37)/($L$4*SQRT(C37)) | E37: =NORMSDIST(D37) | F37: =E37*$L$7 | G37: =F36*B37+H36*EXP($L$5*$L$9) | H37: =G37-F37*B37 | I37: =LN(B37/B36)
A38: =A37+1 | B38: =StockPricePaths!B38 | C38: =$L$3-A38*$L$9 | D38: =(LN(B38/$L$6)+($L$5+0.5*$L$4^2)*C38)/($L$4*SQRT(C38)) | E38: =NORMSDIST(D38) | F38: =E38*$L$7 | G38: =F37*B38+H37*EXP($L$5*$L$9) | H38: =G38-F38*B38 | I38: =LN(B38/B37)
A39: =A38+1 | B39: =StockPricePaths!B39 | C39: =$L$3-A39*$L$9 | D39: =(LN(B39/$L$6)+($L$5+0.5*$L$4^2)*C39)/($L$4*SQRT(C39)) | E39: =NORMSDIST(D39) | F39: =E39*$L$7 | G39: =F38*B39+H38*EXP($L$5*$L$9) | H39: =G39-F39*B39 | I39: =LN(B39/B38)
A40: =A39+1 | B40: =StockPricePaths!B40 | C40: =$L$3-A40*$L$9 | D40: =(LN(B40/$L$6)+($L$5+0.5*$L$4^2)*C40)/($L$4*SQRT(C40)) | E40: =NORMSDIST(D40) | F40: =E40*$L$7 | G40: =F39*B40+H39*EXP($L$5*$L$9) | H40: =G40-F40*B40 | I40: =LN(B40/B39)
...

Sheet Path2_Hedge
A1: Period t | B1: Stock Price S_t | C1: Time to maturity (T-t) | D1: d1 | E1: Delta = N(d1) | F1: # Stocks held x_t | G1: S.F. Portfolio Value V_t | H1: Cash Account $ c_t | I1: Log-return ln(S_t/S_t-1) | K1: Parameter | L1: Value
A2: 0 | B2: =StockPricePaths!C2 | C2: =$L$3-A2*$L$9 | D2: =(LN(B2/$L$6)+($L$5+0.5*$L$4^2)*C2)/($L$4*SQRT(C2)) | E2: =NORMSDIST(D2) | F2: =E2*$L$7 | G2: =$L$7*(B2*NORMSDIST(D2)-$L$6*EXP(-$L$5*C2)*NORMSDIST(D2-$L$4*SQRT(C2))) | H2: =G2-F2*B2 | K2: Initial stock price S0 | L2: =DemoSheet!$B$2
A3: =A2+1 | B3: =StockPricePaths!C3 | C3: =$L$3-A3*$L$9 | D3: =(LN(B3/$L$6)+($L$5+0.5*$L$4^2)*C3)/($L$4*SQRT(C3)) | E3: =NORMSDIST(D3) | F3: =E3*$L$7 | G3: =F2*B3+H2*EXP($L$5*$L$9) | H3: =G3-F3*B3 | I3: =LN(B3/B2) | K3: Expiration T (years) | L3: =DemoSheet!$B$3
A4: =A3+1 | B4: =StockPricePaths!C4 | C4: =$L$3-A4*$L$9 | D4: =(LN(B4/$L$6)+($L$5+0.5*$L$4^2)*C4)/($L$4*SQRT(C4)) | E4: =NORMSDIST(D4) | F4: =E4*$L$7 | G4: =F3*B4+H3*EXP($L$5*$L$9) | H4: =G4-F4*B4 | I4: =LN(B4/B3) | K4: Implied volatility | L4: =DemoSheet!$B$4
A5: =A4+1 | B5: =StockPricePaths!C5 | C5: =$L$3-A5*$L$9 | D5: =(LN(B5/$L$6)+($L$5+0.5*$L$4^2)*C5)/($L$4*SQRT(C5)) | E5: =NORMSDIST(D5) | F5: =E5*$L$7 | G5: =F4*B5+H4*EXP($L$5*$L$9) | H5: =G5-F5*B5 | I5: =LN(B5/B4) | K5: Risk-free rate r | L5: =DemoSheet!$B$5
A6: =A5+1 | B6: =StockPricePaths!C6 | C6: =$L$3-A6*$L$9 | D6: =(LN(B6/$L$6)+($L$5+0.5*$L$4^2)*C6)/($L$4*SQRT(C6)) | E6: =NORMSDIST(D6) | F6: =E6*$L$7 | G6: =F5*B6+H5*EXP($L$5*$L$9) | H6: =G6-F6*B6 | I6: =LN(B6/B5) | K6: Strike K | L6: =DemoSheet!$B$6
A7: =A6+1 | B7: =StockPricePaths!C7 | C7: =$L$3-A7*$L$9 | D7: =(LN(B7/$L$6)+($L$5+0.5*$L$4^2)*C7)/($L$4*SQRT(C7)) | E7: =NORMSDIST(D7) | F7: =E7*$L$7 | G7: =F6*B7+H6*EXP($L$5*$L$9) | H7: =G7-F7*B7 | I7: =LN(B7/B6) | K7: # of options sold | L7: =DemoSheet!$B$7
A8: =A7+1 | B8: =StockPricePaths!C8 | C8: =$L$3-A8*$L$9 | D8: =(LN(B8/$L$6)+($L$5+0.5*$L$4^2)*C8)/($L$4*SQRT(C8)) | E8: =NORMSDIST(D8) | F8: =E8*$L$7 | G8: =F7*B8+H7*EXP($L$5*$L$9) | H8: =G8-F8*B8 | I8: =LN(B8/B7) | K8: # of hedging periods | L8: =DemoSheet!$B$8
A9: =A8+1 | B9: =StockPricePaths!C9 | C9: =$L$3-A9*$L$9 | D9: =(LN(B9/$L$6)+($L$5+0.5*$L$4^2)*C9)/($L$4*SQRT(C9)) | E9: =NORMSDIST(D9) | F9: =E9*$L$7 | G9: =F8*B9+H8*EXP($L$5*$L$9) | H9: =G9-F9*B9 | I9: =LN(B9/B8) | K9: dt = T / # periods | L9: =L3/L8
A10: =A9+1 | B10: =StockPricePaths!C10 | C10: =$L$3-A10*$L$9 | D10: =(LN(B10/$L$6)+($L$5+0.5*$L$4^2)*C10)/($L$4*SQRT(C10)) | E10: =NORMSDIST(D10) | F10: =E10*$L$7 | G10: =F9*B10+H9*EXP($L$5*$L$9) | H10: =G10-F10*B10 | I10: =LN(B10/B9)
A11: =A10+1 | B11: =StockPricePaths!C11 | C11: =$L$3-A11*$L$9 | D11: =(LN(B11/$L$6)+($L$5+0.5*$L$4^2)*C11)/($L$4*SQRT(C11)) | E11: =NORMSDIST(D11) | F11: =E11*$L$7 | G11: =F10*B11+H10*EXP($L$5*$L$9) | H11: =G11-F11*B11 | I11: =LN(B11/B10) | K11: RESULTS
A12: =A11+1 | B12: =StockPricePaths!C12 | C12: =$L$3-A12*$L$9 | D12: =(LN(B12/$L$6)+($L$5+0.5*$L$4^2)*C12)/($L$4*SQRT(C12)) | E12: =NORMSDIST(D12) | F12: =E12*$L$7 | G12: =F11*B12+H11*EXP($L$5*$L$9) | H12: =G12-F12*B12 | I12: =LN(B12/B11) | K12: Mean log-return (annualized) | L12: =AVERAGE(I3:I52)/$L$9
A13: =A12+1 | B13: =StockPricePaths!C13 | C13: =$L$3-A13*$L$9 | D13: =(LN(B13/$L$6)+($L$5+0.5*$L$4^2)*C13)/($L$4*SQRT(C13)) | E13: =NORMSDIST(D13) | F13: =E13*$L$7 | G13: =F12*B13+H12*EXP($L$5*$L$9) | H13: =G13-F13*B13 | I13: =LN(B13/B12) | K13: Realized volatility (annualized) | L13: =STDEV(I3:I52)/SQRT($L$9)
A14: =A13+1 | B14: =StockPricePaths!C14 | C14: =$L$3-A14*$L$9 | D14: =(LN(B14/$L$6)+($L$5+0.5*$L$4^2)*C14)/($L$4*SQRT(C14)) | E14: =NORMSDIST(D14) | F14: =E14*$L$7 | G14: =F13*B14+H13*EXP($L$5*$L$9) | H14: =G14-F14*B14 | I14: =LN(B14/B13) | K14: ANSWER - realized vol in %, 2 dp | L14: =ROUND(L13*100,2)
A15: =A14+1 | B15: =StockPricePaths!C15 | C15: =$L$3-A15*$L$9 | D15: =(LN(B15/$L$6)+($L$5+0.5*$L$4^2)*C15)/($L$4*SQRT(C15)) | E15: =NORMSDIST(D15) | F15: =E15*$L$7 | G15: =F14*B15+H14*EXP($L$5*$L$9) | H15: =G15-F15*B15 | I15: =LN(B15/B14) | K15: Terminal stock price S_T | L15: =B52
A16: =A15+1 | B16: =StockPricePaths!C16 | C16: =$L$3-A16*$L$9 | D16: =(LN(B16/$L$6)+($L$5+0.5*$L$4^2)*C16)/($L$4*SQRT(C16)) | E16: =NORMSDIST(D16) | F16: =E16*$L$7 | G16: =F15*B16+H15*EXP($L$5*$L$9) | H16: =G16-F16*B16 | I16: =LN(B16/B15) | K16: Option payoff = # options x MAX(S_T-K,0) | L16: =MAX(L15-$L$6,0)*$L$7
A17: =A16+1 | B17: =StockPricePaths!C17 | C17: =$L$3-A17*$L$9 | D17: =(LN(B17/$L$6)+($L$5+0.5*$L$4^2)*C17)/($L$4*SQRT(C17)) | E17: =NORMSDIST(D17) | F17: =E17*$L$7 | G17: =F16*B17+H16*EXP($L$5*$L$9) | H17: =G17-F17*B17 | I17: =LN(B17/B16) | K17: Final self-financing portfolio V_T | L17: =G52
A18: =A17+1 | B18: =StockPricePaths!C18 | C18: =$L$3-A18*$L$9 | D18: =(LN(B18/$L$6)+($L$5+0.5*$L$4^2)*C18)/($L$4*SQRT(C18)) | E18: =NORMSDIST(D18) | F18: =E18*$L$7 | G18: =F17*B18+H17*EXP($L$5*$L$9) | H18: =G18-F18*B18 | I18: =LN(B18/B17) | K18: Total hedging P&L = V_T - payoff | L18: =L17-L16
A19: =A18+1 | B19: =StockPricePaths!C19 | C19: =$L$3-A19*$L$9 | D19: =(LN(B19/$L$6)+($L$5+0.5*$L$4^2)*C19)/($L$4*SQRT(C19)) | E19: =NORMSDIST(D19) | F19: =E19*$L$7 | G19: =F18*B19+H18*EXP($L$5*$L$9) | H19: =G19-F19*B19 | I19: =LN(B19/B18) | K19: ANSWER - P&L to nearest integer | L19: =ROUND(L18,0)
A20: =A19+1 | B20: =StockPricePaths!C20 | C20: =$L$3-A20*$L$9 | D20: =(LN(B20/$L$6)+($L$5+0.5*$L$4^2)*C20)/($L$4*SQRT(C20)) | E20: =NORMSDIST(D20) | F20: =E20*$L$7 | G20: =F19*B20+H19*EXP($L$5*$L$9) | H20: =G20-F20*B20 | I20: =LN(B20/B19)
A21: =A20+1 | B21: =StockPricePaths!C21 | C21: =$L$3-A21*$L$9 | D21: =(LN(B21/$L$6)+($L$5+0.5*$L$4^2)*C21)/($L$4*SQRT(C21)) | E21: =NORMSDIST(D21) | F21: =E21*$L$7 | G21: =F20*B21+H20*EXP($L$5*$L$9) | H21: =G21-F21*B21 | I21: =LN(B21/B20) | K21: Prices are linked to StockPricePaths!C. Every other column is a live formula:
A22: =A21+1 | B22: =StockPricePaths!C22 | C22: =$L$3-A22*$L$9 | D22: =(LN(B22/$L$6)+($L$5+0.5*$L$4^2)*C22)/($L$4*SQRT(C22)) | E22: =NORMSDIST(D22) | F22: =E22*$L$7 | G22: =F21*B22+H21*EXP($L$5*$L$9) | H22: =G22-F22*B22 | I22: =LN(B22/B21) | K22: A Period t = 0..50.
A23: =A22+1 | B23: =StockPricePaths!C23 | C23: =$L$3-A23*$L$9 | D23: =(LN(B23/$L$6)+($L$5+0.5*$L$4^2)*C23)/($L$4*SQRT(C23)) | E23: =NORMSDIST(D23) | F23: =E23*$L$7 | G23: =F22*B23+H22*EXP($L$5*$L$9) | H23: =G23-F23*B23 | I23: =LN(B23/B22) | K23: B Stock price, linked to the price path (this is the only input).
A24: =A23+1 | B24: =StockPricePaths!C24 | C24: =$L$3-A24*$L$9 | D24: =(LN(B24/$L$6)+($L$5+0.5*$L$4^2)*C24)/($L$4*SQRT(C24)) | E24: =NORMSDIST(D24) | F24: =E24*$L$7 | G24: =F23*B24+H23*EXP($L$5*$L$9) | H24: =G24-F24*B24 | I24: =LN(B24/B23) | K24: C Time to maturity tau = T - t*dt, dt = T/50 = 0.005 years.
A25: =A24+1 | B25: =StockPricePaths!C25 | C25: =$L$3-A25*$L$9 | D25: =(LN(B25/$L$6)+($L$5+0.5*$L$4^2)*C25)/($L$4*SQRT(C25)) | E25: =NORMSDIST(D25) | F25: =E25*$L$7 | G25: =F24*B25+H24*EXP($L$5*$L$9) | H25: =G25-F25*B25 | I25: =LN(B25/B24) | K25: D d1 = (LN(S/K) + (r + 0.5*sigma^2)*tau) / (sigma*SQRT(tau)), sigma = IMPLIED vol 30%.
A26: =A25+1 | B26: =StockPricePaths!C26 | C26: =$L$3-A26*$L$9 | D26: =(LN(B26/$L$6)+($L$5+0.5*$L$4^2)*C26)/($L$4*SQRT(C26)) | E26: =NORMSDIST(D26) | F26: =E26*$L$7 | G26: =F25*B26+H25*EXP($L$5*$L$9) | H26: =G26-F26*B26 | I26: =LN(B26/B25) | K26: E Delta = N(d1) = NORMSDIST(d1): shares to hold per option.
A27: =A26+1 | B27: =StockPricePaths!C27 | C27: =$L$3-A27*$L$9 | D27: =(LN(B27/$L$6)+($L$5+0.5*$L$4^2)*C27)/($L$4*SQRT(C27)) | E27: =NORMSDIST(D27) | F27: =E27*$L$7 | G27: =F26*B27+H26*EXP($L$5*$L$9) | H27: =G27-F27*B27 | I27: =LN(B27/B26) | K27: F # stocks held x_t = Delta * 100,000 options.
A28: =A27+1 | B28: =StockPricePaths!C28 | C28: =$L$3-A28*$L$9 | D28: =(LN(B28/$L$6)+($L$5+0.5*$L$4^2)*C28)/($L$4*SQRT(C28)) | E28: =NORMSDIST(D28) | F28: =E28*$L$7 | G28: =F27*B28+H27*EXP($L$5*$L$9) | H28: =G28-F28*B28 | I28: =LN(B28/B27) | K28: G Self-financing portfolio. Row 2 = Black-Scholes premium received;
A29: =A28+1 | B29: =StockPricePaths!C29 | C29: =$L$3-A29*$L$9 | D29: =(LN(B29/$L$6)+($L$5+0.5*$L$4^2)*C29)/($L$4*SQRT(C29)) | E29: =NORMSDIST(D29) | F29: =E29*$L$7 | G29: =F28*B29+H28*EXP($L$5*$L$9) | H29: =G29-F29*B29 | I29: =LN(B29/B28) | K29: afterwards V_t+1 = x_t*S_t+1 + c_t*EXP(r*dt) (no cash added or withdrawn).
A30: =A29+1 | B30: =StockPricePaths!C30 | C30: =$L$3-A30*$L$9 | D30: =(LN(B30/$L$6)+($L$5+0.5*$L$4^2)*C30)/($L$4*SQRT(C30)) | E30: =NORMSDIST(D30) | F30: =E30*$L$7 | G30: =F29*B30+H29*EXP($L$5*$L$9) | H30: =G30-F30*B30 | I30: =LN(B30/B29) | K30: H Cash account c_t = V_t - x_t*S_t (negative: we borrow to buy the hedge).
A31: =A30+1 | B31: =StockPricePaths!C31 | C31: =$L$3-A31*$L$9 | D31: =(LN(B31/$L$6)+($L$5+0.5*$L$4^2)*C31)/($L$4*SQRT(C31)) | E31: =NORMSDIST(D31) | F31: =E31*$L$7 | G31: =F30*B31+H30*EXP($L$5*$L$9) | H31: =G31-F31*B31 | I31: =LN(B31/B30) | K31: I Log-returns used for the realized-volatility answer.
A32: =A31+1 | B32: =StockPricePaths!C32 | C32: =$L$3-A32*$L$9 | D32: =(LN(B32/$L$6)+($L$5+0.5*$L$4^2)*C32)/($L$4*SQRT(C32)) | E32: =NORMSDIST(D32) | F32: =E32*$L$7 | G32: =F31*B32+H31*EXP($L$5*$L$9) | H32: =G32-F32*B32 | I32: =LN(B32/B31)
A33: =A32+1 | B33: =StockPricePaths!C33 | C33: =$L$3-A33*$L$9 | D33: =(LN(B33/$L$6)+($L$5+0.5*$L$4^2)*C33)/($L$4*SQRT(C33)) | E33: =NORMSDIST(D33) | F33: =E33*$L$7 | G33: =F32*B33+H32*EXP($L$5*$L$9) | H33: =G33-F33*B33 | I33: =LN(B33/B32)
A34: =A33+1 | B34: =StockPricePaths!C34 | C34: =$L$3-A34*$L$9 | D34: =(LN(B34/$L$6)+($L$5+0.5*$L$4^2)*C34)/($L$4*SQRT(C34)) | E34: =NORMSDIST(D34) | F34: =E34*$L$7 | G34: =F33*B34+H33*EXP($L$5*$L$9) | H34: =G34-F34*B34 | I34: =LN(B34/B33)
A35: =A34+1 | B35: =StockPricePaths!C35 | C35: =$L$3-A35*$L$9 | D35: =(LN(B35/$L$6)+($L$5+0.5*$L$4^2)*C35)/($L$4*SQRT(C35)) | E35: =NORMSDIST(D35) | F35: =E35*$L$7 | G35: =F34*B35+H34*EXP($L$5*$L$9) | H35: =G35-F35*B35 | I35: =LN(B35/B34)
A36: =A35+1 | B36: =StockPricePaths!C36 | C36: =$L$3-A36*$L$9 | D36: =(LN(B36/$L$6)+($L$5+0.5*$L$4^2)*C36)/($L$4*SQRT(C36)) | E36: =NORMSDIST(D36) | F36: =E36*$L$7 | G36: =F35*B36+H35*EXP($L$5*$L$9) | H36: =G36-F36*B36 | I36: =LN(B36/B35)
A37: =A36+1 | B37: =StockPricePaths!C37 | C37: =$L$3-A37*$L$9 | D37: =(LN(B37/$L$6)+($L$5+0.5*$L$4^2)*C37)/($L$4*SQRT(C37)) | E37: =NORMSDIST(D37) | F37: =E37*$L$7 | G37: =F36*B37+H36*EXP($L$5*$L$9) | H37: =G37-F37*B37 | I37: =LN(B37/B36)
A38: =A37+1 | B38: =StockPricePaths!C38 | C38: =$L$3-A38*$L$9 | D38: =(LN(B38/$L$6)+($L$5+0.5*$L$4^2)*C38)/($L$4*SQRT(C38)) | E38: =NORMSDIST(D38) | F38: =E38*$L$7 | G38: =F37*B38+H37*EXP($L$5*$L$9) | H38: =G38-F38*B38 | I38: =LN(B38/B37)
A39: =A38+1 | B39: =StockPricePaths!C39 | C39: =$L$3-A39*$L$9 | D39: =(LN(B39/$L$6)+($L$5+0.5*$L$4^2)*C39)/($L$4*SQRT(C39)) | E39: =NORMSDIST(D39) | F39: =E39*$L$7 | G39: =F38*B39+H38*EXP($L$5*$L$9) | H39: =G39-F39*B39 | I39: =LN(B39/B38)
A40: =A39+1 | B40: =StockPricePaths!C40 | C40: =$L$3-A40*$L$9 | D40: =(LN(B40/$L$6)+($L$5+0.5*$L$4^2)*C40)/($L$4*SQRT(C40)) | E40: =NORMSDIST(D40) | F40: =E40*$L$7 | G40: =F39*B40+H39*EXP($L$5*$L$9) | H40: =G40-F40*B40 | I40: =LN(B40/B39)
...

Sheet Path3_Hedge
A1: Period t | B1: Stock Price S_t | C1: Time to maturity (T-t) | D1: d1 | E1: Delta = N(d1) | F1: # Stocks held x_t | G1: S.F. Portfolio Value V_t | H1: Cash Account $ c_t | I1: Log-return ln(S_t/S_t-1) | K1: Parameter | L1: Value
A2: 0 | B2: =StockPricePaths!D2 | C2: =$L$3-A2*$L$9 | D2: =(LN(B2/$L$6)+($L$5+0.5*$L$4^2)*C2)/($L$4*SQRT(C2)) | E2: =NORMSDIST(D2) | F2: =E2*$L$7 | G2: =$L$7*(B2*NORMSDIST(D2)-$L$6*EXP(-$L$5*C2)*NORMSDIST(D2-$L$4*SQRT(C2))) | H2: =G2-F2*B2 | K2: Initial stock price S0 | L2: =DemoSheet!$B$2
A3: =A2+1 | B3: =StockPricePaths!D3 | C3: =$L$3-A3*$L$9 | D3: =(LN(B3/$L$6)+($L$5+0.5*$L$4^2)*C3)/($L$4*SQRT(C3)) | E3: =NORMSDIST(D3) | F3: =E3*$L$7 | G3: =F2*B3+H2*EXP($L$5*$L$9) | H3: =G3-F3*B3 | I3: =LN(B3/B2) | K3: Expiration T (years) | L3: =DemoSheet!$B$3
A4: =A3+1 | B4: =StockPricePaths!D4 | C4: =$L$3-A4*$L$9 | D4: =(LN(B4/$L$6)+($L$5+0.5*$L$4^2)*C4)/($L$4*SQRT(C4)) | E4: =NORMSDIST(D4) | F4: =E4*$L$7 | G4: =F3*B4+H3*EXP($L$5*$L$9) | H4: =G4-F4*B4 | I4: =LN(B4/B3) | K4: Implied volatility | L4: =DemoSheet!$B$4
A5: =A4+1 | B5: =StockPricePaths!D5 | C5: =$L$3-A5*$L$9 | D5: =(LN(B5/$L$6)+($L$5+0.5*$L$4^2)*C5)/($L$4*SQRT(C5)) | E5: =NORMSDIST(D5) | F5: =E5*$L$7 | G5: =F4*B5+H4*EXP($L$5*$L$9) | H5: =G5-F5*B5 | I5: =LN(B5/B4) | K5: Risk-free rate r | L5: =DemoSheet!$B$5
A6: =A5+1 | B6: =StockPricePaths!D6 | C6: =$L$3-A6*$L$9 | D6: =(LN(B6/$L$6)+($L$5+0.5*$L$4^2)*C6)/($L$4*SQRT(C6)) | E6: =NORMSDIST(D6) | F6: =E6*$L$7 | G6: =F5*B6+H5*EXP($L$5*$L$9) | H6: =G6-F6*B6 | I6: =LN(B6/B5) | K6: Strike K | L6: =DemoSheet!$B$6
A7: =A6+1 | B7: =StockPricePaths!D7 | C7: =$L$3-A7*$L$9 | D7: =(LN(B7/$L$6)+($L$5+0.5*$L$4^2)*C7)/($L$4*SQRT(C7)) | E7: =NORMSDIST(D7) | F7: =E7*$L$7 | G7: =F6*B7+H6*EXP($L$5*$L$9) | H7: =G7-F7*B7 | I7: =LN(B7/B6) | K7: # of options sold | L7: =DemoSheet!$B$7
A8: =A7+1 | B8: =StockPricePaths!D8 | C8: =$L$3-A8*$L$9 | D8: =(LN(B8/$L$6)+($L$5+0.5*$L$4^2)*C8)/($L$4*SQRT(C8)) | E8: =NORMSDIST(D8) | F8: =E8*$L$7 | G8: =F7*B8+H7*EXP($L$5*$L$9) | H8: =G8-F8*B8 | I8: =LN(B8/B7) | K8: # of hedging periods | L8: =DemoSheet!$B$8
A9: =A8+1 | B9: =StockPricePaths!D9 | C9: =$L$3-A9*$L$9 | D9: =(LN(B9/$L$6)+($L$5+0.5*$L$4^2)*C9)/($L$4*SQRT(C9)) | E9: =NORMSDIST(D9) | F9: =E9*$L$7 | G9: =F8*B9+H8*EXP($L$5*$L$9) | H9: =G9-F9*B9 | I9: =LN(B9/B8) | K9: dt = T / # periods | L9: =L3/L8
A10: =A9+1 | B10: =StockPricePaths!D10 | C10: =$L$3-A10*$L$9 | D10: =(LN(B10/$L$6)+($L$5+0.5*$L$4^2)*C10)/($L$4*SQRT(C10)) | E10: =NORMSDIST(D10) | F10: =E10*$L$7 | G10: =F9*B10+H9*EXP($L$5*$L$9) | H10: =G10-F10*B10 | I10: =LN(B10/B9)
A11: =A10+1 | B11: =StockPricePaths!D11 | C11: =$L$3-A11*$L$9 | D11: =(LN(B11/$L$6)+($L$5+0.5*$L$4^2)*C11)/($L$4*SQRT(C11)) | E11: =NORMSDIST(D11) | F11: =E11*$L$7 | G11: =F10*B11+H10*EXP($L$5*$L$9) | H11: =G11-F11*B11 | I11: =LN(B11/B10) | K11: RESULTS
A12: =A11+1 | B12: =StockPricePaths!D12 | C12: =$L$3-A12*$L$9 | D12: =(LN(B12/$L$6)+($L$5+0.5*$L$4^2)*C12)/($L$4*SQRT(C12)) | E12: =NORMSDIST(D12) | F12: =E12*$L$7 | G12: =F11*B12+H11*EXP($L$5*$L$9) | H12: =G12-F12*B12 | I12: =LN(B12/B11) | K12: Mean log-return (annualized) | L12: =AVERAGE(I3:I52)/$L$9
A13: =A12+1 | B13: =StockPricePaths!D13 | C13: =$L$3-A13*$L$9 | D13: =(LN(B13/$L$6)+($L$5+0.5*$L$4^2)*C13)/($L$4*SQRT(C13)) | E13: =NORMSDIST(D13) | F13: =E13*$L$7 | G13: =F12*B13+H12*EXP($L$5*$L$9) | H13: =G13-F13*B13 | I13: =LN(B13/B12) | K13: Realized volatility (annualized) | L13: =STDEV(I3:I52)/SQRT($L$9)
A14: =A13+1 | B14: =StockPricePaths!D14 | C14: =$L$3-A14*$L$9 | D14: =(LN(B14/$L$6)+($L$5+0.5*$L$4^2)*C14)/($L$4*SQRT(C14)) | E14: =NORMSDIST(D14) | F14: =E14*$L$7 | G14: =F13*B14+H13*EXP($L$5*$L$9) | H14: =G14-F14*B14 | I14: =LN(B14/B13) | K14: ANSWER - realized vol in %, 2 dp | L14: =ROUND(L13*100,2)
A15: =A14+1 | B15: =StockPricePaths!D15 | C15: =$L$3-A15*$L$9 | D15: =(LN(B15/$L$6)+($L$5+0.5*$L$4^2)*C15)/($L$4*SQRT(C15)) | E15: =NORMSDIST(D15) | F15: =E15*$L$7 | G15: =F14*B15+H14*EXP($L$5*$L$9) | H15: =G15-F15*B15 | I15: =LN(B15/B14) | K15: Terminal stock price S_T | L15: =B52
A16: =A15+1 | B16: =StockPricePaths!D16 | C16: =$L$3-A16*$L$9 | D16: =(LN(B16/$L$6)+($L$5+0.5*$L$4^2)*C16)/($L$4*SQRT(C16)) | E16: =NORMSDIST(D16) | F16: =E16*$L$7 | G16: =F15*B16+H15*EXP($L$5*$L$9) | H16: =G16-F16*B16 | I16: =LN(B16/B15) | K16: Option payoff = # options x MAX(S_T-K,0) | L16: =MAX(L15-$L$6,0)*$L$7
A17: =A16+1 | B17: =StockPricePaths!D17 | C17: =$L$3-A17*$L$9 | D17: =(LN(B17/$L$6)+($L$5+0.5*$L$4^2)*C17)/($L$4*SQRT(C17)) | E17: =NORMSDIST(D17) | F17: =E17*$L$7 | G17: =F16*B17+H16*EXP($L$5*$L$9) | H17: =G17-F17*B17 | I17: =LN(B17/B16) | K17: Final self-financing portfolio V_T | L17: =G52
A18: =A17+1 | B18: =StockPricePaths!D18 | C18: =$L$3-A18*$L$9 | D18: =(LN(B18/$L$6)+($L$5+0.5*$L$4^2)*C18)/($L$4*SQRT(C18)) | E18: =NORMSDIST(D18) | F18: =E18*$L$7 | G18: =F17*B18+H17*EXP($L$5*$L$9) | H18: =G18-F18*B18 | I18: =LN(B18/B17) | K18: Total hedging P&L = V_T - payoff | L18: =L17-L16
A19: =A18+1 | B19: =StockPricePaths!D19 | C19: =$L$3-A19*$L$9 | D19: =(LN(B19/$L$6)+($L$5+0.5*$L$4^2)*C19)/($L$4*SQRT(C19)) | E19: =NORMSDIST(D19) | F19: =E19*$L$7 | G19: =F18*B19+H18*EXP($L$5*$L$9) | H19: =G19-F19*B19 | I19: =LN(B19/B18) | K19: ANSWER - P&L to nearest integer | L19: =ROUND(L18,0)
A20: =A19+1 | B20: =StockPricePaths!D20 | C20: =$L$3-A20*$L$9 | D20: =(LN(B20/$L$6)+($L$5+0.5*$L$4^2)*C20)/($L$4*SQRT(C20)) | E20: =NORMSDIST(D20) | F20: =E20*$L$7 | G20: =F19*B20+H19*EXP($L$5*$L$9) | H20: =G20-F20*B20 | I20: =LN(B20/B19)
A21: =A20+1 | B21: =StockPricePaths!D21 | C21: =$L$3-A21*$L$9 | D21: =(LN(B21/$L$6)+($L$5+0.5*$L$4^2)*C21)/($L$4*SQRT(C21)) | E21: =NORMSDIST(D21) | F21: =E21*$L$7 | G21: =F20*B21+H20*EXP($L$5*$L$9) | H21: =G21-F21*B21 | I21: =LN(B21/B20) | K21: Prices are linked to StockPricePaths!D. Every other column is a live formula:
A22: =A21+1 | B22: =StockPricePaths!D22 | C22: =$L$3-A22*$L$9 | D22: =(LN(B22/$L$6)+($L$5+0.5*$L$4^2)*C22)/($L$4*SQRT(C22)) | E22: =NORMSDIST(D22) | F22: =E22*$L$7 | G22: =F21*B22+H21*EXP($L$5*$L$9) | H22: =G22-F22*B22 | I22: =LN(B22/B21) | K22: A Period t = 0..50.
A23: =A22+1 | B23: =StockPricePaths!D23 | C23: =$L$3-A23*$L$9 | D23: =(LN(B23/$L$6)+($L$5+0.5*$L$4^2)*C23)/($L$4*SQRT(C23)) | E23: =NORMSDIST(D23) | F23: =E23*$L$7 | G23: =F22*B23+H22*EXP($L$5*$L$9) | H23: =G23-F23*B23 | I23: =LN(B23/B22) | K23: B Stock price, linked to the price path (this is the only input).
A24: =A23+1 | B24: =StockPricePaths!D24 | C24: =$L$3-A24*$L$9 | D24: =(LN(B24/$L$6)+($L$5+0.5*$L$4^2)*C24)/($L$4*SQRT(C24)) | E24: =NORMSDIST(D24) | F24: =E24*$L$7 | G24: =F23*B24+H23*EXP($L$5*$L$9) | H24: =G24-F24*B24 | I24: =LN(B24/B23) | K24: C Time to maturity tau = T - t*dt, dt = T/50 = 0.005 years.
A25: =A24+1 | B25: =StockPricePaths!D25 | C25: =$L$3-A25*$L$9 | D25: =(LN(B25/$L$6)+($L$5+0.5*$L$4^2)*C25)/($L$4*SQRT(C25)) | E25: =NORMSDIST(D25) | F25: =E25*$L$7 | G25: =F24*B25+H24*EXP($L$5*$L$9) | H25: =G25-F25*B25 | I25: =LN(B25/B24) | K25: D d1 = (LN(S/K) + (r + 0.5*sigma^2)*tau) / (sigma*SQRT(tau)), sigma = IMPLIED vol 30%.
A26: =A25+1 | B26: =StockPricePaths!D26 | C26: =$L$3-A26*$L$9 | D26: =(LN(B26/$L$6)+($L$5+0.5*$L$4^2)*C26)/($L$4*SQRT(C26)) | E26: =NORMSDIST(D26) | F26: =E26*$L$7 | G26: =F25*B26+H25*EXP($L$5*$L$9) | H26: =G26-F26*B26 | I26: =LN(B26/B25) | K26: E Delta = N(d1) = NORMSDIST(d1): shares to hold per option.
A27: =A26+1 | B27: =StockPricePaths!D27 | C27: =$L$3-A27*$L$9 | D27: =(LN(B27/$L$6)+($L$5+0.5*$L$4^2)*C27)/($L$4*SQRT(C27)) | E27: =NORMSDIST(D27) | F27: =E27*$L$7 | G27: =F26*B27+H26*EXP($L$5*$L$9) | H27: =G27-F27*B27 | I27: =LN(B27/B26) | K27: F # stocks held x_t = Delta * 100,000 options.
A28: =A27+1 | B28: =StockPricePaths!D28 | C28: =$L$3-A28*$L$9 | D28: =(LN(B28/$L$6)+($L$5+0.5*$L$4^2)*C28)/($L$4*SQRT(C28)) | E28: =NORMSDIST(D28) | F28: =E28*$L$7 | G28: =F27*B28+H27*EXP($L$5*$L$9) | H28: =G28-F28*B28 | I28: =LN(B28/B27) | K28: G Self-financing portfolio. Row 2 = Black-Scholes premium received;
A29: =A28+1 | B29: =StockPricePaths!D29 | C29: =$L$3-A29*$L$9 | D29: =(LN(B29/$L$6)+($L$5+0.5*$L$4^2)*C29)/($L$4*SQRT(C29)) | E29: =NORMSDIST(D29) | F29: =E29*$L$7 | G29: =F28*B29+H28*EXP($L$5*$L$9) | H29: =G29-F29*B29 | I29: =LN(B29/B28) | K29: afterwards V_t+1 = x_t*S_t+1 + c_t*EXP(r*dt) (no cash added or withdrawn).
A30: =A29+1 | B30: =StockPricePaths!D30 | C30: =$L$3-A30*$L$9 | D30: =(LN(B30/$L$6)+($L$5+0.5*$L$4^2)*C30)/($L$4*SQRT(C30)) | E30: =NORMSDIST(D30) | F30: =E30*$L$7 | G30: =F29*B30+H29*EXP($L$5*$L$9) | H30: =G30-F30*B30 | I30: =LN(B30/B29) | K30: H Cash account c_t = V_t - x_t*S_t (negative: we borrow to buy the hedge).
A31: =A30+1 | B31: =StockPricePaths!D31 | C31: =$L$3-A31*$L$9 | D31: =(LN(B31/$L$6)+($L$5+0.5*$L$4^2)*C31)/($L$4*SQRT(C31)) | E31: =NORMSDIST(D31) | F31: =E31*$L$7 | G31: =F30*B31+H30*EXP($L$5*$L$9) | H31: =G31-F31*B31 | I31: =LN(B31/B30) | K31: I Log-returns used for the realized-volatility answer.
A32: =A31+1 | B32: =StockPricePaths!D32 | C32: =$L$3-A32*$L$9 | D32: =(LN(B32/$L$6)+($L$5+0.5*$L$4^2)*C32)/($L$4*SQRT(C32)) | E32: =NORMSDIST(D32) | F32: =E32*$L$7 | G32: =F31*B32+H31*EXP($L$5*$L$9) | H32: =G32-F32*B32 | I32: =LN(B32/B31)
A33: =A32+1 | B33: =StockPricePaths!D33 | C33: =$L$3-A33*$L$9 | D33: =(LN(B33/$L$6)+($L$5+0.5*$L$4^2)*C33)/($L$4*SQRT(C33)) | E33: =NORMSDIST(D33) | F33: =E33*$L$7 | G33: =F32*B33+H32*EXP($L$5*$L$9) | H33: =G33-F33*B33 | I33: =LN(B33/B32)
A34: =A33+1 | B34: =StockPricePaths!D34 | C34: =$L$3-A34*$L$9 | D34: =(LN(B34/$L$6)+($L$5+0.5*$L$4^2)*C34)/($L$4*SQRT(C34)) | E34: =NORMSDIST(D34) | F34: =E34*$L$7 | G34: =F33*B34+H33*EXP($L$5*$L$9) | H34: =G34-F34*B34 | I34: =LN(B34/B33)
A35: =A34+1 | B35: =StockPricePaths!D35 | C35: =$L$3-A35*$L$9 | D35: =(LN(B35/$L$6)+($L$5+0.5*$L$4^2)*C35)/($L$4*SQRT(C35)) | E35: =NORMSDIST(D35) | F35: =E35*$L$7 | G35: =F34*B35+H34*EXP($L$5*$L$9) | H35: =G35-F35*B35 | I35: =LN(B35/B34)
A36: =A35+1 | B36: =StockPricePaths!D36 | C36: =$L$3-A36*$L$9 | D36: =(LN(B36/$L$6)+($L$5+0.5*$L$4^2)*C36)/($L$4*SQRT(C36)) | E36: =NORMSDIST(D36) | F36: =E36*$L$7 | G36: =F35*B36+H35*EXP($L$5*$L$9) | H36: =G36-F36*B36 | I36: =LN(B36/B35)
A37: =A36+1 | B37: =StockPricePaths!D37 | C37: =$L$3-A37*$L$9 | D37: =(LN(B37/$L$6)+($L$5+0.5*$L$4^2)*C37)/($L$4*SQRT(C37)) | E37: =NORMSDIST(D37) | F37: =E37*$L$7 | G37: =F36*B37+H36*EXP($L$5*$L$9) | H37: =G37-F37*B37 | I37: =LN(B37/B36)
A38: =A37+1 | B38: =StockPricePaths!D38 | C38: =$L$3-A38*$L$9 | D38: =(LN(B38/$L$6)+($L$5+0.5*$L$4^2)*C38)/($L$4*SQRT(C38)) | E38: =NORMSDIST(D38) | F38: =E38*$L$7 | G38: =F37*B38+H37*EXP($L$5*$L$9) | H38: =G38-F38*B38 | I38: =LN(B38/B37)
A39: =A38+1 | B39: =StockPricePaths!D39 | C39: =$L$3-A39*$L$9 | D39: =(LN(B39/$L$6)+($L$5+0.5*$L$4^2)*C39)/($L$4*SQRT(C39)) | E39: =NORMSDIST(D39) | F39: =E39*$L$7 | G39: =F38*B39+H38*EXP($L$5*$L$9) | H39: =G39-F39*B39 | I39: =LN(B39/B38)
A40: =A39+1 | B40: =StockPricePaths!D40 | C40: =$L$3-A40*$L$9 | D40: =(LN(B40/$L$6)+($L$5+0.5*$L$4^2)*C40)/($L$4*SQRT(C40)) | E40: =NORMSDIST(D40) | F40: =E40*$L$7 | G40: =F39*B40+H39*EXP($L$5*$L$9) | H40: =G40-F40*B40 | I40: =LN(B40/B39)
...

Sheet Path4_Hedge
A1: Period t | B1: Stock Price S_t | C1: Time to maturity (T-t) | D1: d1 | E1: Delta = N(d1) | F1: # Stocks held x_t | G1: S.F. Portfolio Value V_t | H1: Cash Account $ c_t | I1: Log-return ln(S_t/S_t-1) | K1: Parameter | L1: Value
A2: 0 | B2: =StockPricePaths!E2 | C2: =$L$3-A2*$L$9 | D2: =(LN(B2/$L$6)+($L$5+0.5*$L$4^2)*C2)/($L$4*SQRT(C2)) | E2: =NORMSDIST(D2) | F2: =E2*$L$7 | G2: =$L$7*(B2*NORMSDIST(D2)-$L$6*EXP(-$L$5*C2)*NORMSDIST(D2-$L$4*SQRT(C2))) | H2: =G2-F2*B2 | K2: Initial stock price S0 | L2: =DemoSheet!$B$2
A3: =A2+1 | B3: =StockPricePaths!E3 | C3: =$L$3-A3*$L$9 | D3: =(LN(B3/$L$6)+($L$5+0.5*$L$4^2)*C3)/($L$4*SQRT(C3)) | E3: =NORMSDIST(D3) | F3: =E3*$L$7 | G3: =F2*B3+H2*EXP($L$5*$L$9) | H3: =G3-F3*B3 | I3: =LN(B3/B2) | K3: Expiration T (years) | L3: =DemoSheet!$B$3
A4: =A3+1 | B4: =StockPricePaths!E4 | C4: =$L$3-A4*$L$9 | D4: =(LN(B4/$L$6)+($L$5+0.5*$L$4^2)*C4)/($L$4*SQRT(C4)) | E4: =NORMSDIST(D4) | F4: =E4*$L$7 | G4: =F3*B4+H3*EXP($L$5*$L$9) | H4: =G4-F4*B4 | I4: =LN(B4/B3) | K4: Implied volatility | L4: =DemoSheet!$B$4
A5: =A4+1 | B5: =StockPricePaths!E5 | C5: =$L$3-A5*$L$9 | D5: =(LN(B5/$L$6)+($L$5+0.5*$L$4^2)*C5)/($L$4*SQRT(C5)) | E5: =NORMSDIST(D5) | F5: =E5*$L$7 | G5: =F4*B5+H4*EXP($L$5*$L$9) | H5: =G5-F5*B5 | I5: =LN(B5/B4) | K5: Risk-free rate r | L5: =DemoSheet!$B$5
A6: =A5+1 | B6: =StockPricePaths!E6 | C6: =$L$3-A6*$L$9 | D6: =(LN(B6/$L$6)+($L$5+0.5*$L$4^2)*C6)/($L$4*SQRT(C6)) | E6: =NORMSDIST(D6) | F6: =E6*$L$7 | G6: =F5*B6+H5*EXP($L$5*$L$9) | H6: =G6-F6*B6 | I6: =LN(B6/B5) | K6: Strike K | L6: =DemoSheet!$B$6
A7: =A6+1 | B7: =StockPricePaths!E7 | C7: =$L$3-A7*$L$9 | D7: =(LN(B7/$L$6)+($L$5+0.5*$L$4^2)*C7)/($L$4*SQRT(C7)) | E7: =NORMSDIST(D7) | F7: =E7*$L$7 | G7: =F6*B7+H6*EXP($L$5*$L$9) | H7: =G7-F7*B7 | I7: =LN(B7/B6) | K7: # of options sold | L7: =DemoSheet!$B$7
A8: =A7+1 | B8: =StockPricePaths!E8 | C8: =$L$3-A8*$L$9 | D8: =(LN(B8/$L$6)+($L$5+0.5*$L$4^2)*C8)/($L$4*SQRT(C8)) | E8: =NORMSDIST(D8) | F8: =E8*$L$7 | G8: =F7*B8+H7*EXP($L$5*$L$9) | H8: =G8-F8*B8 | I8: =LN(B8/B7) | K8: # of hedging periods | L8: =DemoSheet!$B$8
A9: =A8+1 | B9: =StockPricePaths!E9 | C9: =$L$3-A9*$L$9 | D9: =(LN(B9/$L$6)+($L$5+0.5*$L$4^2)*C9)/($L$4*SQRT(C9)) | E9: =NORMSDIST(D9) | F9: =E9*$L$7 | G9: =F8*B9+H8*EXP($L$5*$L$9) | H9: =G9-F9*B9 | I9: =LN(B9/B8) | K9: dt = T / # periods | L9: =L3/L8
A10: =A9+1 | B10: =StockPricePaths!E10 | C10: =$L$3-A10*$L$9 | D10: =(LN(B10/$L$6)+($L$5+0.5*$L$4^2)*C10)/($L$4*SQRT(C10)) | E10: =NORMSDIST(D10) | F10: =E10*$L$7 | G10: =F9*B10+H9*EXP($L$5*$L$9) | H10: =G10-F10*B10 | I10: =LN(B10/B9)
A11: =A10+1 | B11: =StockPricePaths!E11 | C11: =$L$3-A11*$L$9 | D11: =(LN(B11/$L$6)+($L$5+0.5*$L$4^2)*C11)/($L$4*SQRT(C11)) | E11: =NORMSDIST(D11) | F11: =E11*$L$7 | G11: =F10*B11+H10*EXP($L$5*$L$9) | H11: =G11-F11*B11 | I11: =LN(B11/B10) | K11: RESULTS
A12: =A11+1 | B12: =StockPricePaths!E12 | C12: =$L$3-A12*$L$9 | D12: =(LN(B12/$L$6)+($L$5+0.5*$L$4^2)*C12)/($L$4*SQRT(C12)) | E12: =NORMSDIST(D12) | F12: =E12*$L$7 | G12: =F11*B12+H11*EXP($L$5*$L$9) | H12: =G12-F12*B12 | I12: =LN(B12/B11) | K12: Mean log-return (annualized) | L12: =AVERAGE(I3:I52)/$L$9
A13: =A12+1 | B13: =StockPricePaths!E13 | C13: =$L$3-A13*$L$9 | D13: =(LN(B13/$L$6)+($L$5+0.5*$L$4^2)*C13)/($L$4*SQRT(C13)) | E13: =NORMSDIST(D13) | F13: =E13*$L$7 | G13: =F12*B13+H12*EXP($L$5*$L$9) | H13: =G13-F13*B13 | I13: =LN(B13/B12) | K13: Realized volatility (annualized) | L13: =STDEV(I3:I52)/SQRT($L$9)
A14: =A13+1 | B14: =StockPricePaths!E14 | C14: =$L$3-A14*$L$9 | D14: =(LN(B14/$L$6)+($L$5+0.5*$L$4^2)*C14)/($L$4*SQRT(C14)) | E14: =NORMSDIST(D14) | F14: =E14*$L$7 | G14: =F13*B14+H13*EXP($L$5*$L$9) | H14: =G14-F14*B14 | I14: =LN(B14/B13) | K14: ANSWER - realized vol in %, 2 dp | L14: =ROUND(L13*100,2)
A15: =A14+1 | B15: =StockPricePaths!E15 | C15: =$L$3-A15*$L$9 | D15: =(LN(B15/$L$6)+($L$5+0.5*$L$4^2)*C15)/($L$4*SQRT(C15)) | E15: =NORMSDIST(D15) | F15: =E15*$L$7 | G15: =F14*B15+H14*EXP($L$5*$L$9) | H15: =G15-F15*B15 | I15: =LN(B15/B14) | K15: Terminal stock price S_T | L15: =B52
A16: =A15+1 | B16: =StockPricePaths!E16 | C16: =$L$3-A16*$L$9 | D16: =(LN(B16/$L$6)+($L$5+0.5*$L$4^2)*C16)/($L$4*SQRT(C16)) | E16: =NORMSDIST(D16) | F16: =E16*$L$7 | G16: =F15*B16+H15*EXP($L$5*$L$9) | H16: =G16-F16*B16 | I16: =LN(B16/B15) | K16: Option payoff = # options x MAX(S_T-K,0) | L16: =MAX(L15-$L$6,0)*$L$7
A17: =A16+1 | B17: =StockPricePaths!E17 | C17: =$L$3-A17*$L$9 | D17: =(LN(B17/$L$6)+($L$5+0.5*$L$4^2)*C17)/($L$4*SQRT(C17)) | E17: =NORMSDIST(D17) | F17: =E17*$L$7 | G17: =F16*B17+H16*EXP($L$5*$L$9) | H17: =G17-F17*B17 | I17: =LN(B17/B16) | K17: Final self-financing portfolio V_T | L17: =G52
A18: =A17+1 | B18: =StockPricePaths!E18 | C18: =$L$3-A18*$L$9 | D18: =(LN(B18/$L$6)+($L$5+0.5*$L$4^2)*C18)/($L$4*SQRT(C18)) | E18: =NORMSDIST(D18) | F18: =E18*$L$7 | G18: =F17*B18+H17*EXP($L$5*$L$9) | H18: =G18-F18*B18 | I18: =LN(B18/B17) | K18: Total hedging P&L = V_T - payoff | L18: =L17-L16
A19: =A18+1 | B19: =StockPricePaths!E19 | C19: =$L$3-A19*$L$9 | D19: =(LN(B19/$L$6)+($L$5+0.5*$L$4^2)*C19)/($L$4*SQRT(C19)) | E19: =NORMSDIST(D19) | F19: =E19*$L$7 | G19: =F18*B19+H18*EXP($L$5*$L$9) | H19: =G19-F19*B19 | I19: =LN(B19/B18) | K19: ANSWER - P&L to nearest integer | L19: =ROUND(L18,0)
A20: =A19+1 | B20: =StockPricePaths!E20 | C20: =$L$3-A20*$L$9 | D20: =(LN(B20/$L$6)+($L$5+0.5*$L$4^2)*C20)/($L$4*SQRT(C20)) | E20: =NORMSDIST(D20) | F20: =E20*$L$7 | G20: =F19*B20+H19*EXP($L$5*$L$9) | H20: =G20-F20*B20 | I20: =LN(B20/B19)
A21: =A20+1 | B21: =StockPricePaths!E21 | C21: =$L$3-A21*$L$9 | D21: =(LN(B21/$L$6)+($L$5+0.5*$L$4^2)*C21)/($L$4*SQRT(C21)) | E21: =NORMSDIST(D21) | F21: =E21*$L$7 | G21: =F20*B21+H20*EXP($L$5*$L$9) | H21: =G21-F21*B21 | I21: =LN(B21/B20) | K21: Prices are linked to StockPricePaths!E. Every other column is a live formula:
A22: =A21+1 | B22: =StockPricePaths!E22 | C22: =$L$3-A22*$L$9 | D22: =(LN(B22/$L$6)+($L$5+0.5*$L$4^2)*C22)/($L$4*SQRT(C22)) | E22: =NORMSDIST(D22) | F22: =E22*$L$7 | G22: =F21*B22+H21*EXP($L$5*$L$9) | H22: =G22-F22*B22 | I22: =LN(B22/B21) | K22: A Period t = 0..50.
A23: =A22+1 | B23: =StockPricePaths!E23 | C23: =$L$3-A23*$L$9 | D23: =(LN(B23/$L$6)+($L$5+0.5*$L$4^2)*C23)/($L$4*SQRT(C23)) | E23: =NORMSDIST(D23) | F23: =E23*$L$7 | G23: =F22*B23+H22*EXP($L$5*$L$9) | H23: =G23-F23*B23 | I23: =LN(B23/B22) | K23: B Stock price, linked to the price path (this is the only input).
A24: =A23+1 | B24: =StockPricePaths!E24 | C24: =$L$3-A24*$L$9 | D24: =(LN(B24/$L$6)+($L$5+0.5*$L$4^2)*C24)/($L$4*SQRT(C24)) | E24: =NORMSDIST(D24) | F24: =E24*$L$7 | G24: =F23*B24+H23*EXP($L$5*$L$9) | H24: =G24-F24*B24 | I24: =LN(B24/B23) | K24: C Time to maturity tau = T - t*dt, dt = T/50 = 0.005 years.
A25: =A24+1 | B25: =StockPricePaths!E25 | C25: =$L$3-A25*$L$9 | D25: =(LN(B25/$L$6)+($L$5+0.5*$L$4^2)*C25)/($L$4*SQRT(C25)) | E25: =NORMSDIST(D25) | F25: =E25*$L$7 | G25: =F24*B25+H24*EXP($L$5*$L$9) | H25: =G25-F25*B25 | I25: =LN(B25/B24) | K25: D d1 = (LN(S/K) + (r + 0.5*sigma^2)*tau) / (sigma*SQRT(tau)), sigma = IMPLIED vol 30%.
A26: =A25+1 | B26: =StockPricePaths!E26 | C26: =$L$3-A26*$L$9 | D26: =(LN(B26/$L$6)+($L$5+0.5*$L$4^2)*C26)/($L$4*SQRT(C26)) | E26: =NORMSDIST(D26) | F26: =E26*$L$7 | G26: =F25*B26+H25*EXP($L$5*$L$9) | H26: =G26-F26*B26 | I26: =LN(B26/B25) | K26: E Delta = N(d1) = NORMSDIST(d1): shares to hold per option.
A27: =A26+1 | B27: =StockPricePaths!E27 | C27: =$L$3-A27*$L$9 | D27: =(LN(B27/$L$6)+($L$5+0.5*$L$4^2)*C27)/($L$4*SQRT(C27)) | E27: =NORMSDIST(D27) | F27: =E27*$L$7 | G27: =F26*B27+H26*EXP($L$5*$L$9) | H27: =G27-F27*B27 | I27: =LN(B27/B26) | K27: F # stocks held x_t = Delta * 100,000 options.
A28: =A27+1 | B28: =StockPricePaths!E28 | C28: =$L$3-A28*$L$9 | D28: =(LN(B28/$L$6)+($L$5+0.5*$L$4^2)*C28)/($L$4*SQRT(C28)) | E28: =NORMSDIST(D28) | F28: =E28*$L$7 | G28: =F27*B28+H27*EXP($L$5*$L$9) | H28: =G28-F28*B28 | I28: =LN(B28/B27) | K28: G Self-financing portfolio. Row 2 = Black-Scholes premium received;
A29: =A28+1 | B29: =StockPricePaths!E29 | C29: =$L$3-A29*$L$9 | D29: =(LN(B29/$L$6)+($L$5+0.5*$L$4^2)*C29)/($L$4*SQRT(C29)) | E29: =NORMSDIST(D29) | F29: =E29*$L$7 | G29: =F28*B29+H28*EXP($L$5*$L$9) | H29: =G29-F29*B29 | I29: =LN(B29/B28) | K29: afterwards V_t+1 = x_t*S_t+1 + c_t*EXP(r*dt) (no cash added or withdrawn).
A30: =A29+1 | B30: =StockPricePaths!E30 | C30: =$L$3-A30*$L$9 | D30: =(LN(B30/$L$6)+($L$5+0.5*$L$4^2)*C30)/($L$4*SQRT(C30)) | E30: =NORMSDIST(D30) | F30: =E30*$L$7 | G30: =F29*B30+H29*EXP($L$5*$L$9) | H30: =G30-F30*B30 | I30: =LN(B30/B29) | K30: H Cash account c_t = V_t - x_t*S_t (negative: we borrow to buy the hedge).
A31: =A30+1 | B31: =StockPricePaths!E31 | C31: =$L$3-A31*$L$9 | D31: =(LN(B31/$L$6)+($L$5+0.5*$L$4^2)*C31)/($L$4*SQRT(C31)) | E31: =NORMSDIST(D31) | F31: =E31*$L$7 | G31: =F30*B31+H30*EXP($L$5*$L$9) | H31: =G31-F31*B31 | I31: =LN(B31/B30) | K31: I Log-returns used for the realized-volatility answer.
A32: =A31+1 | B32: =StockPricePaths!E32 | C32: =$L$3-A32*$L$9 | D32: =(LN(B32/$L$6)+($L$5+0.5*$L$4^2)*C32)/($L$4*SQRT(C32)) | E32: =NORMSDIST(D32) | F32: =E32*$L$7 | G32: =F31*B32+H31*EXP($L$5*$L$9) | H32: =G32-F32*B32 | I32: =LN(B32/B31)
A33: =A32+1 | B33: =StockPricePaths!E33 | C33: =$L$3-A33*$L$9 | D33: =(LN(B33/$L$6)+($L$5+0.5*$L$4^2)*C33)/($L$4*SQRT(C33)) | E33: =NORMSDIST(D33) | F33: =E33*$L$7 | G33: =F32*B33+H32*EXP($L$5*$L$9) | H33: =G33-F33*B33 | I33: =LN(B33/B32)
A34: =A33+1 | B34: =StockPricePaths!E34 | C34: =$L$3-A34*$L$9 | D34: =(LN(B34/$L$6)+($L$5+0.5*$L$4^2)*C34)/($L$4*SQRT(C34)) | E34: =NORMSDIST(D34) | F34: =E34*$L$7 | G34: =F33*B34+H33*EXP($L$5*$L$9) | H34: =G34-F34*B34 | I34: =LN(B34/B33)
A35: =A34+1 | B35: =StockPricePaths!E35 | C35: =$L$3-A35*$L$9 | D35: =(LN(B35/$L$6)+($L$5+0.5*$L$4^2)*C35)/($L$4*SQRT(C35)) | E35: =NORMSDIST(D35) | F35: =E35*$L$7 | G35: =F34*B35+H34*EXP($L$5*$L$9) | H35: =G35-F35*B35 | I35: =LN(B35/B34)
A36: =A35+1 | B36: =StockPricePaths!E36 | C36: =$L$3-A36*$L$9 | D36: =(LN(B36/$L$6)+($L$5+0.5*$L$4^2)*C36)/($L$4*SQRT(C36)) | E36: =NORMSDIST(D36) | F36: =E36*$L$7 | G36: =F35*B36+H35*EXP($L$5*$L$9) | H36: =G36-F36*B36 | I36: =LN(B36/B35)
A37: =A36+1 | B37: =StockPricePaths!E37 | C37: =$L$3-A37*$L$9 | D37: =(LN(B37/$L$6)+($L$5+0.5*$L$4^2)*C37)/($L$4*SQRT(C37)) | E37: =NORMSDIST(D37) | F37: =E37*$L$7 | G37: =F36*B37+H36*EXP($L$5*$L$9) | H37: =G37-F37*B37 | I37: =LN(B37/B36)
A38: =A37+1 | B38: =StockPricePaths!E38 | C38: =$L$3-A38*$L$9 | D38: =(LN(B38/$L$6)+($L$5+0.5*$L$4^2)*C38)/($L$4*SQRT(C38)) | E38: =NORMSDIST(D38) | F38: =E38*$L$7 | G38: =F37*B38+H37*EXP($L$5*$L$9) | H38: =G38-F38*B38 | I38: =LN(B38/B37)
A39: =A38+1 | B39: =StockPricePaths!E39 | C39: =$L$3-A39*$L$9 | D39: =(LN(B39/$L$6)+($L$5+0.5*$L$4^2)*C39)/($L$4*SQRT(C39)) | E39: =NORMSDIST(D39) | F39: =E39*$L$7 | G39: =F38*B39+H38*EXP($L$5*$L$9) | H39: =G39-F39*B39 | I39: =LN(B39/B38)
A40: =A39+1 | B40: =StockPricePaths!E40 | C40: =$L$3-A40*$L$9 | D40: =(LN(B40/$L$6)+($L$5+0.5*$L$4^2)*C40)/($L$4*SQRT(C40)) | E40: =NORMSDIST(D40) | F40: =E40*$L$7 | G40: =F39*B40+H39*EXP($L$5*$L$9) | H40: =G40-F40*B40 | I40: =LN(B40/B39)
...

Sheet DemoCheck_Hedge
A1: Period t | B1: Stock Price S_t | C1: Time to maturity (T-t) | D1: d1 | E1: Delta = N(d1) | F1: # Stocks held x_t | G1: S.F. Portfolio Value V_t | H1: Cash Account $ c_t | I1: Log-return ln(S_t/S_t-1) | K1: Parameter | L1: Value
A2: 0 | B2: =DemoSheet!E2 | C2: =$L$3-A2*$L$9 | D2: =(LN(B2/$L$6)+($L$5+0.5*$L$4^2)*C2)/($L$4*SQRT(C2)) | E2: =NORMSDIST(D2) | F2: =E2*$L$7 | G2: =$L$7*(B2*NORMSDIST(D2)-$L$6*EXP(-$L$5*C2)*NORMSDIST(D2-$L$4*SQRT(C2))) | H2: =G2-F2*B2 | K2: Initial stock price S0 | L2: =DemoSheet!$B$2
A3: =A2+1 | B3: =DemoSheet!E3 | C3: =$L$3-A3*$L$9 | D3: =(LN(B3/$L$6)+($L$5+0.5*$L$4^2)*C3)/($L$4*SQRT(C3)) | E3: =NORMSDIST(D3) | F3: =E3*$L$7 | G3: =F2*B3+H2*EXP($L$5*$L$9) | H3: =G3-F3*B3 | I3: =LN(B3/B2) | K3: Expiration T (years) | L3: =DemoSheet!$B$3
A4: =A3+1 | B4: =DemoSheet!E4 | C4: =$L$3-A4*$L$9 | D4: =(LN(B4/$L$6)+($L$5+0.5*$L$4^2)*C4)/($L$4*SQRT(C4)) | E4: =NORMSDIST(D4) | F4: =E4*$L$7 | G4: =F3*B4+H3*EXP($L$5*$L$9) | H4: =G4-F4*B4 | I4: =LN(B4/B3) | K4: Implied volatility | L4: =DemoSheet!$B$4
A5: =A4+1 | B5: =DemoSheet!E5 | C5: =$L$3-A5*$L$9 | D5: =(LN(B5/$L$6)+($L$5+0.5*$L$4^2)*C5)/($L$4*SQRT(C5)) | E5: =NORMSDIST(D5) | F5: =E5*$L$7 | G5: =F4*B5+H4*EXP($L$5*$L$9) | H5: =G5-F5*B5 | I5: =LN(B5/B4) | K5: Risk-free rate r | L5: =DemoSheet!$B$5
A6: =A5+1 | B6: =DemoSheet!E6 | C6: =$L$3-A6*$L$9 | D6: =(LN(B6/$L$6)+($L$5+0.5*$L$4^2)*C6)/($L$4*SQRT(C6)) | E6: =NORMSDIST(D6) | F6: =E6*$L$7 | G6: =F5*B6+H5*EXP($L$5*$L$9) | H6: =G6-F6*B6 | I6: =LN(B6/B5) | K6: Strike K | L6: =DemoSheet!$B$6
A7: =A6+1 | B7: =DemoSheet!E7 | C7: =$L$3-A7*$L$9 | D7: =(LN(B7/$L$6)+($L$5+0.5*$L$4^2)*C7)/($L$4*SQRT(C7)) | E7: =NORMSDIST(D7) | F7: =E7*$L$7 | G7: =F6*B7+H6*EXP($L$5*$L$9) | H7: =G7-F7*B7 | I7: =LN(B7/B6) | K7: # of options sold | L7: =DemoSheet!$B$7
A8: =A7+1 | B8: =DemoSheet!E8 | C8: =$L$3-A8*$L$9 | D8: =(LN(B8/$L$6)+($L$5+0.5*$L$4^2)*C8)/($L$4*SQRT(C8)) | E8: =NORMSDIST(D8) | F8: =E8*$L$7 | G8: =F7*B8+H7*EXP($L$5*$L$9) | H8: =G8-F8*B8 | I8: =LN(B8/B7) | K8: # of hedging periods | L8: =DemoSheet!$B$8
A9: =A8+1 | B9: =DemoSheet!E9 | C9: =$L$3-A9*$L$9 | D9: =(LN(B9/$L$6)+($L$5+0.5*$L$4^2)*C9)/($L$4*SQRT(C9)) | E9: =NORMSDIST(D9) | F9: =E9*$L$7 | G9: =F8*B9+H8*EXP($L$5*$L$9) | H9: =G9-F9*B9 | I9: =LN(B9/B8) | K9: dt = T / # periods | L9: =L3/L8
A10: =A9+1 | B10: =DemoSheet!E10 | C10: =$L$3-A10*$L$9 | D10: =(LN(B10/$L$6)+($L$5+0.5*$L$4^2)*C10)/($L$4*SQRT(C10)) | E10: =NORMSDIST(D10) | F10: =E10*$L$7 | G10: =F9*B10+H9*EXP($L$5*$L$9) | H10: =G10-F10*B10 | I10: =LN(B10/B9)
A11: =A10+1 | B11: =DemoSheet!E11 | C11: =$L$3-A11*$L$9 | D11: =(LN(B11/$L$6)+($L$5+0.5*$L$4^2)*C11)/($L$4*SQRT(C11)) | E11: =NORMSDIST(D11) | F11: =E11*$L$7 | G11: =F10*B11+H10*EXP($L$5*$L$9) | H11: =G11-F11*B11 | I11: =LN(B11/B10) | K11: RESULTS
A12: =A11+1 | B12: =DemoSheet!E12 | C12: =$L$3-A12*$L$9 | D12: =(LN(B12/$L$6)+($L$5+0.5*$L$4^2)*C12)/($L$4*SQRT(C12)) | E12: =NORMSDIST(D12) | F12: =E12*$L$7 | G12: =F11*B12+H11*EXP($L$5*$L$9) | H12: =G12-F12*B12 | I12: =LN(B12/B11) | K12: Mean log-return (annualized) | L12: =AVERAGE(I3:I52)/$L$9
A13: =A12+1 | B13: =DemoSheet!E13 | C13: =$L$3-A13*$L$9 | D13: =(LN(B13/$L$6)+($L$5+0.5*$L$4^2)*C13)/($L$4*SQRT(C13)) | E13: =NORMSDIST(D13) | F13: =E13*$L$7 | G13: =F12*B13+H12*EXP($L$5*$L$9) | H13: =G13-F13*B13 | I13: =LN(B13/B12) | K13: Realized volatility (annualized) | L13: =STDEV(I3:I52)/SQRT($L$9)
A14: =A13+1 | B14: =DemoSheet!E14 | C14: =$L$3-A14*$L$9 | D14: =(LN(B14/$L$6)+($L$5+0.5*$L$4^2)*C14)/($L$4*SQRT(C14)) | E14: =NORMSDIST(D14) | F14: =E14*$L$7 | G14: =F13*B14+H13*EXP($L$5*$L$9) | H14: =G14-F14*B14 | I14: =LN(B14/B13) | K14: ANSWER - realized vol in %, 2 dp | L14: =ROUND(L13*100,2)
A15: =A14+1 | B15: =DemoSheet!E15 | C15: =$L$3-A15*$L$9 | D15: =(LN(B15/$L$6)+($L$5+0.5*$L$4^2)*C15)/($L$4*SQRT(C15)) | E15: =NORMSDIST(D15) | F15: =E15*$L$7 | G15: =F14*B15+H14*EXP($L$5*$L$9) | H15: =G15-F15*B15 | I15: =LN(B15/B14) | K15: Terminal stock price S_T | L15: =B52
A16: =A15+1 | B16: =DemoSheet!E16 | C16: =$L$3-A16*$L$9 | D16: =(LN(B16/$L$6)+($L$5+0.5*$L$4^2)*C16)/($L$4*SQRT(C16)) | E16: =NORMSDIST(D16) | F16: =E16*$L$7 | G16: =F15*B16+H15*EXP($L$5*$L$9) | H16: =G16-F16*B16 | I16: =LN(B16/B15) | K16: Option payoff = # options x MAX(S_T-K,0) | L16: =MAX(L15-$L$6,0)*$L$7
A17: =A16+1 | B17: =DemoSheet!E17 | C17: =$L$3-A17*$L$9 | D17: =(LN(B17/$L$6)+($L$5+0.5*$L$4^2)*C17)/($L$4*SQRT(C17)) | E17: =NORMSDIST(D17) | F17: =E17*$L$7 | G17: =F16*B17+H16*EXP($L$5*$L$9) | H17: =G17-F17*B17 | I17: =LN(B17/B16) | K17: Final self-financing portfolio V_T | L17: =G52
A18: =A17+1 | B18: =DemoSheet!E18 | C18: =$L$3-A18*$L$9 | D18: =(LN(B18/$L$6)+($L$5+0.5*$L$4^2)*C18)/($L$4*SQRT(C18)) | E18: =NORMSDIST(D18) | F18: =E18*$L$7 | G18: =F17*B18+H17*EXP($L$5*$L$9) | H18: =G18-F18*B18 | I18: =LN(B18/B17) | K18: Total hedging P&L = V_T - payoff | L18: =L17-L16
A19: =A18+1 | B19: =DemoSheet!E19 | C19: =$L$3-A19*$L$9 | D19: =(LN(B19/$L$6)+($L$5+0.5*$L$4^2)*C19)/($L$4*SQRT(C19)) | E19: =NORMSDIST(D19) | F19: =E19*$L$7 | G19: =F18*B19+H18*EXP($L$5*$L$9) | H19: =G19-F19*B19 | I19: =LN(B19/B18) | K19: ANSWER - P&L to nearest integer | L19: =ROUND(L18,0)
A20: =A19+1 | B20: =DemoSheet!E20 | C20: =$L$3-A20*$L$9 | D20: =(LN(B20/$L$6)+($L$5+0.5*$L$4^2)*C20)/($L$4*SQRT(C20)) | E20: =NORMSDIST(D20) | F20: =E20*$L$7 | G20: =F19*B20+H19*EXP($L$5*$L$9) | H20: =G20-F20*B20 | I20: =LN(B20/B19)
A21: =A20+1 | B21: =DemoSheet!E21 | C21: =$L$3-A21*$L$9 | D21: =(LN(B21/$L$6)+($L$5+0.5*$L$4^2)*C21)/($L$4*SQRT(C21)) | E21: =NORMSDIST(D21) | F21: =E21*$L$7 | G21: =F20*B21+H20*EXP($L$5*$L$9) | H21: =G21-F21*B21 | I21: =LN(B21/B20) | K21: Prices are linked to DemoSheet!E (the worked example). Every other column is a live formula:
A22: =A21+1 | B22: =DemoSheet!E22 | C22: =$L$3-A22*$L$9 | D22: =(LN(B22/$L$6)+($L$5+0.5*$L$4^2)*C22)/($L$4*SQRT(C22)) | E22: =NORMSDIST(D22) | F22: =E22*$L$7 | G22: =F21*B22+H21*EXP($L$5*$L$9) | H22: =G22-F22*B22 | I22: =LN(B22/B21) | K22: A Period t = 0..50.
A23: =A22+1 | B23: =DemoSheet!E23 | C23: =$L$3-A23*$L$9 | D23: =(LN(B23/$L$6)+($L$5+0.5*$L$4^2)*C23)/($L$4*SQRT(C23)) | E23: =NORMSDIST(D23) | F23: =E23*$L$7 | G23: =F22*B23+H22*EXP($L$5*$L$9) | H23: =G23-F23*B23 | I23: =LN(B23/B22) | K23: B Stock price, linked to the price path (this is the only input).
A24: =A23+1 | B24: =DemoSheet!E24 | C24: =$L$3-A24*$L$9 | D24: =(LN(B24/$L$6)+($L$5+0.5*$L$4^2)*C24)/($L$4*SQRT(C24)) | E24: =NORMSDIST(D24) | F24: =E24*$L$7 | G24: =F23*B24+H23*EXP($L$5*$L$9) | H24: =G24-F24*B24 | I24: =LN(B24/B23) | K24: C Time to maturity tau = T - t*dt, dt = T/50 = 0.005 years.
